Workbook

Sheet Kurs
B2: TCF ACB Sınav Değerlendirme Sistemi (SDS) 2021
B6: Sınava Ait Bilgiler
B9: Kursu veren | C9: : | D9: Türkiye Cimnastik Federasyonu
B11: Eğitmen | C11: :
B13: Şehir | C13: : | D13: ANTALYA
B15: Tarih | C15: : | D15: 44218

Sheet Hakemler
A1: Hakemlere Ait Bilgiler
A3: No. | B3: Soyadı | C3: Adı | D3: Şehir | E3: 14. Dönem brövesi | F3: 15. Dönem brövesi
A4: 1 | B4: Yalçıner | C4: Yunus Emre | D4: İstanbul | E4: ADAY | F4: Bölge
A5: =A4+1 -> 2 | B5: Deneme | C5: Hakem | D5: İstanbul | E5: Bölge | F5: Milli
A6: =A5+1 -> 3
A7: =A6+1 -> 4
A8: =A7+1 -> 5
A9: =A8+1 -> 6
A10: =A9+1 -> 7
A11: =A10+1 -> 8
A12: =A11+1 -> 9
A13: =A12+1 -> 10
A14: =A13+1 -> 11
A15: =A14+1 -> 12
A16: =A15+1 -> 13
A17: =A16+1 -> 14
... A103: =A102+1 -> 100

Sheet AtM_D
A1: ATLAMA MASASI - D Puanı
A2: No. | B2: Soyadı | C2: Adı | D2: D1 | F2: D2 | H2: D3 | J2: D4 | L2: D5 | N2: D6 | P2: D7 | R2: D8 | T2: D9 | V2: D10
D3: D1 | E3: P | F3: D2 | G3: P | H3: D3 | I3: P | J3: D4 | K3: P | L3: D5 | M3: P | N3: D5 | O3: P | P3: D5 | Q3: P | R3: D5 | S3: P | T3: D5 | U3: P | V3: D5 | W3: P | X3: Ortalama
A4: 1 | B4: =Hakemler!B4 -> Yalçıner | C4: =Hakemler!C4 -> Yunus Emre | D4: 5.4 | E4: =IF(D4=Uzman_D!$B$24,1,0) -> 1 | F4: 4.6 | G4: =IF(F4=Uzman_D!$B$25,1,0) -> 1 | H4: 4.2 | I4: =IF(H4=Uzman_D!$B$26,1,0) -> 1 | J4: 3.8 | K4: =IF(J4=Uzman_D!$B$27,1,0) -> 1 | L4: 5.2 | M4: =IF(L4=Uzman_D!$B$28,1,0) -> 1 | O4: =IF(N4=Uzman_D!$B$29,1,0) -> 1 | Q4: =IF(P4=Uzman_D!$B$30,1,0) -> 1 | S4: =IF(R4=Uzman_D!$B$31,1,0) -> 1 | U4: =IF(T4=Uzman_D!$B$32,1,0) -> 1 | W4: =IF(V4=Uzman_D!$B$33,1,0) -> 1 | X4: =(E4+G4+I4+K4+M4+O4+Q4+S4+U4+W4)/10 -> 1
A5: 2 | B5: =Hakemler!B5 -> Deneme | C5: =Hakemler!C5 -> Hakem | E5: =IF(D5=Uzman_D!$B$24,1,0) -> 0 | G5: =IF(F5=Uzman_D!$B$25,1,0) -> 0 | I5: =IF(H5=Uzman_D!$B$26,1,0) -> 0 | K5: =IF(J5=Uzman_D!$B$27,1,0) -> 0 | M5: =IF(L5=Uzman_D!$B$28,1,0) -> 0 | O5: =IF(N5=Uzman_D!$B$29,1,0) -> 1 | Q5: =IF(P5=Uzman_D!$B$30,1,0) -> 1 | S5: =IF(R5=Uzman_D!$B$31,1,0) -> 1 | U5: =IF(T5=Uzman_D!$B$32,1,0) -> 1 | W5: =IF(V5=Uzman_D!$B$33,1,0) -> 1 | X5: =(E5+G5+I5+K5+M5+O5+Q5+S5+U5+W5)/10 -> 0.5
A6: 3 | B6: =Hakemler!B6 -> 0 | C6: =Hakemler!C6 -> 0 | E6: =IF(D6=Uzman_D!$B$24,1,0) -> 0 | G6: =IF(F6=Uzman_D!$B$25,1,0) -> 0 | I6: =IF(H6=Uzman_D!$B$26,1,0) -> 0 | K6: =IF(J6=Uzman_D!$B$27,1,0) -> 0 | M6: =IF(L6=Uzman_D!$B$28,1,0) -> 0 | O6: =IF(N6=Uzman_D!$B$29,1,0) -> 1 | Q6: =IF(P6=Uzman_D!$B$30,1,0) -> 1 | S6: =IF(R6=Uzman_D!$B$31,1,0) -> 1 | U6: =IF(T6=Uzman_D!$B$32,1,0) -> 1 | W6: =IF(V6=Uzman_D!$B$33,1,0) -> 1 | X6: =(E6+G6+I6+K6+M6+O6+Q6+S6+U6+W6)/10 -> 0.5
A7: 4 | B7: =Hakemler!B7 -> 0 | C7: =Hakemler!C7 -> 0 | E7: =IF(D7=Uzman_D!$B$24,1,0) -> 0 | G7: =IF(F7=Uzman_D!$B$25,1,0) -> 0 | I7: =IF(H7=Uzman_D!$B$26,1,0) -> 0 | K7: =IF(J7=Uzman_D!$B$27,1,0) -> 0 | M7: =IF(L7=Uzman_D!$B$28,1,0) -> 0 | O7: =IF(N7=Uzman_D!$B$29,1,0) -> 1 | Q7: =IF(P7=Uzman_D!$B$30,1,0) -> 1 | S7: =IF(R7=Uzman_D!$B$31,1,0) -> 1 | U7: =IF(T7=Uzman_D!$B$32,1,0) -> 1 | W7: =IF(V7=Uzman_D!$B$33,1,0) -> 1 | X7: =(E7+G7+I7+K7+M7+O7+Q7+S7+U7+W7)/10 -> 0.5
A8: 5 | B8: =Hakemler!B8 -> 0 | C8: =Hakemler!C8 -> 0 | E8: =IF(D8=Uzman_D!$B$24,1,0) -> 0 | G8: =IF(F8=Uzman_D!$B$25,1,0) -> 0 | I8: =IF(H8=Uzman_D!$B$26,1,0) -> 0 | K8: =IF(J8=Uzman_D!$B$27,1,0) -> 0 | M8: =IF(L8=Uzman_D!$B$28,1,0) -> 0 | O8: =IF(N8=Uzman_D!$B$29,1,0) -> 1 | Q8: =IF(P8=Uzman_D!$B$30,1,0) -> 1 | S8: =IF(R8=Uzman_D!$B$31,1,0) -> 1 | U8: =IF(T8=Uzman_D!$B$32,1,0) -> 1 | W8: =IF(V8=Uzman_D!$B$33,1,0) -> 1 | X8: =(E8+G8+I8+K8+M8+O8+Q8+S8+U8+W8)/10 -> 0.5
A9: 6 | B9: =Hakemler!B9 -> 0 | C9: =Hakemler!C9 -> 0 | E9: =IF(D9=Uzman_D!$B$24,1,0) -> 0 | G9: =IF(F9=Uzman_D!$B$25,1,0) -> 0 | I9: =IF(H9=Uzman_D!$B$26,1,0) -> 0 | K9: =IF(J9=Uzman_D!$B$27,1,0) -> 0 | M9: =IF(L9=Uzman_D!$B$28,1,0) -> 0 | O9: =IF(N9=Uzman_D!$B$29,1,0) -> 1 | Q9: =IF(P9=Uzman_D!$B$30,1,0) -> 1 | S9: =IF(R9=Uzman_D!$B$31,1,0) -> 1 | U9: =IF(T9=Uzman_D!$B$32,1,0) -> 1 | W9: =IF(V9=Uzman_D!$B$33,1,0) -> 1 | X9: =(E9+G9+I9+K9+M9+O9+Q9+S9+U9+W9)/10 -> 0.5
A10: 7 | B10: =Hakemler!B10 -> 0 | C10: =Hakemler!C10 -> 0 | E10: =IF(D10=Uzman_D!$B$24,1,0) -> 0 | G10: =IF(F10=Uzman_D!$B$25,1,0) -> 0 | I10: =IF(H10=Uzman_D!$B$26,1,0) -> 0 | K10: =IF(J10=Uzman_D!$B$27,1,0) -> 0 | M10: =IF(L10=Uzman_D!$B$28,1,0) -> 0 | O10: =IF(N10=Uzman_D!$B$29,1,0) -> 1 | Q10: =IF(P10=Uzman_D!$B$30,1,0) -> 1 | S10: =IF(R10=Uzman_D!$B$31,1,0) -> 1 | U10: =IF(T10=Uzman_D!$B$32,1,0) -> 1 | W10: =IF(V10=Uzman_D!$B$33,1,0) -> 1 | X10: =(E10+G10+I10+K10+M10+O10+Q10+S10+U10+W10)/10 -> 0.5
A11: 8 | B11: =Hakemler!B11 -> 0 | C11: =Hakemler!C11 -> 0 | E11: =IF(D11=Uzman_D!$B$24,1,0) -> 0 | G11: =IF(F11=Uzman_D!$B$25,1,0) -> 0 | I11: =IF(H11=Uzman_D!$B$26,1,0) -> 0 | K11: =IF(J11=Uzman_D!$B$27,1,0) -> 0 | M11: =IF(L11=Uzman_D!$B$28,1,0) -> 0 | O11: =IF(N11=Uzman_D!$B$29,1,0) -> 1 | Q11: =IF(P11=Uzman_D!$B$30,1,0) -> 1 | S11: =IF(R11=Uzman_D!$B$31,1,0) -> 1 | U11: =IF(T11=Uzman_D!$B$32,1,0) -> 1 | W11: =IF(V11=Uzman_D!$B$33,1,0) -> 1 | X11: =(E11+G11+I11+K11+M11+O11+Q11+S11+U11+W11)/10 -> 0.5
A12: 9 | B12: =Hakemler!B12 -> 0 | C12: =Hakemler!C12 -> 0 | E12: =IF(D12=Uzman_D!$B$24,1,0) -> 0 | G12: =IF(F12=Uzman_D!$B$25,1,0) -> 0 | I12: =IF(H12=Uzman_D!$B$26,1,0) -> 0 | K12: =IF(J12=Uzman_D!$B$27,1,0) -> 0 | M12: =IF(L12=Uzman_D!$B$28,1,0) -> 0 | O12: =IF(N12=Uzman_D!$B$29,1,0) -> 1 | Q12: =IF(P12=Uzman_D!$B$30,1,0) -> 1 | S12: =IF(R12=Uzman_D!$B$31,1,0) -> 1 | U12: =IF(T12=Uzman_D!$B$32,1,0) -> 1 | W12: =IF(V12=Uzman_D!$B$33,1,0) -> 1 | X12: =(E12+G12+I12+K12+M12+O12+Q12+S12+U12+W12)/10 -> 0.5
A13: 10 | B13: =Hakemler!B13 -> 0 | C13: =Hakemler!C13 -> 0 | E13: =IF(D13=Uzman_D!$B$24,1,0) -> 0 | G13: =IF(F13=Uzman_D!$B$25,1,0) -> 0 | I13: =IF(H13=Uzman_D!$B$26,1,0) -> 0 | K13: =IF(J13=Uzman_D!$B$27,1,0) -> 0 | M13: =IF(L13=Uzman_D!$B$28,1,0) -> 0 | O13: =IF(N13=Uzman_D!$B$29,1,0) -> 1 | Q13: =IF(P13=Uzman_D!$B$30,1,0) -> 1 | S13: =IF(R13=Uzman_D!$B$31,1,0) -> 1 | U13: =IF(T13=Uzman_D!$B$32,1,0) -> 1 | W13: =IF(V13=Uzman_D!$B$33,1,0) -> 1 | X13: =(E13+G13+I13+K13+M13+O13+Q13+S13+U13+W13)/10 -> 0.5
A14: 11 | B14: =Hakemler!B14 -> 0 | C14: =Hakemler!C14 -> 0 | E14: =IF(D14=Uzman_D!$B$24,1,0) -> 0 | G14: =IF(F14=Uzman_D!$B$25,1,0) -> 0 | I14: =IF(H14=Uzman_D!$B$26,1,0) -> 0 | K14: =IF(J14=Uzman_D!$B$27,1,0) -> 0 | M14: =IF(L14=Uzman_D!$B$28,1,0) -> 0 | O14: =IF(N14=Uzman_D!$B$29,1,0) -> 1 | Q14: =IF(P14=Uzman_D!$B$30,1,0) -> 1 | S14: =IF(R14=Uzman_D!$B$31,1,0) -> 1 | U14: =IF(T14=Uzman_D!$B$32,1,0) -> 1 | W14: =IF(V14=Uzman_D!$B$33,1,0) -> 1 | X14: =(E14+G14+I14+K14+M14+O14+Q14+S14+U14+W14)/10 -> 0.5
A15: 12 | B15: =Hakemler!B15 -> 0 | C15: =Hakemler!C15 -> 0 | E15: =IF(D15=Uzman_D!$B$24,1,0) -> 0 | G15: =IF(F15=Uzman_D!$B$25,1,0) -> 0 | I15: =IF(H15=Uzman_D!$B$26,1,0) -> 0 | K15: =IF(J15=Uzman_D!$B$27,1,0) -> 0 | M15: =IF(L15=Uzman_D!$B$28,1,0) -> 0 | O15: =IF(N15=Uzman_D!$B$29,1,0) -> 1 | Q15: =IF(P15=Uzman_D!$B$30,1,0) -> 1 | S15: =IF(R15=Uzman_D!$B$31,1,0) -> 1 | U15: =IF(T15=Uzman_D!$B$32,1,0) -> 1 | W15: =IF(V15=Uzman_D!$B$33,1,0) -> 1 | X15: =(E15+G15+I15+K15+M15+O15+Q15+S15+U15+W15)/10 -> 0.5
A16: 13 | B16: =Hakemler!B16 -> 0 | C16: =Hakemler!C16 -> 0 | E16: =IF(D16=Uzman_D!$B$24,1,0) -> 0 | G16: =IF(F16=Uzman_D!$B$25,1,0) -> 0 | I16: =IF(H16=Uzman_D!$B$26,1,0) -> 0 | K16: =IF(J16=Uzman_D!$B$27,1,0) -> 0 | M16: =IF(L16=Uzman_D!$B$28,1,0) -> 0 | O16: =IF(N16=Uzman_D!$B$29,1,0) -> 1 | Q16: =IF(P16=Uzman_D!$B$30,1,0) -> 1 | S16: =IF(R16=Uzman_D!$B$31,1,0) -> 1 | U16: =IF(T16=Uzman_D!$B$32,1,0) -> 1 | W16: =IF(V16=Uzman_D!$B$33,1,0) -> 1 | X16: =(E16+G16+I16+K16+M16+O16+Q16+S16+U16+W16)/10 -> 0.5
... A103: 100 | B103: =Hakemler!B103 -> 0 | C103: =Hakemler!C103 -> 0 | E103: =IF(D103=Uzman_D!$B$24,1,0) -> 0 | G103: =IF(F103=Uzman_D!$B$25,1,0) -> 0 | I103: =IF(H103=Uzman_D!$B$26,1,0) -> 0 | K103: =IF(J103=Uzman_D!$B$27,1,0) -> 0 | M103: =IF(L103=Uzman_D!$B$28,1,0) -> 0 | O103: =IF(N103=Uzman_D!$B$29,1,0) -> 1 | Q103: =IF(P103=Uzman_D!$B$30,1,0) -> 1 | S103: =IF(R103=Uzman_D!$B$31,1,0) -> 1 | U103: =IF(T103=Uzman_D!$B$32,1,0) -> 1 | W103: =IF(V103=Uzman_D!$B$33,1,0) -> 1 | X103: =(E103+G103+I103+K103+M103+O103+Q103+S103+U103+W103)/10 -> 0.5

Sheet AtM_E
A1: ATLAMA MASASI - E Puanı
A2: No. | B2: Soyadı | C2: Adı | D2: E1 | G2: E2 | J2: E3 | M2: E4 | P2: E5
D3: E1 | E3: Hata | F3: P | G3: E2 | H3: Hata | I3: P | J3: E3 | K3: Hata | L3: P | M3: E4 | N3: Hata | O3: P | P3: E5 | Q3: Hata | R3: P | S3: Ortalama
A4: 1 | B4: =Hakemler!B4 -> Yalçıner | C4: =Hakemler!C4 -> Yunus Emre | D4: 2.3 | E4: =IF(ISBLANK(D4),0,ABS(Uzman_E!A$4-D4)) -> 0.6 | F4: =IF(ISBLANK(D4),0,INDEX(Tablo_E!$B$2:$CX$102,MATCH(ROUND(Uzman_E!A$4,1),Tablo_E!$A$2:$A$102,1),MATCH(ROUND(E4,1),Tablo_E!$B$1:$CX$1,1))) -> 0.7 | G4: 1.2 | H4: =IF(ISBLANK(G4),0,ABS(Uzman_E!B$4-G4)) -> 0.3 | I4: =IF(ISBLANK(G4),0,INDEX(Tablo_E!$B$2:$CX$102,MATCH(ROUND(Uzman_E!B$4,1),Tablo_E!$A$2:$A$102,1),MATCH(ROUND(H4,1),Tablo_E!$B$1:$CX$1,1))) -> 0.9 | J4: 1.4 | K4: =IF(ISBLANK(J4),0,ABS(Uzman_E!C$4-J4)) -> 0.1 | L4: =IF(ISBLANK(J4),0,INDEX(Tablo_E!$B$2:$CX$102,MATCH(ROUND(Uzman_E!C$4,1),Tablo_E!$A$2:$A$102,1),MATCH(ROUND(K4,1),Tablo_E!$B$1:$CX$1,1))) -> 1 | M4: 1.7 | N4: =IF(ISBLANK(M4),0,ABS(Uzman_E!D$4-M4)) -> 0.4 | O4: =IF(ISBLANK(M4),0,INDEX(Tablo_E!$B$2:$CX$102,MATCH(ROUND(Uzman_E!D$4,1),Tablo_E!$A$2:$A$102,1),MATCH(ROUND(N4,1),Tablo_E!$B$1:$CX$1,1))) -> 0.8 | P4: 0.8 | Q4: =IF(ISBLANK(P4),0,ABS(Uzman_E!E$4-P4)) -> 0.2 | R4: =IF(ISBLANK(P4),0,INDEX(Tablo_E!$B$2:$CX$102,MATCH(ROUND(Uzman_E!B$4,1),Tablo_E!$A$2:$A$102,1),MATCH(ROUND(Q4,1),Tablo_E!$B$1:$CX$1,1))) -> 1 | S4: =(F4+I4+L4+O4+R4)/5 -> 0.88
A5: 2 | B5: =Hakemler!B5 -> Deneme | C5: =Hakemler!C5 -> Hakem | D5: 1 | E5: =IF(ISBLANK(D5),0,ABS(Uzman_E!A$4-D5)) -> 0.7 | F5: =IF(ISBLANK(D5),0,INDEX(Tablo_E!$B$2:$CX$102,MATCH(ROUND(Uzman_E!A$4,1),Tablo_E!$A$2:$A$102,1),MATCH(ROUND(E5,1),Tablo_E!$B$1:$CX$1,1))) -> 0.6 | H5: =IF(ISBLANK(G5),0,ABS(Uzman_E!B$4-G5)) -> 0 | I5: =IF(ISBLANK(G5),0,INDEX(Tablo_E!$B$2:$CX$102,MATCH(ROUND(Uzman_E!B$4,1),Tablo_E!$A$2:$A$102,1),MATCH(ROUND(H5,1),Tablo_E!$B$1:$CX$1,1))) -> 0 | K5: =IF(ISBLANK(J5),0,ABS(Uzman_E!C$4-J5)) -> 0 | L5: =IF(ISBLANK(J5),0,INDEX(Tablo_E!$B$2:$CX$102,MATCH(ROUND(Uzman_E!C$4,1),Tablo_E!$A$2:$A$102,1),MATCH(ROUND(K5,1),Tablo_E!$B$1:$CX$1,1))) -> 0 | N5: =IF(ISBLANK(M5),0,ABS(Uzman_E!D$4-M5)) -> 0 | O5: =IF(ISBLANK(M5),0,INDEX(Tablo_E!$B$2:$CX$102,MATCH(ROUND(Uzman_E!D$4,1),Tablo_E!$A$2:$A$102,1),MATCH(ROUND(N5,1),Tablo_E!$B$1:$CX$1,1))) -> 0 | P5: 1 | Q5: =IF(ISBLANK(P5),0,ABS(Uzman_E!E$4-P5)) -> 0 | R5: =IF(ISBLANK(P5),0,INDEX(Tablo_E!$B$2:$CX$102,MATCH(ROUND(Uzman_E!B$4,1),Tablo_E!$A$2:$A$102,1),MATCH(ROUND(Q5,1),Tablo_E!$B$1:$CX$1,1))) -> 1 | S5: =(F5+I5+L5+O5+R5)/5 -> 0.32
A6: 3 | B6: =Hakemler!B6 -> 0 | C6: =Hakemler!C6 -> 0 | E6: =IF(ISBLANK(D6),0,ABS(Uzman_E!A$4-D6)) -> 0 | F6: =IF(ISBLANK(D6),0,INDEX(Tablo_E!$B$2:$CX$102,MATCH(ROUND(Uzman_E!A$4,1),Tablo_E!$A$2:$A$102,1),MATCH(ROUND(E6,1),Tablo_E!$B$1:$CX$1,1))) -> 0 | H6: =IF(ISBLANK(G6),0,ABS(Uzman_E!B$4-G6)) -> 0 | I6: =IF(ISBLANK(G6),0,INDEX(Tablo_E!$B$2:$CX$102,MATCH(ROUND(Uzman_E!B$4,1),Tablo_E!$A$2:$A$102,1),MATCH(ROUND(H6,1),Tablo_E!$B$1:$CX$1,1))) -> 0 | J6: 3 | K6: =IF(ISBLANK(J6),0,ABS(Uzman_E!C$4-J6)) -> 1.5 | L6: =IF(ISBLANK(J6),0,INDEX(Tablo_E!$B$2:$CX$102,MATCH(ROUND(Uzman_E!C$4,1),Tablo_E!$A$2:$A$102,1),MATCH(ROUND(K6,1),Tablo_E!$B$1:$CX$1,1))) -> 0 | N6: =IF(ISBLANK(M6),0,ABS(Uzman_E!D$4-M6)) -> 0 | O6: =IF(ISBLANK(M6),0,INDEX(Tablo_E!$B$2:$CX$102,MATCH(ROUND(Uzman_E!D$4,1),Tablo_E!$A$2:$A$102,1),MATCH(ROUND(N6,1),Tablo_E!$B$1:$CX$1,1))) -> 0 | P6: 1.2 | Q6: =IF(ISBLANK(P6),0,ABS(Uzman_E!E$4-P6)) -> 0.2 | R6: =IF(ISBLANK(P6),0,INDEX(Tablo_E!$B$2:$CX$102,MATCH(ROUND(Uzman_E!B$4,1),Tablo_E!$A$2:$A$102,1),MATCH(ROUND(Q6,1),Tablo_E!$B$1:$CX$1,1))) -> 1 | S6: =(F6+I6+L6+O6+R6)/5 -> 0.2
A7: 4 | B7: =Hakemler!B7 -> 0 | C7: =Hakemler!C7 -> 0 | E7: =IF(ISBLANK(D7),0,ABS(Uzman_E!A$4-D7)) -> 0 | F7: =IF(ISBLANK(D7),0,INDEX(Tablo_E!$B$2:$CX$102,MATCH(ROUND(Uzman_E!A$4,1),Tablo_E!$A$2:$A$102,1),MATCH(ROUND(E7,1),Tablo_E!$B$1:$CX$1,1))) -> 0 | G7: 2 | H7: =IF(ISBLANK(G7),0,ABS(Uzman_E!B$4-G7)) -> 0.5 | I7: =IF(ISBLANK(G7),0,INDEX(Tablo_E!$B$2:$CX$102,MATCH(ROUND(Uzman_E!B$4,1),Tablo_E!$A$2:$A$102,1),MATCH(ROUND(H7,1),Tablo_E!$B$1:$CX$1,1))) -> 0.7 | J7: 2 | K7: =IF(ISBLANK(J7),0,ABS(Uzman_E!C$4-J7)) -> 0.5 | L7: =IF(ISBLANK(J7),0,INDEX(Tablo_E!$B$2:$CX$102,MATCH(ROUND(Uzman_E!C$4,1),Tablo_E!$A$2:$A$102,1),MATCH(ROUND(K7,1),Tablo_E!$B$1:$CX$1,1))) -> 0.7 | N7: =IF(ISBLANK(M7),0,ABS(Uzman_E!D$4-M7)) -> 0 | O7: =IF(ISBLANK(M7),0,INDEX(Tablo_E!$B$2:$CX$102,MATCH(ROUND(Uzman_E!D$4,1),Tablo_E!$A$2:$A$102,1),MATCH(ROUND(N7,1),Tablo_E!$B$1:$CX$1,1))) -> 0 | P7: 1.4 | Q7: =IF(ISBLANK(P7),0,ABS(Uzman_E!E$4-P7)) -> 0.4 | R7: =IF(ISBLANK(P7),0,INDEX(Tablo_E!$B$2:$CX$102,MATCH(ROUND(Uzman_E!B$4,1),Tablo_E!$A$2:$A$102,1),MATCH(ROUND(Q7,1),Tablo_E!$B$1:$CX$1,1))) -> 0.8 | S7: =(F7+I7+L7+O7+R7)/5 -> 0.44
A8: 5 | B8: =Hakemler!B8 -> 0 | C8: =Hakemler!C8 -> 0 | E8: =IF(ISBLANK(D8),0,ABS(Uzman_E!A$4-D8)) -> 0 | F8: =IF(ISBLANK(D8),0,INDEX(Tablo_E!$B$2:$CX$102,MATCH(ROUND(Uzman_E!A$4,1),Tablo_E!$A$2:$A$102,1),MATCH(ROUND(E8,1),Tablo_E!$B$1:$CX$1,1))) -> 0 | G8: 1.2 | H8: =IF(ISBLANK(G8),0,ABS(Uzman_E!B$4-G8)) -> 0.3 | I8: =IF(ISBLANK(G8),0,INDEX(Tablo_E!$B$2:$CX$102,MATCH(ROUND(Uzman_E!B$4,1),Tablo_E!$A$2:$A$102,1),MATCH(ROUND(H8,1),Tablo_E!$B$1:$CX$1,1))) -> 0.9 | J8: 1 | K8: =IF(ISBLANK(J8),0,ABS(Uzman_E!C$4-J8)) -> 0.5 | L8: =IF(ISBLANK(J8),0,INDEX(Tablo_E!$B$2:$CX$102,MATCH(ROUND(Uzman_E!C$4,1),Tablo_E!$A$2:$A$102,1),MATCH(ROUND(K8,1),Tablo_E!$B$1:$CX$1,1))) -> 0.7 | N8: =IF(ISBLANK(M8),0,ABS(Uzman_E!D$4-M8)) -> 0 | O8: =IF(ISBLANK(M8),0,INDEX(Tablo_E!$B$2:$CX$102,MATCH(ROUND(Uzman_E!D$4,1),Tablo_E!$A$2:$A$102,1),MATCH(ROUND(N8,1),Tablo_E!$B$1:$CX$1,1))) -> 0 | Q8: =IF(ISBLANK(P8),0,ABS(Uzman_E!E$4-P8)) -> 0 | R8: =IF(ISBLANK(P8),0,INDEX(Tablo_E!$B$2:$CX$102,MATCH(ROUND(Uzman_E!B$4,1),Tablo_E!$A$2:$A$102,1),MATCH(ROUND(Q8,1),Tablo_E!$B$1:$CX$1,1))) -> 0 | S8: =(F8+I8+L8+O8+R8)/5 -> 0.32
A9: 6 | B9: =Hakemler!B9 -> 0 | C9: =Hakemler!C9 -> 0 | E9: =IF(ISBLANK(D9),0,ABS(Uzman_E!A$4-D9)) -> 0 | F9: =IF(ISBLANK(D9),0,INDEX(Tablo_E!$B$2:$CX$102,MATCH(ROUND(Uzman_E!A$4,1),Tablo_E!$A$2:$A$102,1),MATCH(ROUND(E9,1),Tablo_E!$B$1:$CX$1,1))) -> 0 | G9: 1 | H9: =IF(ISBLANK(G9),0,ABS(Uzman_E!B$4-G9)) -> 0.5 | I9: =IF(ISBLANK(G9),0,INDEX(Tablo_E!$B$2:$CX$102,MATCH(ROUND(Uzman_E!B$4,1),Tablo_E!$A$2:$A$102,1),MATCH(ROUND(H9,1),Tablo_E!$B$1:$CX$1,1))) -> 0.7 | J9: 5 | K9: =IF(ISBLANK(J9),0,ABS(Uzman_E!C$4-J9)) -> 3.5 | L9: =IF(ISBLANK(J9),0,INDEX(Tablo_E!$B$2:$CX$102,MATCH(ROUND(Uzman_E!C$4,1),Tablo_E!$A$2:$A$102,1),MATCH(ROUND(K9,1),Tablo_E!$B$1:$CX$1,1))) -> 0 | N9: =IF(ISBLANK(M9),0,ABS(Uzman_E!D$4-M9)) -> 0 | O9: =IF(ISBLANK(M9),0,INDEX(Tablo_E!$B$2:$CX$102,MATCH(ROUND(Uzman_E!D$4,1),Tablo_E!$A$2:$A$102,1),MATCH(ROUND(N9,1),Tablo_E!$B$1:$CX$1,1))) -> 0 | Q9: =IF(ISBLANK(P9),0,ABS(Uzman_E!E$4-P9)) -> 0 | R9: =IF(ISBLANK(P9),0,INDEX(Tablo_E!$B$2:$CX$102,MATCH(ROUND(Uzman_E!B$4,1),Tablo_E!$A$2:$A$102,1),MATCH(ROUND(Q9,1),Tablo_E!$B$1:$CX$1,1))) -> 0 | S9: =(F9+I9+L9+O9+R9)/5 -> 0.14
A10: 7 | B10: =Hakemler!B10 -> 0 | C10: =Hakemler!C10 -> 0 | E10: =IF(ISBLANK(D10),0,ABS(Uzman_E!A$4-D10)) -> 0 | F10: =IF(ISBLANK(D10),0,INDEX(Tablo_E!$B$2:$CX$102,MATCH(ROUND(Uzman_E!A$4,1),Tablo_E!$A$2:$A$102,1),MATCH(ROUND(E10,1),Tablo_E!$B$1:$CX$1,1))) -> 0 | G10: 1.5 | H10: =IF(ISBLANK(G10),0,ABS(Uzman_E!B$4-G10)) -> 0 | I10: =IF(ISBLANK(G10),0,INDEX(Tablo_E!$B$2:$CX$102,MATCH(ROUND(Uzman_E!B$4,1),Tablo_E!$A$2:$A$102,1),MATCH(ROUND(H10,1),Tablo_E!$B$1:$CX$1,1))) -> 1 | J10: 4 | K10: =IF(ISBLANK(J10),0,ABS(Uzman_E!C$4-J10)) -> 2.5 | L10: =IF(ISBLANK(J10),0,INDEX(Tablo_E!$B$2:$CX$102,MATCH(ROUND(Uzman_E!C$4,1),Tablo_E!$A$2:$A$102,1),MATCH(ROUND(K10,1),Tablo_E!$B$1:$CX$1,1))) -> 0 | N10: =IF(ISBLANK(M10),0,ABS(Uzman_E!D$4-M10)) -> 0 | O10: =IF(ISBLANK(M10),0,INDEX(Tablo_E!$B$2:$CX$102,MATCH(ROUND(Uzman_E!D$4,1),Tablo_E!$A$2:$A$102,1),MATCH(ROUND(N10,1),Tablo_E!$B$1:$CX$1,1))) -> 0 | Q10: =IF(ISBLANK(P10),0,ABS(Uzman_E!E$4-P10)) -> 0 | R10: =IF(ISBLANK(P10),0,INDEX(Tablo_E!$B$2:$CX$102,MATCH(ROUND(Uzman_E!B$4,1),Tablo_E!$A$2:$A$102,1),MATCH(ROUND(Q10,1),Tablo_E!$B$1:$CX$1,1))) -> 0 | S10: =(F10+I10+L10+O10+R10)/5 -> 0.2
A11: 8 | B11: =Hakemler!B11 -> 0 | C11: =Hakemler!C11 -> 0 | E11: =IF(ISBLANK(D11),0,ABS(Uzman_E!A$4-D11)) -> 0 | F11: =IF(ISBLANK(D11),0,INDEX(Tablo_E!$B$2:$CX$102,MATCH(ROUND(Uzman_E!A$4,1),Tablo_E!$A$2:$A$102,1),MATCH(ROUND(E11,1),Tablo_E!$B$1:$CX$1,1))) -> 0 | H11: =IF(ISBLANK(G11),0,ABS(Uzman_E!B$4-G11)) -> 0 | I11: =IF(ISBLANK(G11),0,INDEX(Tablo_E!$B$2:$CX$102,MATCH(ROUND(Uzman_E!B$4,1),Tablo_E!$A$2:$A$102,1),MATCH(ROUND(H11,1),Tablo_E!$B$1:$CX$1,1))) -> 0 | K11: =IF(ISBLANK(J11),0,ABS(Uzman_E!C$4-J11)) -> 0 | L11: =IF(ISBLANK(J11),0,INDEX(Tablo_E!$B$2:$CX$102,MATCH(ROUND(Uzman_E!C$4,1),Tablo_E!$A$2:$A$102,1),MATCH(ROUND(K11,1),Tablo_E!$B$1:$CX$1,1))) -> 0 | N11: =IF(ISBLANK(M11),0,ABS(Uzman_E!D$4-M11)) -> 0 | O11: =IF(ISBLANK(M11),0,INDEX(Tablo_E!$B$2:$CX$102,MATCH(ROUND(Uzman_E!D$4,1),Tablo_E!$A$2:$A$102,1),MATCH(ROUND(N11,1),Tablo_E!$B$1:$CX$1,1))) -> 0 | Q11: =IF(ISBLANK(P11),0,ABS(Uzman_E!E$4-P11)) -> 0 | R11: =IF(ISBLANK(P11),0,INDEX(Tablo_E!$B$2:$CX$102,MATCH(ROUND(Uzman_E!B$4,1),Tablo_E!$A$2:$A$102,1),MATCH(ROUND(Q11,1),Tablo_E!$B$1:$CX$1,1))) -> 0 | S11: =(F11+I11+L11+O11+R11)/5 -> 0
A12: 9 | B12: =Hakemler!B12 -> 0 | C12: =Hakemler!C12 -> 0 | E12: =IF(ISBLANK(D12),0,ABS(Uzman_E!A$4-D12)) -> 0 | F12: =IF(ISBLANK(D12),0,INDEX(Tablo_E!$B$2:$CX$102,MATCH(ROUND(Uzman_E!A$4,1),Tablo_E!$A$2:$A$102,1),MATCH(ROUND(E12,1),Tablo_E!$B$1:$CX$1,1))) -> 0 | H12: =IF(ISBLANK(G12),0,ABS(Uzman_E!B$4-G12)) -> 0 | I12: =IF(ISBLANK(G12),0,INDEX(Tablo_E!$B$2:$CX$102,MATCH(ROUND(Uzman_E!B$4,1),Tablo_E!$A$2:$A$102,1),MATCH(ROUND(H12,1),Tablo_E!$B$1:$CX$1,1))) -> 0 | J12: 3 | K12: =IF(ISBLANK(J12),0,ABS(Uzman_E!C$4-J12)) -> 1.5 | L12: =IF(ISBLANK(J12),0,INDEX(Tablo_E!$B$2:$CX$102,MATCH(ROUND(Uzman_E!C$4,1),Tablo_E!$A$2:$A$102,1),MATCH(ROUND(K12,1),Tablo_E!$B$1:$CX$1,1))) -> 0 | N12: =IF(ISBLANK(M12),0,ABS(Uzman_E!D$4-M12)) -> 0 | O12: =IF(ISBLANK(M12),0,INDEX(Tablo_E!$B$2:$CX$102,MATCH(ROUND(Uzman_E!D$4,1),Tablo_E!$A$2:$A$102,1),MATCH(ROUND(N12,1),Tablo_E!$B$1:$CX$1,1))) -> 0 | Q12: =IF(ISBLANK(P12),0,ABS(Uzman_E!E$4-P12)) -> 0 | R12: =IF(ISBLANK(P12),0,INDEX(Tablo_E!$B$2:$CX$102,MATCH(ROUND(Uzman_E!B$4,1),Tablo_E!$A$2:$A$102,1),MATCH(ROUND(Q12,1),Tablo_E!$B$1:$CX$1,1))) -> 0 | S12: =(F12+I12+L12+O12+R12)/5 -> 0
A13: 10 | B13: =Hakemler!B13 -> 0 | C13: =Hakemler!C13 -> 0 | E13: =IF(ISBLANK(D13),0,ABS(Uzman_E!A$4-D13)) -> 0 | F13: =IF(ISBLANK(D13),0,INDEX(Tablo_E!$B$2:$CX$102,MATCH(ROUND(Uzman_E!A$4,1),Tablo_E!$A$2:$A$102,1),MATCH(ROUND(E13,1),Tablo_E!$B$1:$CX$1,1))) -> 0 | H13: =IF(ISBLANK(G13),0,ABS(Uzman_E!B$4-G13)) -> 0 | I13: =IF(ISBLANK(G13),0,INDEX(Tablo_E!$B$2:$CX$102,MATCH(ROUND(Uzman_E!B$4,1),Tablo_E!$A$2:$A$102,1),MATCH(ROUND(H13,1),Tablo_E!$B$1:$CX$1,1))) -> 0 | J13: 1.1 | K13: =IF(ISBLANK(J13),0,ABS(Uzman_E!C$4-J13)) -> 0.4 | L13: =IF(ISBLANK(J13),0,INDEX(Tablo_E!$B$2:$CX$102,MATCH(ROUND(Uzman_E!C$4,1),Tablo_E!$A$2:$A$102,1),MATCH(ROUND(K13,1),Tablo_E!$B$1:$CX$1,1))) -> 0.8 | N13: =IF(ISBLANK(M13),0,ABS(Uzman_E!D$4-M13)) -> 0 | O13: =IF(ISBLANK(M13),0,INDEX(Tablo_E!$B$2:$CX$102,MATCH(ROUND(Uzman_E!D$4,1),Tablo_E!$A$2:$A$102,1),MATCH(ROUND(N13,1),Tablo_E!$B$1:$CX$1,1))) -> 0 | Q13: =IF(ISBLANK(P13),0,ABS(Uzman_E!E$4-P13)) -> 0 | R13: =IF(ISBLANK(P13),0,INDEX(Tablo_E!$B$2:$CX$102,MATCH(ROUND(Uzman_E!B$4,1),Tablo_E!$A$2:$A$102,1),MATCH(ROUND(Q13,1),Tablo_E!$B$1:$CX$1,1))) -> 0 | S13: =(F13+I13+L13+O13+R13)/5 -> 0.16
A14: 11 | B14: =Hakemler!B14 -> 0 | C14: =Hakemler!C14 -> 0 | E14: =IF(ISBLANK(D14),0,ABS(Uzman_E!A$4-D14)) -> 0 | F14: =IF(ISBLANK(D14),0,INDEX(Tablo_E!$B$2:$CX$102,MATCH(ROUND(Uzman_E!A$4,1),Tablo_E!$A$2:$A$102,1),MATCH(ROUND(E14,1),Tablo_E!$B$1:$CX$1,1))) -> 0 | H14: =IF(ISBLANK(G14),0,ABS(Uzman_E!B$4-G14)) -> 0 | I14: =IF(ISBLANK(G14),0,INDEX(Tablo_E!$B$2:$CX$102,MATCH(ROUND(Uzman_E!B$4,1),Tablo_E!$A$2:$A$102,1),MATCH(ROUND(H14,1),Tablo_E!$B$1:$CX$1,1))) -> 0 | J14: 1.2 | K14: =IF(ISBLANK(J14),0,ABS(Uzman_E!C$4-J14)) -> 0.3 | L14: =IF(ISBLANK(J14),0,INDEX(Tablo_E!$B$2:$CX$102,MATCH(ROUND(Uzman_E!C$4,1),Tablo_E!$A$2:$A$102,1),MATCH(ROUND(K14,1),Tablo_E!$B$1:$CX$1,1))) -> 0.9 | N14: =IF(ISBLANK(M14),0,ABS(Uzman_E!D$4-M14)) -> 0 | O14: =IF(ISBLANK(M14),0,INDEX(Tablo_E!$B$2:$CX$102,MATCH(ROUND(Uzman_E!D$4,1),Tablo_E!$A$2:$A$102,1),MATCH(ROUND(N14,1),Tablo_E!$B$1:$CX$1,1))) -> 0 | Q14: =IF(ISBLANK(P14),0,ABS(Uzman_E!E$4-P14)) -> 0 | R14: =IF(ISBLANK(P14),0,INDEX(Tablo_E!$B$2:$CX$102,MATCH(ROUND(Uzman_E!B$4,1),Tablo_E!$A$2:$A$102,1),MATCH(ROUND(Q14,1),Tablo_E!$B$1:$CX$1,1))) -> 0 | S14: =(F14+I14+L14+O14+R14)/5 -> 0.18
A15: 12 | B15: =Hakemler!B15 -> 0 | C15: =Hakemler!C15 -> 0 | E15: =IF(ISBLANK(D15),0,ABS(Uzman_E!A$4-D15)) -> 0 | F15: =IF(ISBLANK(D15),0,INDEX(Tablo_E!$B$2:$CX$102,MATCH(ROUND(Uzman_E!A$4,1),Tablo_E!$A$2:$A$102,1),MATCH(ROUND(E15,1),Tablo_E!$B$1:$CX$1,1))) -> 0 | H15: =IF(ISBLANK(G15),0,ABS(Uzman_E!B$4-G15)) -> 0 | I15: =IF(ISBLANK(G15),0,INDEX(Tablo_E!$B$2:$CX$102,MATCH(ROUND(Uzman_E!B$4,1),Tablo_E!$A$2:$A$102,1),MATCH(ROUND(H15,1),Tablo_E!$B$1:$CX$1,1))) -> 0 | J15: 1.3 | K15: =IF(ISBLANK(J15),0,ABS(Uzman_E!C$4-J15)) -> 0.2 | L15: =IF(ISBLANK(J15),0,INDEX(Tablo_E!$B$2:$CX$102,MATCH(ROUND(Uzman_E!C$4,1),Tablo_E!$A$2:$A$102,1),MATCH(ROUND(K15,1),Tablo_E!$B$1:$CX$1,1))) -> 1 | M15: 1.6 | N15: =IF(ISBLANK(M15),0,ABS(Uzman_E!D$4-M15)) -> 0.3 | O15: =IF(ISBLANK(M15),0,INDEX(Tablo_E!$B$2:$CX$102,MATCH(ROUND(Uzman_E!D$4,1),Tablo_E!$A$2:$A$102,1),MATCH(ROUND(N15,1),Tablo_E!$B$1:$CX$1,1))) -> 0.9 | Q15: =IF(ISBLANK(P15),0,ABS(Uzman_E!E$4-P15)) -> 0 | R15: =IF(ISBLANK(P15),0,INDEX(Tablo_E!$B$2:$CX$102,MATCH(ROUND(Uzman_E!B$4,1),Tablo_E!$A$2:$A$102,1),MATCH(ROUND(Q15,1),Tablo_E!$B$1:$CX$1,1))) -> 0 | S15: =(F15+I15+L15+O15+R15)/5 -> 0.38
A16: 13 | B16: =Hakemler!B16 -> 0 | C16: =Hakemler!C16 -> 0 | E16: =IF(ISBLANK(D16),0,ABS(Uzman_E!A$4-D16)) -> 0 | F16: =IF(ISBLANK(D16),0,INDEX(Tablo_E!$B$2:$CX$102,MATCH(ROUND(Uzman_E!A$4,1),Tablo_E!$A$2:$A$102,1),MATCH(ROUND(E16,1),Tablo_E!$B$1:$CX$1,1))) -> 0 | H16: =IF(ISBLANK(G16),0,ABS(Uzman_E!B$4-G16)) -> 0 | I16: =IF(ISBLANK(G16),0,INDEX(Tablo_E!$B$2:$CX$102,MATCH(ROUND(Uzman_E!B$4,1),Tablo_E!$A$2:$A$102,1),MATCH(ROUND(H16,1),Tablo_E!$B$1:$CX$1,1))) -> 0 | K16: =IF(ISBLANK(J16),0,ABS(Uzman_E!C$4-J16)) -> 0 | L16: =IF(ISBLANK(J16),0,INDEX(Tablo_E!$B$2:$CX$102,MATCH(ROUND(Uzman_E!C$4,1),Tablo_E!$A$2:$A$102,1),MATCH(ROUND(K16,1),Tablo_E!$B$1:$CX$1,1))) -> 0 | M16: 1.5 | N16: =IF(ISBLANK(M16),0,ABS(Uzman_E!D$4-M16)) -> 0.2 | O16: =IF(ISBLANK(M16),0,INDEX(Tablo_E!$B$2:$CX$102,MATCH(ROUND(Uzman_E!D$4,1),Tablo_E!$A$2:$A$102,1),MATCH(ROUND(N16,1),Tablo_E!$B$1:$CX$1,1))) -> 1 | Q16: =IF(ISBLANK(P16),0,ABS(Uzman_E!E$4-P16)) -> 0 | R16: =IF(ISBLANK(P16),0,INDEX(Tablo_E!$B$2:$CX$102,MATCH(ROUND(Uzman_E!B$4,1),Tablo_E!$A$2:$A$102,1),MATCH(ROUND(Q16,1),Tablo_E!$B$1:$CX$1,1))) -> 0 | S16: =(F16+I16+L16+O16+R16)/5 -> 0.2
A17: 14 | B17: =Hakemler!B17 -> 0 | C17: =Hakemler!C17 -> 0 | E17: =IF(ISBLANK(D17),0,ABS(Uzman_E!A$4-D17)) -> 0 | F17: =IF(ISBLANK(D17),0,INDEX(Tablo_E!$B$2:$CX$102,MATCH(ROUND(Uzman_E!A$4,1),Tablo_E!$A$2:$A$102,1),MATCH(ROUND(E17,1),Tablo_E!$B$1:$CX$1,1))) -> 0 | H17: =IF(ISBLANK(G17),0,ABS(Uzman_E!B$4-G17)) -> 0 | I17: =IF(ISBLANK(G17),0,INDEX(Tablo_E!$B$2:$CX$102,MATCH(ROUND(Uzman_E!B$4,1),Tablo_E!$A$2:$A$102,1),MATCH(ROUND(H17,1),Tablo_E!$B$1:$CX$1,1))) -> 0 | K17: =IF(ISBLANK(J17),0,ABS(Uzman_E!C$4-J17)) -> 0 | L17: =IF(ISBLANK(J17),0,INDEX(Tablo_E!$B$2:$CX$102,MATCH(ROUND(Uzman_E!C$4,1),Tablo_E!$A$2:$A$102,1),MATCH(ROUND(K17,1),Tablo_E!$B$1:$CX$1,1))) -> 0 | M17: 1.4 | N17: =IF(ISBLANK(M17),0,ABS(Uzman_E!D$4-M17)) -> 0.1 | O17: =IF(ISBLANK(M17),0,INDEX(Tablo_E!$B$2:$CX$102,MATCH(ROUND(Uzman_E!D$4,1),Tablo_E!$A$2:$A$102,1),MATCH(ROUND(N17,1),Tablo_E!$B$1:$CX$1,1))) -> 1 | Q17: =IF(ISBLANK(P17),0,ABS(Uzman_E!E$4-P17)) -> 0 | R17: =IF(ISBLANK(P17),0,INDEX(Tablo_E!$B$2:$CX$102,MATCH(ROUND(Uzman_E!B$4,1),Tablo_E!$A$2:$A$102,1),MATCH(ROUND(Q17,1),Tablo_E!$B$1:$CX$1,1))) -> 0 | S17: =(F17+I17+L17+O17+R17)/5 -> 0.2
A18: 15 | B18: =Hakemler!B18 -> 0 | C18: =Hakemler!C18 -> 0 | E18: =IF(ISBLANK(D18),0,ABS(Uzman_E!A$4-D18)) -> 0 | F18: =IF(ISBLANK(D18),0,INDEX(Tablo_E!$B$2:$CX$102,MATCH(ROUND(Uzman_E!A$4,1),Tablo_E!$A$2:$A$102,1),MATCH(ROUND(E18,1),Tablo_E!$B$1:$CX$1,1))) -> 0 | H18: =IF(ISBLANK(G18),0,ABS(Uzman_E!B$4-G18)) -> 0 | I18: =IF(ISBLANK(G18),0,INDEX(Tablo_E!$B$2:$CX$102,MATCH(ROUND(Uzman_E!B$4,1),Tablo_E!$A$2:$A$102,1),MATCH(ROUND(H18,1),Tablo_E!$B$1:$CX$1,1))) -> 0 | K18: =IF(ISBLANK(J18),0,ABS(Uzman_E!C$4-J18)) -> 0 | L18: =IF(ISBLANK(J18),0,INDEX(Tablo_E!$B$2:$CX$102,MATCH(ROUND(Uzman_E!C$4,1),Tablo_E!$A$2:$A$102,1),MATCH(ROUND(K18,1),Tablo_E!$B$1:$CX$1,1))) -> 0 | M18: 1.3 | N18: =IF(ISBLANK(M18),0,ABS(Uzman_E!D$4-M18)) -> 0 | O18: =IF(ISBLANK(M18),0,INDEX(Tablo_E!$B$2:$CX$102,MATCH(ROUND(Uzman_E!D$4,1),Tablo_E!$A$2:$A$102,1),MATCH(ROUND(N18,1),Tablo_E!$B$1:$CX$1,1))) -> 1 | Q18: =IF(ISBLANK(P18),0,ABS(Uzman_E!E$4-P18)) -> 0 | R18: =IF(ISBLANK(P18),0,INDEX(Tablo_E!$B$2:$CX$102,MATCH(ROUND(Uzman_E!B$4,1),Tablo_E!$A$2:$A$102,1),MATCH(ROUND(Q18,1),Tablo_E!$B$1:$CX$1,1))) -> 0 | S18: =(F18+I18+L18+O18+R18)/5 -> 0.2
A19: 16 | B19: =Hakemler!B19 -> 0 | C19: =Hakemler!C19 -> 0 | E19: =IF(ISBLANK(D19),0,ABS(Uzman_E!A$4-D19)) -> 0 | F19: =IF(ISBLANK(D19),0,INDEX(Tablo_E!$B$2:$CX$102,MATCH(ROUND(Uzman_E!A$4,1),Tablo_E!$A$2:$A$102,1),MATCH(ROUND(E19,1),Tablo_E!$B$1:$CX$1,1))) -> 0 | H19: =IF(ISBLANK(G19),0,ABS(Uzman_E!B$4-G19)) -> 0 | I19: =IF(ISBLANK(G19),0,INDEX(Tablo_E!$B$2:$CX$102,MATCH(ROUND(Uzman_E!B$4,1),Tablo_E!$A$2:$A$102,1),MATCH(ROUND(H19,1),Tablo_E!$B$1:$CX$1,1))) -> 0 | K19: =IF(ISBLANK(J19),0,ABS(Uzman_E!C$4-J19)) -> 0 | L19: =IF(ISBLANK(J19),0,INDEX(Tablo_E!$B$2:$CX$102,MATCH(ROUND(Uzman_E!C$4,1),Tablo_E!$A$2:$A$102,1),MATCH(ROUND(K19,1),Tablo_E!$B$1:$CX$1,1))) -> 0 | M19: 1.2 | N19: =IF(ISBLANK(M19),0,ABS(Uzman_E!D$4-M19)) -> 0.1 | O19: =IF(ISBLANK(M19),0,INDEX(Tablo_E!$B$2:$CX$102,MATCH(ROUND(Uzman_E!D$4,1),Tablo_E!$A$2:$A$102,1),MATCH(ROUND(N19,1),Tablo_E!$B$1:$CX$1,1))) -> 1 | Q19: =IF(ISBLANK(P19),0,ABS(Uzman_E!E$4-P19)) -> 0 | R19: =IF(ISBLANK(P19),0,INDEX(Tablo_E!$B$2:$CX$102,MATCH(ROUND(Uzman_E!B$4,1),Tablo_E!$A$2:$A$102,1),MATCH(ROUND(Q19,1),Tablo_E!$B$1:$CX$1,1))) -> 0 | S19: =(F19+I19+L19+O19+R19)/5 -> 0.2
A20: 17 | B20: =Hakemler!B20 -> 0 | C20: =Hakemler!C20 -> 0 | E20: =IF(ISBLANK(D20),0,ABS(Uzman_E!A$4-D20)) -> 0 | F20: =IF(ISBLANK(D20),0,INDEX(Tablo_E!$B$2:$CX$102,MATCH(ROUND(Uzman_E!A$4,1),Tablo_E!$A$2:$A$102,1),MATCH(ROUND(E20,1),Tablo_E!$B$1:$CX$1,1))) -> 0 | H20: =IF(ISBLANK(G20),0,ABS(Uzman_E!B$4-G20)) -> 0 | I20: =IF(ISBLANK(G20),0,INDEX(Tablo_E!$B$2:$CX$102,MATCH(ROUND(Uzman_E!B$4,1),Tablo_E!$A$2:$A$102,1),MATCH(ROUND(H20,1),Tablo_E!$B$1:$CX$1,1))) -> 0 | K20: =IF(ISBLANK(J20),0,ABS(Uzman_E!C$4-J20)) -> 0 | L20: =IF(ISBLANK(J20),0,INDEX(Tablo_E!$B$2:$CX$102,MATCH(ROUND(Uzman_E!C$4,1),Tablo_E!$A$2:$A$102,1),MATCH(ROUND(K20,1),Tablo_E!$B$1:$CX$1,1))) -> 0 | M20: 1.1 | N20: =IF(ISBLANK(M20),0,ABS(Uzman_E!D$4-M20)) -> 0.2 | O20: =IF(ISBLANK(M20),0,INDEX(Tablo_E!$B$2:$CX$102,MATCH(ROUND(Uzman_E!D$4,1),Tablo_E!$A$2:$A$102,1),MATCH(ROUND(N20,1),Tablo_E!$B$1:$CX$1,1))) -> 1 | Q20: =IF(ISBLANK(P20),0,ABS(Uzman_E!E$4-P20)) -> 0 | R20: =IF(ISBLANK(P20),0,INDEX(Tablo_E!$B$2:$CX$102,MATCH(ROUND(Uzman_E!B$4,1),Tablo_E!$A$2:$A$102,1),MATCH(ROUND(Q20,1),Tablo_E!$B$1:$CX$1,1))) -> 0 | S20: =(F20+I20+L20+O20+R20)/5 -> 0.2
A21: 18 | B21: =Hakemler!B21 -> 0 | C21: =Hakemler!C21 -> 0 | E21: =IF(ISBLANK(D21),0,ABS(Uzman_E!A$4-D21)) -> 0 | F21: =IF(ISBLANK(D21),0,INDEX(Tablo_E!$B$2:$CX$102,MATCH(ROUND(Uzman_E!A$4,1),Tablo_E!$A$2:$A$102,1),MATCH(ROUND(E21,1),Tablo_E!$B$1:$CX$1,1))) -> 0 | H21: =IF(ISBLANK(G21),0,ABS(Uzman_E!B$4-G21)) -> 0 | I21: =IF(ISBLANK(G21),0,INDEX(Tablo_E!$B$2:$CX$102,MATCH(ROUND(Uzman_E!B$4,1),Tablo_E!$A$2:$A$102,1),MATCH(ROUND(H21,1),Tablo_E!$B$1:$CX$1,1))) -> 0 | K21: =IF(ISBLANK(J21),0,ABS(Uzman_E!C$4-J21)) -> 0 | L21: =IF(ISBLANK(J21),0,INDEX(Tablo_E!$B$2:$CX$102,MATCH(ROUND(Uzman_E!C$4,1),Tablo_E!$A$2:$A$102,1),MATCH(ROUND(K21,1),Tablo_E!$B$1:$CX$1,1))) -> 0 | M21: 1 | N21: =IF(ISBLANK(M21),0,ABS(Uzman_E!D$4-M21)) -> 0.3 | O21: =IF(ISBLANK(M21),0,INDEX(Tablo_E!$B$2:$CX$102,MATCH(ROUND(Uzman_E!D$4,1),Tablo_E!$A$2:$A$102,1),MATCH(ROUND(N21,1),Tablo_E!$B$1:$CX$1,1))) -> 0.9 | Q21: =IF(ISBLANK(P21),0,ABS(Uzman_E!E$4-P21)) -> 0 | R21: =IF(ISBLANK(P21),0,INDEX(Tablo_E!$B$2:$CX$102,MATCH(ROUND(Uzman_E!B$4,1),Tablo_E!$A$2:$A$102,1),MATCH(ROUND(Q21,1),Tablo_E!$B$1:$CX$1,1))) -> 0 | S21: =(F21+I21+L21+O21+R21)/5 -> 0.18
A22: 19 | B22: =Hakemler!B22 -> 0 | C22: =Hakemler!C22 -> 0 | E22: =IF(ISBLANK(D22),0,ABS(Uzman_E!A$4-D22)) -> 0 | F22: =IF(ISBLANK(D22),0,INDEX(Tablo_E!$B$2:$CX$102,MATCH(ROUND(Uzman_E!A$4,1),Tablo_E!$A$2:$A$102,1),MATCH(ROUND(E22,1),Tablo_E!$B$1:$CX$1,1))) -> 0 | H22: =IF(ISBLANK(G22),0,ABS(Uzman_E!B$4-G22)) -> 0 | I22: =IF(ISBLANK(G22),0,INDEX(Tablo_E!$B$2:$CX$102,MATCH(ROUND(Uzman_E!B$4,1),Tablo_E!$A$2:$A$102,1),MATCH(ROUND(H22,1),Tablo_E!$B$1:$CX$1,1))) -> 0 | K22: =IF(ISBLANK(J22),0,ABS(Uzman_E!C$4-J22)) -> 0 | L22: =IF(ISBLANK(J22),0,INDEX(Tablo_E!$B$2:$CX$102,MATCH(ROUND(Uzman_E!C$4,1),Tablo_E!$A$2:$A$102,1),MATCH(ROUND(K22,1),Tablo_E!$B$1:$CX$1,1))) -> 0 | N22: =IF(ISBLANK(M22),0,ABS(Uzman_E!D$4-M22)) -> 0 | O22: =IF(ISBLANK(M22),0,INDEX(Tablo_E!$B$2:$CX$102,MATCH(ROUND(Uzman_E!D$4,1),Tablo_E!$A$2:$A$102,1),MATCH(ROUND(N22,1),Tablo_E!$B$1:$CX$1,1))) -> 0 | Q22: =IF(ISBLANK(P22),0,ABS(Uzman_E!E$4-P22)) -> 0 | R22: =IF(ISBLANK(P22),0,INDEX(Tablo_E!$B$2:$CX$102,MATCH(ROUND(Uzman_E!B$4,1),Tablo_E!$A$2:$A$102,1),MATCH(ROUND(Q22,1),Tablo_E!$B$1:$CX$1,1))) -> 0 | S22: =(F22+I22+L22+O22+R22)/5 -> 0
A23: 20 | B23: =Hakemler!B23 -> 0 | C23: =Hakemler!C23 -> 0 | E23: =IF(ISBLANK(D23),0,ABS(Uzman_E!A$4-D23)) -> 0 | F23: =IF(ISBLANK(D23),0,INDEX(Tablo_E!$B$2:$CX$102,MATCH(ROUND(Uzman_E!A$4,1),Tablo_E!$A$2:$A$102,1),MATCH(ROUND(E23,1),Tablo_E!$B$1:$CX$1,1))) -> 0 | H23: =IF(ISBLANK(G23),0,ABS(Uzman_E!B$4-G23)) -> 0 | I23: =IF(ISBLANK(G23),0,INDEX(Tablo_E!$B$2:$CX$102,MATCH(ROUND(Uzman_E!B$4,1),Tablo_E!$A$2:$A$102,1),MATCH(ROUND(H23,1),Tablo_E!$B$1:$CX$1,1))) -> 0 | K23: =IF(ISBLANK(J23),0,ABS(Uzman_E!C$4-J23)) -> 0 | L23: =IF(ISBLANK(J23),0,INDEX(Tablo_E!$B$2:$CX$102,MATCH(ROUND(Uzman_E!C$4,1),Tablo_E!$A$2:$A$102,1),MATCH(ROUND(K23,1),Tablo_E!$B$1:$CX$1,1))) -> 0 | N23: =IF(ISBLANK(M23),0,ABS(Uzman_E!D$4-M23)) -> 0 | O23: =IF(ISBLANK(M23),0,INDEX(Tablo_E!$B$2:$CX$102,MATCH(ROUND(Uzman_E!D$4,1),Tablo_E!$A$2:$A$102,1),MATCH(ROUND(N23,1),Tablo_E!$B$1:$CX$1,1))) -> 0 | Q23: =IF(ISBLANK(P23),0,ABS(Uzman_E!E$4-P23)) -> 0 | R23: =IF(ISBLANK(P23),0,INDEX(Tablo_E!$B$2:$CX$102,MATCH(ROUND(Uzman_E!B$4,1),Tablo_E!$A$2:$A$102,1),MATCH(ROUND(Q23,1),Tablo_E!$B$1:$CX$1,1))) -> 0 | S23: =(F23+I23+L23+O23+R23)/5 -> 0
A24: 21 | B24: =Hakemler!B24 -> 0 | C24: =Hakemler!C24 -> 0 | E24: =IF(ISBLANK(D24),0,ABS(Uzman_E!A$4-D24)) -> 0 | F24: =IF(ISBLANK(D24),0,INDEX(Tablo_E!$B$2:$CX$102,MATCH(ROUND(Uzman_E!A$4,1),Tablo_E!$A$2:$A$102,1),MATCH(ROUND(E24,1),Tablo_E!$B$1:$CX$1,1))) -> 0 | H24: =IF(ISBLANK(G24),0,ABS(Uzman_E!B$4-G24)) -> 0 | I24: =IF(ISBLANK(G24),0,INDEX(Tablo_E!$B$2:$CX$102,MATCH(ROUND(Uzman_E!B$4,1),Tablo_E!$A$2:$A$102,1),MATCH(ROUND(H24,1),Tablo_E!$B$1:$CX$1,1))) -> 0 | K24: =IF(ISBLANK(J24),0,ABS(Uzman_E!C$4-J24)) -> 0 | L24: =IF(ISBLANK(J24),0,INDEX(Tablo_E!$B$2:$CX$102,MATCH(ROUND(Uzman_E!C$4,1),Tablo_E!$A$2:$A$102,1),MATCH(ROUND(K24,1),Tablo_E!$B$1:$CX$1,1))) -> 0 | N24: =IF(ISBLANK(M24),0,ABS(Uzman_E!D$4-M24)) -> 0 | O24: =IF(ISBLANK(M24),0,INDEX(Tablo_E!$B$2:$CX$102,MATCH(ROUND(Uzman_E!D$4,1),Tablo_E!$A$2:$A$102,1),MATCH(ROUND(N24,1),Tablo_E!$B$1:$CX$1,1))) -> 0 | Q24: =IF(ISBLANK(P24),0,ABS(Uzman_E!E$4-P24)) -> 0 | R24: =IF(ISBLANK(P24),0,INDEX(Tablo_E!$B$2:$CX$102,MATCH(ROUND(Uzman_E!B$4,1),Tablo_E!$A$2:$A$102,1),MATCH(ROUND(Q24,1),Tablo_E!$B$1:$CX$1,1))) -> 0 | S24: =(F24+I24+L24+O24+R24)/5 -> 0
A25: 22 | B25: =Hakemler!B25 -> 0 | C25: =Hakemler!C25 -> 0 | E25: =IF(ISBLANK(D25),0,ABS(Uzman_E!A$4-D25)) -> 0 | F25: =IF(ISBLANK(D25),0,INDEX(Tablo_E!$B$2:$CX$102,MATCH(ROUND(Uzman_E!A$4,1),Tablo_E!$A$2:$A$102,1),MATCH(ROUND(E25,1),Tablo_E!$B$1:$CX$1,1))) -> 0 | H25: =IF(ISBLANK(G25),0,ABS(Uzman_E!B$4-G25)) -> 0 | I25: =IF(ISBLANK(G25),0,INDEX(Tablo_E!$B$2:$CX$102,MATCH(ROUND(Uzman_E!B$4,1),Tablo_E!$A$2:$A$102,1),MATCH(ROUND(H25,1),Tablo_E!$B$1:$CX$1,1))) -> 0 | K25: =IF(ISBLANK(J25),0,ABS(Uzman_E!C$4-J25)) -> 0 | L25: =IF(ISBLANK(J25),0,INDEX(Tablo_E!$B$2:$CX$102,MATCH(ROUND(Uzman_E!C$4,1),Tablo_E!$A$2:$A$102,1),MATCH(ROUND(K25,1),Tablo_E!$B$1:$CX$1,1))) -> 0 | N25: =IF(ISBLANK(M25),0,ABS(Uzman_E!D$4-M25)) -> 0 | O25: =IF(ISBLANK(M25),0,INDEX(Tablo_E!$B$2:$CX$102,MATCH(ROUND(Uzman_E!D$4,1),Tablo_E!$A$2:$A$102,1),MATCH(ROUND(N25,1),Tablo_E!$B$1:$CX$1,1))) -> 0 | Q25: =IF(ISBLANK(P25),0,ABS(Uzman_E!E$4-P25)) -> 0 | R25: =IF(ISBLANK(P25),0,INDEX(Tablo_E!$B$2:$CX$102,MATCH(ROUND(Uzman_E!B$4,1),Tablo_E!$A$2:$A$102,1),MATCH(ROUND(Q25,1),Tablo_E!$B$1:$CX$1,1))) -> 0 | S25: =(F25+I25+L25+O25+R25)/5 -> 0
A26: 23 | B26: =Hakemler!B26 -> 0 | C26: =Hakemler!C26 -> 0 | E26: =IF(ISBLANK(D26),0,ABS(Uzman_E!A$4-D26)) -> 0 | F26: =IF(ISBLANK(D26),0,INDEX(Tablo_E!$B$2:$CX$102,MATCH(ROUND(Uzman_E!A$4,1),Tablo_E!$A$2:$A$102,1),MATCH(ROUND(E26,1),Tablo_E!$B$1:$CX$1,1))) -> 0 | H26: =IF(ISBLANK(G26),0,ABS(Uzman_E!B$4-G26)) -> 0 | I26: =IF(ISBLANK(G26),0,INDEX(Tablo_E!$B$2:$CX$102,MATCH(ROUND(Uzman_E!B$4,1),Tablo_E!$A$2:$A$102,1),MATCH(ROUND(H26,1),Tablo_E!$B$1:$CX$1,1))) -> 0 | K26: =IF(ISBLANK(J26),0,ABS(Uzman_E!C$4-J26)) -> 0 | L26: =IF(ISBLANK(J26),0,INDEX(Tablo_E!$B$2:$CX$102,MATCH(ROUND(Uzman_E!C$4,1),Tablo_E!$A$2:$A$102,1),MATCH(ROUND(K26,1),Tablo_E!$B$1:$CX$1,1))) -> 0 | N26: =IF(ISBLANK(M26),0,ABS(Uzman_E!D$4-M26)) -> 0 | O26: =IF(ISBLANK(M26),0,INDEX(Tablo_E!$B$2:$CX$102,MATCH(ROUND(Uzman_E!D$4,1),Tablo_E!$A$2:$A$102,1),MATCH(ROUND(N26,1),Tablo_E!$B$1:$CX$1,1))) -> 0 | Q26: =IF(ISBLANK(P26),0,ABS(Uzman_E!E$4-P26)) -> 0 | R26: =IF(ISBLANK(P26),0,INDEX(Tablo_E!$B$2:$CX$102,MATCH(ROUND(Uzman_E!B$4,1),Tablo_E!$A$2:$A$102,1),MATCH(ROUND(Q26,1),Tablo_E!$B$1:$CX$1,1))) -> 0 | S26: =(F26+I26+L26+O26+R26)/5 -> 0
A27: 24 | B27: =Hakemler!B27 -> 0 | C27: =Hakemler!C27 -> 0 | E27: =IF(ISBLANK(D27),0,ABS(Uzman_E!A$4-D27)) -> 0 | F27: =IF(ISBLANK(D27),0,INDEX(Tablo_E!$B$2:$CX$102,MATCH(ROUND(Uzman_E!A$4,1),Tablo_E!$A$2:$A$102,1),MATCH(ROUND(E27,1),Tablo_E!$B$1:$CX$1,1))) -> 0 | H27: =IF(ISBLANK(G27),0,ABS(Uzman_E!B$4-G27)) -> 0 | I27: =IF(ISBLANK(G27),0,INDEX(Tablo_E!$B$2:$CX$102,MATCH(ROUND(Uzman_E!B$4,1),Tablo_E!$A$2:$A$102,1),MATCH(ROUND(H27,1),Tablo_E!$B$1:$CX$1,1))) -> 0 | K27: =IF(ISBLANK(J27),0,ABS(Uzman_E!C$4-J27)) -> 0 | L27: =IF(ISBLANK(J27),0,INDEX(Tablo_E!$B$2:$CX$102,MATCH(ROUND(Uzman_E!C$4,1),Tablo_E!$A$2:$A$102,1),MATCH(ROUND(K27,1),Tablo_E!$B$1:$CX$1,1))) -> 0 | N27: =IF(ISBLANK(M27),0,ABS(Uzman_E!D$4-M27)) -> 0 | O27: =IF(ISBLANK(M27),0,INDEX(Tablo_E!$B$2:$CX$102,MATCH(ROUND(Uzman_E!D$4,1),Tablo_E!$A$2:$A$102,1),MATCH(ROUND(N27,1),Tablo_E!$B$1:$CX$1,1))) -> 0 | Q27: =IF(ISBLANK(P27),0,ABS(Uzman_E!E$4-P27)) -> 0 | R27: =IF(ISBLANK(P27),0,INDEX(Tablo_E!$B$2:$CX$102,MATCH(ROUND(Uzman_E!B$4,1),Tablo_E!$A$2:$A$102,1),MATCH(ROUND(Q27,1),Tablo_E!$B$1:$CX$1,1))) -> 0 | S27: =(F27+I27+L27+O27+R27)/5 -> 0
A28: 25 | B28: =Hakemler!B28 -> 0 | C28: =Hakemler!C28 -> 0 | E28: =IF(ISBLANK(D28),0,ABS(Uzman_E!A$4-D28)) -> 0 | F28: =IF(ISBLANK(D28),0,INDEX(Tablo_E!$B$2:$CX$102,MATCH(ROUND(Uzman_E!A$4,1),Tablo_E!$A$2:$A$102,1),MATCH(ROUND(E28,1),Tablo_E!$B$1:$CX$1,1))) -> 0 | H28: =IF(ISBLANK(G28),0,ABS(Uzman_E!B$4-G28)) -> 0 | I28: =IF(ISBLANK(G28),0,INDEX(Tablo_E!$B$2:$CX$102,MATCH(ROUND(Uzman_E!B$4,1),Tablo_E!$A$2:$A$102,1),MATCH(ROUND(H28,1),Tablo_E!$B$1:$CX$1,1))) -> 0 | K28: =IF(ISBLANK(J28),0,ABS(Uzman_E!C$4-J28)) -> 0 | L28: =IF(ISBLANK(J28),0,INDEX(Tablo_E!$B$2:$CX$102,MATCH(ROUND(Uzman_E!C$4,1),Tablo_E!$A$2:$A$102,1),MATCH(ROUND(K28,1),Tablo_E!$B$1:$CX$1,1))) -> 0 | N28: =IF(ISBLANK(M28),0,ABS(Uzman_E!D$4-M28)) -> 0 | O28: =IF(ISBLANK(M28),0,INDEX(Tablo_E!$B$2:$CX$102,MATCH(ROUND(Uzman_E!D$4,1),Tablo_E!$A$2:$A$102,1),MATCH(ROUND(N28,1),Tablo_E!$B$1:$CX$1,1))) -> 0 | Q28: =IF(ISBLANK(P28),0,ABS(Uzman_E!E$4-P28)) -> 0 | R28: =IF(ISBLANK(P28),0,INDEX(Tablo_E!$B$2:$CX$102,MATCH(ROUND(Uzman_E!B$4,1),Tablo_E!$A$2:$A$102,1),MATCH(ROUND(Q28,1),Tablo_E!$B$1:$CX$1,1))) -> 0 | S28: =(F28+I28+L28+O28+R28)/5 -> 0
A29: 26 | B29: =Hakemler!B29 -> 0 | C29: =Hakemler!C29 -> 0 | E29: =IF(ISBLANK(D29),0,ABS(Uzman_E!A$4-D29)) -> 0 | F29: =IF(ISBLANK(D29),0,INDEX(Tablo_E!$B$2:$CX$102,MATCH(ROUND(Uzman_E!A$4,1),Tablo_E!$A$2:$A$102,1),MATCH(ROUND(E29,1),Tablo_E!$B$1:$CX$1,1))) -> 0 | H29: =IF(ISBLANK(G29),0,ABS(Uzman_E!B$4-G29)) -> 0 | I29: =IF(ISBLANK(G29),0,INDEX(Tablo_E!$B$2:$CX$102,MATCH(ROUND(Uzman_E!B$4,1),Tablo_E!$A$2:$A$102,1),MATCH(ROUND(H29,1),Tablo_E!$B$1:$CX$1,1))) -> 0 | K29: =IF(ISBLANK(J29),0,ABS(Uzman_E!C$4-J29)) -> 0 | L29: =IF(ISBLANK(J29),0,INDEX(Tablo_E!$B$2:$CX$102,MATCH(ROUND(Uzman_E!C$4,1),Tablo_E!$A$2:$A$102,1),MATCH(ROUND(K29,1),Tablo_E!$B$1:$CX$1,1))) -> 0 | N29: =IF(ISBLANK(M29),0,ABS(Uzman_E!D$4-M29)) -> 0 | O29: =IF(ISBLANK(M29),0,INDEX(Tablo_E!$B$2:$CX$102,MATCH(ROUND(Uzman_E!D$4,1),Tablo_E!$A$2:$A$102,1),MATCH(ROUND(N29,1),Tablo_E!$B$1:$CX$1,1))) -> 0 | Q29: =IF(ISBLANK(P29),0,ABS(Uzman_E!E$4-P29)) -> 0 | R29: =IF(ISBLANK(P29),0,INDEX(Tablo_E!$B$2:$CX$102,MATCH(ROUND(Uzman_E!B$4,1),Tablo_E!$A$2:$A$102,1),MATCH(ROUND(Q29,1),Tablo_E!$B$1:$CX$1,1))) -> 0 | S29: =(F29+I29+L29+O29+R29)/5 -> 0
A30: 27 | B30: =Hakemler!B30 -> 0 | C30: =Hakemler!C30 -> 0 | E30: =IF(ISBLANK(D30),0,ABS(Uzman_E!A$4-D30)) -> 0 | F30: =IF(ISBLANK(D30),0,INDEX(Tablo_E!$B$2:$CX$102,MATCH(ROUND(Uzman_E!A$4,1),Tablo_E!$A$2:$A$102,1),MATCH(ROUND(E30,1),Tablo_E!$B$1:$CX$1,1))) -> 0 | H30: =IF(ISBLANK(G30),0,ABS(Uzman_E!B$4-G30)) -> 0 | I30: =IF(ISBLANK(G30),0,INDEX(Tablo_E!$B$2:$CX$102,MATCH(ROUND(Uzman_E!B$4,1),Tablo_E!$A$2:$A$102,1),MATCH(ROUND(H30,1),Tablo_E!$B$1:$CX$1,1))) -> 0 | K30: =IF(ISBLANK(J30),0,ABS(Uzman_E!C$4-J30)) -> 0 | L30: =IF(ISBLANK(J30),0,INDEX(Tablo_E!$B$2:$CX$102,MATCH(ROUND(Uzman_E!C$4,1),Tablo_E!$A$2:$A$102,1),MATCH(ROUND(K30,1),Tablo_E!$B$1:$CX$1,1))) -> 0 | N30: =IF(ISBLANK(M30),0,ABS(Uzman_E!D$4-M30)) -> 0 | O30: =IF(ISBLANK(M30),0,INDEX(Tablo_E!$B$2:$CX$102,MATCH(ROUND(Uzman_E!D$4,1),Tablo_E!$A$2:$A$102,1),MATCH(ROUND(N30,1),Tablo_E!$B$1:$CX$1,1))) -> 0 | Q30: =IF(ISBLANK(P30),0,ABS(Uzman_E!E$4-P30)) -> 0 | R30: =IF(ISBLANK(P30),0,INDEX(Tablo_E!$B$2:$CX$102,MATCH(ROUND(Uzman_E!B$4,1),Tablo_E!$A$2:$A$102,1),MATCH(ROUND(Q30,1),Tablo_E!$B$1:$CX$1,1))) -> 0 | S30: =(F30+I30+L30+O30+R30)/5 -> 0
A31: 28 | B31: =Hakemler!B31 -> 0 | C31: =Hakemler!C31 -> 0 | E31: =IF(ISBLANK(D31),0,ABS(Uzman_E!A$4-D31)) -> 0 | F31: =IF(ISBLANK(D31),0,INDEX(Tablo_E!$B$2:$CX$102,MATCH(ROUND(Uzman_E!A$4,1),Tablo_E!$A$2:$A$102,1),MATCH(ROUND(E31,1),Tablo_E!$B$1:$CX$1,1))) -> 0 | H31: =IF(ISBLANK(G31),0,ABS(Uzman_E!B$4-G31)) -> 0 | I31: =IF(ISBLANK(G31),0,INDEX(Tablo_E!$B$2:$CX$102,MATCH(ROUND(Uzman_E!B$4,1),Tablo_E!$A$2:$A$102,1),MATCH(ROUND(H31,1),Tablo_E!$B$1:$CX$1,1))) -> 0 | K31: =IF(ISBLANK(J31),0,ABS(Uzman_E!C$4-J31)) -> 0 | L31: =IF(ISBLANK(J31),0,INDEX(Tablo_E!$B$2:$CX$102,MATCH(ROUND(Uzman_E!C$4,1),Tablo_E!$A$2:$A$102,1),MATCH(ROUND(K31,1),Tablo_E!$B$1:$CX$1,1))) -> 0 | N31: =IF(ISBLANK(M31),0,ABS(Uzman_E!D$4-M31)) -> 0 | O31: =IF(ISBLANK(M31),0,INDEX(Tablo_E!$B$2:$CX$102,MATCH(ROUND(Uzman_E!D$4,1),Tablo_E!$A$2:$A$102,1),MATCH(ROUND(N31,1),Tablo_E!$B$1:$CX$1,1))) -> 0 | Q31: =IF(ISBLANK(P31),0,ABS(Uzman_E!E$4-P31)) -> 0 | R31: =IF(ISBLANK(P31),0,INDEX(Tablo_E!$B$2:$CX$102,MATCH(ROUND(Uzman_E!B$4,1),Tablo_E!$A$2:$A$102,1),MATCH(ROUND(Q31,1),Tablo_E!$B$1:$CX$1,1))) -> 0 | S31: =(F31+I31+L31+O31+R31)/5 -> 0
A32: 29 | B32: =Hakemler!B32 -> 0 | C32: =Hakemler!C32 -> 0 | E32: =IF(ISBLANK(D32),0,ABS(Uzman_E!A$4-D32)) -> 0 | F32: =IF(ISBLANK(D32),0,INDEX(Tablo_E!$B$2:$CX$102,MATCH(ROUND(Uzman_E!A$4,1),Tablo_E!$A$2:$A$102,1),MATCH(ROUND(E32,1),Tablo_E!$B$1:$CX$1,1))) -> 0 | H32: =IF(ISBLANK(G32),0,ABS(Uzman_E!B$4-G32)) -> 0 | I32: =IF(ISBLANK(G32),0,INDEX(Tablo_E!$B$2:$CX$102,MATCH(ROUND(Uzman_E!B$4,1),Tablo_E!$A$2:$A$102,1),MATCH(ROUND(H32,1),Tablo_E!$B$1:$CX$1,1))) -> 0 | K32: =IF(ISBLANK(J32),0,ABS(Uzman_E!C$4-J32)) -> 0 | L32: =IF(ISBLANK(J32),0,INDEX(Tablo_E!$B$2:$CX$102,MATCH(ROUND(Uzman_E!C$4,1),Tablo_E!$A$2:$A$102,1),MATCH(ROUND(K32,1),Tablo_E!$B$1:$CX$1,1))) -> 0 | N32: =IF(ISBLANK(M32),0,ABS(Uzman_E!D$4-M32)) -> 0 | O32: =IF(ISBLANK(M32),0,INDEX(Tablo_E!$B$2:$CX$102,MATCH(ROUND(Uzman_E!D$4,1),Tablo_E!$A$2:$A$102,1),MATCH(ROUND(N32,1),Tablo_E!$B$1:$CX$1,1))) -> 0 | Q32: =IF(ISBLANK(P32),0,ABS(Uzman_E!E$4-P32)) -> 0 | R32: =IF(ISBLANK(P32),0,INDEX(Tablo_E!$B$2:$CX$102,MATCH(ROUND(Uzman_E!B$4,1),Tablo_E!$A$2:$A$102,1),MATCH(ROUND(Q32,1),Tablo_E!$B$1:$CX$1,1))) -> 0 | S32: =(F32+I32+L32+O32+R32)/5 -> 0
A33: 30 | B33: =Hakemler!B33 -> 0 | C33: =Hakemler!C33 -> 0 | E33: =IF(ISBLANK(D33),0,ABS(Uzman_E!A$4-D33)) -> 0 | F33: =IF(ISBLANK(D33),0,INDEX(Tablo_E!$B$2:$CX$102,MATCH(ROUND(Uzman_E!A$4,1),Tablo_E!$A$2:$A$102,1),MATCH(ROUND(E33,1),Tablo_E!$B$1:$CX$1,1))) -> 0 | H33: =IF(ISBLANK(G33),0,ABS(Uzman_E!B$4-G33)) -> 0 | I33: =IF(ISBLANK(G33),0,INDEX(Tablo_E!$B$2:$CX$102,MATCH(ROUND(Uzman_E!B$4,1),Tablo_E!$A$2:$A$102,1),MATCH(ROUND(H33,1),Tablo_E!$B$1:$CX$1,1))) -> 0 | K33: =IF(ISBLANK(J33),0,ABS(Uzman_E!C$4-J33)) -> 0 | L33: =IF(ISBLANK(J33),0,INDEX(Tablo_E!$B$2:$CX$102,MATCH(ROUND(Uzman_E!C$4,1),Tablo_E!$A$2:$A$102,1),MATCH(ROUND(K33,1),Tablo_E!$B$1:$CX$1,1))) -> 0 | N33: =IF(ISBLANK(M33),0,ABS(Uzman_E!D$4-M33)) -> 0 | O33: =IF(ISBLANK(M33),0,INDEX(Tablo_E!$B$2:$CX$102,MATCH(ROUND(Uzman_E!D$4,1),Tablo_E!$A$2:$A$102,1),MATCH(ROUND(N33,1),Tablo_E!$B$1:$CX$1,1))) -> 0 | Q33: =IF(ISBLANK(P33),0,ABS(Uzman_E!E$4-P33)) -> 0 | R33: =IF(ISBLANK(P33),0,INDEX(Tablo_E!$B$2:$CX$102,MATCH(ROUND(Uzman_E!B$4,1),Tablo_E!$A$2:$A$102,1),MATCH(ROUND(Q33,1),Tablo_E!$B$1:$CX$1,1))) -> 0 | S33: =(F33+I33+L33+O33+R33)/5 -> 0
... A103: 100 | B103: =Hakemler!B103 -> 0 | C103: =Hakemler!C103 -> 0 | E103: =IF(ISBLANK(D103),0,ABS(Uzman_E!A$4-D103)) -> 0 | F103: =IF(ISBLANK(D103),0,INDEX(Tablo_E!$B$2:$CX$102,MATCH(ROUND(Uzman_E!A$4,1),Tablo_E!$A$2:$A$102,1),MATCH(ROUND(E103,1),Tablo_E!$B$1:$CX$1,1))) -> 0 | H103: =IF(ISBLANK(G103),0,ABS(Uzman_E!B$4-G103)) -> 0 | I103: =IF(ISBLANK(G103),0,INDEX(Tablo_E!$B$2:$CX$102,MATCH(ROUND(Uzman_E!B$4,1),Tablo_E!$A$2:$A$102,1),MATCH(ROUND(H103,1),Tablo_E!$B$1:$CX$1,1))) -> 0 | K103: =IF(ISBLANK(J103),0,ABS(Uzman_E!C$4-J103)) -> 0 | L103: =IF(ISBLANK(J103),0,INDEX(Tablo_E!$B$2:$CX$102,MATCH(ROUND(Uzman_E!C$4,1),Tablo_E!$A$2:$A$102,1),MATCH(ROUND(K103,1),Tablo_E!$B$1:$CX$1,1))) -> 0 | N103: =IF(ISBLANK(M103),0,ABS(Uzman_E!D$4-M103)) -> 0 | O103: =IF(ISBLANK(M103),0,INDEX(Tablo_E!$B$2:$CX$102,MATCH(ROUND(Uzman_E!D$4,1),Tablo_E!$A$2:$A$102,1),MATCH(ROUND(N103,1),Tablo_E!$B$1:$CX$1,1))) -> 0 | Q103: =IF(ISBLANK(P103),0,ABS(Uzman_E!E$4-P103)) -> 0 | R103: =IF(ISBLANK(P103),0,INDEX(Tablo_E!$B$2:$CX$102,MATCH(ROUND(Uzman_E!B$4,1),Tablo_E!$A$2:$A$102,1),MATCH(ROUND(Q103,1),Tablo_E!$B$1:$CX$1,1))) -> 0 | S103: =(F103+I103+L103+O103+R103)/5 -> 0

Sheet KP_D
A1: KIZ PARALELI - D Puanı
A2: No. | B2: Soyadı | C2: Adı | D2: D1 | Q2: D2 | AD2: D3 | AQ2: D4 | BD2: D5
D3: A | E3: B | F3: C | G3: D | H3: E | I3: F | J3: G | K3: H | L3: I | M3: J | N3: KG | O3: BD | P3: P | Q3: A | R3: B | S3: C | T3: D | U3: E | V3: F | W3: G | X3: H | Y3: I | Z3: J | AA3: KG | AB3: BD | AC3: P | AD3: A | AE3: B | AF3: C | AG3: D | AH3: E | AI3: F | AJ3: G | AK3: H | AL3: I | AM3: J | AN3: KG | AO3: BD | AP3: P | AQ3: A | AR3: B | AS3: C | AT3: D | AU3: E | AV3: F | AW3: G | AX3: H | AY3: I | AZ3: J | BA3: KG | BB3: BD | BC3: P | BD3: A | BE3: B | BF3: C | BG3: D | BH3: E | BI3: F | BJ3: G | BK3: H | BL3: I | BM3: J | BN3: KG | BO3: BD | BP3: P | BQ3: Ortalama
A4: 1 | B4: =Hakemler!B4 -> Yalçıner | C4: =Hakemler!C4 -> Yunus Emre | D4: 0 | E4: 0 | F4: 0 | G4: 4 | H4: 2 | I4: 2 | J4: 0 | K4: 0 | L4: 0 | M4: 0 | N4: 2 | O4: 0.7 | P4: =1 - ( SUM( IF(D4-Uzman_D!$B$4<0, -(D4-Uzman_D!$B$4), D4-Uzman_D!$B$4)*0.1 + IF(E4-Uzman_D!$C$4<0, -(E4-Uzman_D!$C$4), E4-Uzman_D!$C$4)*0.1 + IF(F4-Uzman_D!$D$4<0, -(F4-Uzman_D!$D$4), F4-Uzman_D!$D$4)*0.1 + IF(G4-Uzman_D!$E$4<0, -(G4-Uzman_D!$E$4), G4-Uzman_D!$E$4)*0.1 + IF(H4-Uzman_D!$F$4<0, -(H4-Uzman_D!$F$4), H4-Uzman_D!$F$4)*0.1 + IF(I4-Uzman_D!$G$4<0, -(I4-Uzman_D!$G$4), I4-Uzman_D!$G$4)*0.1 + IF(J4-Uzman_D!$H$4<0, -(J4-Uzman_D!$H$4), J4-Uzman_D!$H$4)*0.1 + IF(K4-Uzman_D!$I$4<0, -(K4-Uzman_D!$I$4), K4-Uzman_D!$I$4)*0.1 + IF(L4-Uzman_D!$J$4<0, -(L4-Uzman_D!$J$4), L4-Uzman_D!$J$4)*0.1 ) + IF(ROUND((IF(N4-Uzman_D!$L$4<0, -(N4-Uzman_D!$L$4), N4-Uzman_D!$L$4)*2),0)/2 = IF(N4-Uzman_D!$L$4<0, -(N4-Uzman_D!$L$4), N4-Uzman_D!$L$4), (ROUND((IF(N4-Uzman_D!$L$4<0, -(N4-Uzman_D!$L$4), N4-Uzman_D!$L$4)*2),0)/1 * 0.1), 0) + IF(O4-Uzman_D!$M$4<0, -(O4-Uzman_D!$M$4), O4-Uzman_D!$M$4)*1 ) -> 1 | Q4: 0 | R4: 0 | S4: 0 | T4: 5 | U4: 3 | V4: 0 | W4: 0 | X4: 0 | Y4: 0 | Z4: 0 | AA4: 2 | AB4: 0.3 | AC4: =1 - ( SUM( IF(Q4-Uzman_D!$B$5<0, -(Q4-Uzman_D!$B$5), Q4-Uzman_D!$B$5)*0.1 + IF(R4-Uzman_D!$C$5<0, -(R4-Uzman_D!$C$5), R4-Uzman_D!$C$5)*0.1 + IF(S4-Uzman_D!$D$5<0, -(S4-Uzman_D!$D$5), S4-Uzman_D!$D$5)*0.1 + IF(T4-Uzman_D!$E$5<0, -(T4-Uzman_D!$E$5), T4-Uzman_D!$E$5)*0.1 + IF(U4-Uzman_D!$F$5<0, -(U4-Uzman_D!$F$5), U4-Uzman_D!$F$5)*0.1 + IF(V4-Uzman_D!$G$5<0, -(V4-Uzman_D!$G$5), V4-Uzman_D!$G$5)*0.1 + IF(W4-Uzman_D!$H$5<0, -(W4-Uzman_D!$H$5), W4-Uzman_D!$H$5)*0.1 + IF(X4-Uzman_D!$I$5<0, -(X4-Uzman_D!$I$5), X4-Uzman_D!$I$5)*0.1 + IF(Y4-Uzman_D!$J$5<0, -(Y4-Uzman_D!$J$5), Y4-Uzman_D!$J$5)*0.1 ) + IF(ROUND((IF(AA4-Uzman_D!$L$5<0, -(AA4-Uzman_D!$L$5), AA4-Uzman_D!$L$5)*2),0)/2 = IF(AA4-Uzman_D!$L$5<0, -(AA4-Uzman_D!$L$5), AA4-Uzman_D!$L$5), (ROUND((IF(AA4-Uzman_D!$L$5<0, -(AA4-Uzman_D!$L$5), AA4-Uzman_D!$L$5)*2),0)/1 * 0.1), 0) + IF(AB4-Uzman_D!$M$5<0, -(AB4-Uzman_D!$M$5), AB4-Uzman_D!$M$5)*1 ) -> 1 | AD4: 0 | AE4: 1 | AF4: 2 | AG4: 5 | AH4: 0 | AI4: 0 | AJ4: 0 | AK4: 0 | AL4: 0 | AM4: 0 | AN4: 2 | AO4: 0.4 | AP4: =1 - ( SUM( IF(AD4-Uzman_D!$B$6<0, -(AD4-Uzman_D!$B$6), AD4-Uzman_D!$B$6)*0.1 + IF(AE4-Uzman_D!$C$6<0, -(AE4-Uzman_D!$C$6), AE4-Uzman_D!$C$6)*0.1 + IF(AF4-Uzman_D!$D$6<0, -(AF4-Uzman_D!$D$6), AF4-Uzman_D!$D$6)*0.1 + IF(AG4-Uzman_D!$E$6<0, -(AG4-Uzman_D!$E$6), AG4-Uzman_D!$E$6)*0.1 + IF(AH4-Uzman_D!$F$6<0, -(AH4-Uzman_D!$F$6), AH4-Uzman_D!$F$6)*0.1 + IF(AI4-Uzman_D!$G$6<0, -(AI4-Uzman_D!$G$6), AI4-Uzman_D!$G$6)*0.1 + IF(AJ4-Uzman_D!$H$6<0, -(AJ4-Uzman_D!$H$6), AJ4-Uzman_D!$H$6)*0.1 + IF(AK4-Uzman_D!$I$6<0, -(AK4-Uzman_D!$I$6), AK4-Uzman_D!$I$6)*0.1 + IF(AL4-Uzman_D!$J$6<0, -(AL4-Uzman_D!$J$6), AL4-Uzman_D!$J$6)*0.1 ) + IF(ROUND((IF(AN4-Uzman_D!$L$6<0, -(AN4-Uzman_D!$L$6), AN4-Uzman_D!$L$6)*2),0)/2 = IF(AN4-Uzman_D!$L$6<0, -(AN4-Uzman_D!$L$6), AN4-Uzman_D!$L$6), (ROUND((IF(AN4-Uzman_D!$L$6<0, -(AN4-Uzman_D!$L$6), AN4-Uzman_D!$L$6)*2),0)/1 * 0.1), 0) + IF(AO4-Uzman_D!$M$6<0, -(AO4-Uzman_D!$M$6), AO4-Uzman_D!$M$6)*1 ) -> 1 | AQ4: 0 | AR4: 1 | AS4: 3 | AT4: 4 | AU4: 0 | AV4: 0 | AW4: 0 | AX4: 0 | AY4: 0 | AZ4: 0 | BA4: 2 | BB4: 0.3 | BC4: =1 - ( SUM( IF(AQ4-Uzman_D!$B$7<0, -(AQ4-Uzman_D!$B$7), AQ4-Uzman_D!$B$7)*0.1 + IF(AR4-Uzman_D!$C$7<0, -(AR4-Uzman_D!$C$7), AR4-Uzman_D!$C$7)*0.1 + IF(AS4-Uzman_D!$D$7<0, -(AS4-Uzman_D!$D$7), AS4-Uzman_D!$D$7)*0.1 + IF(AT4-Uzman_D!$E$7<0, -(AT4-Uzman_D!$E$7), AT4-Uzman_D!$E$7)*0.1 + IF(AU4-Uzman_D!$F$7<0, -(AU4-Uzman_D!$F$7), AU4-Uzman_D!$F$7)*0.1 + IF(AV4-Uzman_D!$G$7<0, -(AV4-Uzman_D!$G$7), AV4-Uzman_D!$G$7)*0.1 + IF(AW4-Uzman_D!$H$7<0, -(AW4-Uzman_D!$H$7), AW4-Uzman_D!$H$7)*0.1 + IF(AX4-Uzman_D!$I$7<0, -(AX4-Uzman_D!$I$7), AX4-Uzman_D!$I$7)*0.1 + IF(AY4-Uzman_D!$J$7<0, -(AY4-Uzman_D!$J$7), AY4-Uzman_D!$J$7)*0.1 ) + IF(ROUND((IF(BA4-Uzman_D!$L$7<0, -(BA4-Uzman_D!$L$7), BA4-Uzman_D!$L$7)*2),0)/2 = IF(BA4-Uzman_D!$L$7<0, -(BA4-Uzman_D!$L$7), BA4-Uzman_D!$L$7), (ROUND((IF(BA4-Uzman_D!$L$7<0, -(BA4-Uzman_D!$L$7), BA4-Uzman_D!$L$7)*2),0)/1 * 0.1), 0) + IF(BB4-Uzman_D!$M$7<0, -(BB4-Uzman_D!$M$7), BB4-Uzman_D!$M$7)*1 ) -> 1 | BD4: 0 | BE4: 4 | BF4: 2 | BG4: 2 | BH4: 0 | BI4: 0 | BJ4: 0 | BK4: 0 | BL4: 0 | BM4: 0 | BN4: 2 | BO4: 0 | BP4: =1 - ( SUM( IF(BD4-Uzman_D!$B$8<0, -(BD4-Uzman_D!$B$8), BD4-Uzman_D!$B$8)*0.1 + IF(BE4-Uzman_D!$C$8<0, -(BE4-Uzman_D!$C$8), BE4-Uzman_D!$C$8)*0.1 + IF(BF4-Uzman_D!$D$8<0, -(BF4-Uzman_D!$D$8), BF4-Uzman_D!$D$8)*0.1 + IF(BG4-Uzman_D!$E$8<0, -(BG4-Uzman_D!$E$8), BG4-Uzman_D!$E$8)*0.1 + IF(BH4-Uzman_D!$F$8<0, -(BH4-Uzman_D!$F$8), BH4-Uzman_D!$F$8)*0.1 + IF(BI4-Uzman_D!$G$8<0, -(BI4-Uzman_D!$G$8), BI4-Uzman_D!$G$8)*0.1 + IF(BJ4-Uzman_D!$H$8<0, -(BJ4-Uzman_D!$H$8), BJ4-Uzman_D!$H$8)*0.1 + IF(BK4-Uzman_D!$I$8<0, -(BK4-Uzman_D!$I$8), BK4-Uzman_D!$I$8)*0.1 + IF(BL4-Uzman_D!$J$8<0, -(BL4-Uzman_D!$J$8), BL4-Uzman_D!$J$8)*0.1 ) + IF(ROUND((IF(BN4-Uzman_D!$L$8<0, -(BN4-Uzman_D!$L$8), BN4-Uzman_D!$L$8)*2),0)/2 = IF(BN4-Uzman_D!$L$8<0, -(BN4-Uzman_D!$L$8), BN4-Uzman_D!$L$8), (ROUND((IF(BN4-Uzman_D!$L$8<0, -(BN4-Uzman_D!$L$8), BN4-Uzman_D!$L$8)*2),0)/1 * 0.1), 0) + IF(BO4-Uzman_D!$M$8<0, -(BO4-Uzman_D!$M$8), BO4-Uzman_D!$M$8)*1 ) -> 1 | BQ4: =(P4+AC4+AP4+BC4+BP4)/5 -> 1
A5: 2 | B5: =Hakemler!B5 -> Deneme | C5: =Hakemler!C5 -> Hakem | P5: =1 - ( SUM( IF(D5-Uzman_D!$B$4<0, -(D5-Uzman_D!$B$4), D5-Uzman_D!$B$4)*0.1 + IF(E5-Uzman_D!$C$4<0, -(E5-Uzman_D!$C$4), E5-Uzman_D!$C$4)*0.1 + IF(F5-Uzman_D!$D$4<0, -(F5-Uzman_D!$D$4), F5-Uzman_D!$D$4)*0.1 + IF(G5-Uzman_D!$E$4<0, -(G5-Uzman_D!$E$4), G5-Uzman_D!$E$4)*0.1 + IF(H5-Uzman_D!$F$4<0, -(H5-Uzman_D!$F$4), H5-Uzman_D!$F$4)*0.1 + IF(I5-Uzman_D!$G$4<0, -(I5-Uzman_D!$G$4), I5-Uzman_D!$G$4)*0.1 + IF(J5-Uzman_D!$H$4<0, -(J5-Uzman_D!$H$4), J5-Uzman_D!$H$4)*0.1 + IF(K5-Uzman_D!$I$4<0, -(K5-Uzman_D!$I$4), K5-Uzman_D!$I$4)*0.1 + IF(L5-Uzman_D!$J$4<0, -(L5-Uzman_D!$J$4), L5-Uzman_D!$J$4)*0.1 ) + IF(ROUND((IF(N5-Uzman_D!$L$4<0, -(N5-Uzman_D!$L$4), N5-Uzman_D!$L$4)*2),0)/2 = IF(N5-Uzman_D!$L$4<0, -(N5-Uzman_D!$L$4), N5-Uzman_D!$L$4), (ROUND((IF(N5-Uzman_D!$L$4<0, -(N5-Uzman_D!$L$4), N5-Uzman_D!$L$4)*2),0)/1 * 0.1), 0) + IF(O5-Uzman_D!$M$4<0, -(O5-Uzman_D!$M$4), O5-Uzman_D!$M$4)*1 ) -> -0.9 | AC5: =1 - ( SUM( IF(Q5-Uzman_D!$B$5<0, -(Q5-Uzman_D!$B$5), Q5-Uzman_D!$B$5)*0.1 + IF(R5-Uzman_D!$C$5<0, -(R5-Uzman_D!$C$5), R5-Uzman_D!$C$5)*0.1 + IF(S5-Uzman_D!$D$5<0, -(S5-Uzman_D!$D$5), S5-Uzman_D!$D$5)*0.1 + IF(T5-Uzman_D!$E$5<0, -(T5-Uzman_D!$E$5), T5-Uzman_D!$E$5)*0.1 + IF(U5-Uzman_D!$F$5<0, -(U5-Uzman_D!$F$5), U5-Uzman_D!$F$5)*0.1 + IF(V5-Uzman_D!$G$5<0, -(V5-Uzman_D!$G$5), V5-Uzman_D!$G$5)*0.1 + IF(W5-Uzman_D!$H$5<0, -(W5-Uzman_D!$H$5), W5-Uzman_D!$H$5)*0.1 + IF(X5-Uzman_D!$I$5<0, -(X5-Uzman_D!$I$5), X5-Uzman_D!$I$5)*0.1 + IF(Y5-Uzman_D!$J$5<0, -(Y5-Uzman_D!$J$5), Y5-Uzman_D!$J$5)*0.1 ) + IF(ROUND((IF(AA5-Uzman_D!$L$5<0, -(AA5-Uzman_D!$L$5), AA5-Uzman_D!$L$5)*2),0)/2 = IF(AA5-Uzman_D!$L$5<0, -(AA5-Uzman_D!$L$5), AA5-Uzman_D!$L$5), (ROUND((IF(AA5-Uzman_D!$L$5<0, -(AA5-Uzman_D!$L$5), AA5-Uzman_D!$L$5)*2),0)/1 * 0.1), 0) + IF(AB5-Uzman_D!$M$5<0, -(AB5-Uzman_D!$M$5), AB5-Uzman_D!$M$5)*1 ) -> -0.5 | AP5: =1 - ( SUM( IF(AD5-Uzman_D!$B$6<0, -(AD5-Uzman_D!$B$6), AD5-Uzman_D!$B$6)*0.1 + IF(AE5-Uzman_D!$C$6<0, -(AE5-Uzman_D!$C$6), AE5-Uzman_D!$C$6)*0.1 + IF(AF5-Uzman_D!$D$6<0, -(AF5-Uzman_D!$D$6), AF5-Uzman_D!$D$6)*0.1 + IF(AG5-Uzman_D!$E$6<0, -(AG5-Uzman_D!$E$6), AG5-Uzman_D!$E$6)*0.1 + IF(AH5-Uzman_D!$F$6<0, -(AH5-Uzman_D!$F$6), AH5-Uzman_D!$F$6)*0.1 + IF(AI5-Uzman_D!$G$6<0, -(AI5-Uzman_D!$G$6), AI5-Uzman_D!$G$6)*0.1 + IF(AJ5-Uzman_D!$H$6<0, -(AJ5-Uzman_D!$H$6), AJ5-Uzman_D!$H$6)*0.1 + IF(AK5-Uzman_D!$I$6<0, -(AK5-Uzman_D!$I$6), AK5-Uzman_D!$I$6)*0.1 + IF(AL5-Uzman_D!$J$6<0, -(AL5-Uzman_D!$J$6), AL5-Uzman_D!$J$6)*0.1 ) + IF(ROUND((IF(AN5-Uzman_D!$L$6<0, -(AN5-Uzman_D!$L$6), AN5-Uzman_D!$L$6)*2),0)/2 = IF(AN5-Uzman_D!$L$6<0, -(AN5-Uzman_D!$L$6), AN5-Uzman_D!$L$6), (ROUND((IF(AN5-Uzman_D!$L$6<0, -(AN5-Uzman_D!$L$6), AN5-Uzman_D!$L$6)*2),0)/1 * 0.1), 0) + IF(AO5-Uzman_D!$M$6<0, -(AO5-Uzman_D!$M$6), AO5-Uzman_D!$M$6)*1 ) -> -0.6 | BC5: =1 - ( SUM( IF(AQ5-Uzman_D!$B$7<0, -(AQ5-Uzman_D!$B$7), AQ5-Uzman_D!$B$7)*0.1 + IF(AR5-Uzman_D!$C$7<0, -(AR5-Uzman_D!$C$7), AR5-Uzman_D!$C$7)*0.1 + IF(AS5-Uzman_D!$D$7<0, -(AS5-Uzman_D!$D$7), AS5-Uzman_D!$D$7)*0.1 + IF(AT5-Uzman_D!$E$7<0, -(AT5-Uzman_D!$E$7), AT5-Uzman_D!$E$7)*0.1 + IF(AU5-Uzman_D!$F$7<0, -(AU5-Uzman_D!$F$7), AU5-Uzman_D!$F$7)*0.1 + IF(AV5-Uzman_D!$G$7<0, -(AV5-Uzman_D!$G$7), AV5-Uzman_D!$G$7)*0.1 + IF(AW5-Uzman_D!$H$7<0, -(AW5-Uzman_D!$H$7), AW5-Uzman_D!$H$7)*0.1 + IF(AX5-Uzman_D!$I$7<0, -(AX5-Uzman_D!$I$7), AX5-Uzman_D!$I$7)*0.1 + IF(AY5-Uzman_D!$J$7<0, -(AY5-Uzman_D!$J$7), AY5-Uzman_D!$J$7)*0.1 ) + IF(ROUND((IF(BA5-Uzman_D!$L$7<0, -(BA5-Uzman_D!$L$7), BA5-Uzman_D!$L$7)*2),0)/2 = IF(BA5-Uzman_D!$L$7<0, -(BA5-Uzman_D!$L$7), BA5-Uzman_D!$L$7), (ROUND((IF(BA5-Uzman_D!$L$7<0, -(BA5-Uzman_D!$L$7), BA5-Uzman_D!$L$7)*2),0)/1 * 0.1), 0) + IF(BB5-Uzman_D!$M$7<0, -(BB5-Uzman_D!$M$7), BB5-Uzman_D!$M$7)*1 ) -> -0.5 | BP5: =1 - ( SUM( IF(BD5-Uzman_D!$B$8<0, -(BD5-Uzman_D!$B$8), BD5-Uzman_D!$B$8)*0.1 + IF(BE5-Uzman_D!$C$8<0, -(BE5-Uzman_D!$C$8), BE5-Uzman_D!$C$8)*0.1 + IF(BF5-Uzman_D!$D$8<0, -(BF5-Uzman_D!$D$8), BF5-Uzman_D!$D$8)*0.1 + IF(BG5-Uzman_D!$E$8<0, -(BG5-Uzman_D!$E$8), BG5-Uzman_D!$E$8)*0.1 + IF(BH5-Uzman_D!$F$8<0, -(BH5-Uzman_D!$F$8), BH5-Uzman_D!$F$8)*0.1 + IF(BI5-Uzman_D!$G$8<0, -(BI5-Uzman_D!$G$8), BI5-Uzman_D!$G$8)*0.1 + IF(BJ5-Uzman_D!$H$8<0, -(BJ5-Uzman_D!$H$8), BJ5-Uzman_D!$H$8)*0.1 + IF(BK5-Uzman_D!$I$8<0, -(BK5-Uzman_D!$I$8), BK5-Uzman_D!$I$8)*0.1 + IF(BL5-Uzman_D!$J$8<0, -(BL5-Uzman_D!$J$8), BL5-Uzman_D!$J$8)*0.1 ) + IF(ROUND((IF(BN5-Uzman_D!$L$8<0, -(BN5-Uzman_D!$L$8), BN5-Uzman_D!$L$8)*2),0)/2 = IF(BN5-Uzman_D!$L$8<0, -(BN5-Uzman_D!$L$8), BN5-Uzman_D!$L$8), (ROUND((IF(BN5-Uzman_D!$L$8<0, -(BN5-Uzman_D!$L$8), BN5-Uzman_D!$L$8)*2),0)/1 * 0.1), 0) + IF(BO5-Uzman_D!$M$8<0, -(BO5-Uzman_D!$M$8), BO5-Uzman_D!$M$8)*1 ) -> -0.2 | BQ5: =(P5+AC5+AP5+BC5+BP5)/5 -> -0.54
A6: 3 | B6: =Hakemler!B6 -> 0 | C6: =Hakemler!C6 -> 0 | P6: =1 - ( SUM( IF(D6-Uzman_D!$B$4<0, -(D6-Uzman_D!$B$4), D6-Uzman_D!$B$4)*0.1 + IF(E6-Uzman_D!$C$4<0, -(E6-Uzman_D!$C$4), E6-Uzman_D!$C$4)*0.1 + IF(F6-Uzman_D!$D$4<0, -(F6-Uzman_D!$D$4), F6-Uzman_D!$D$4)*0.1 + IF(G6-Uzman_D!$E$4<0, -(G6-Uzman_D!$E$4), G6-Uzman_D!$E$4)*0.1 + IF(H6-Uzman_D!$F$4<0, -(H6-Uzman_D!$F$4), H6-Uzman_D!$F$4)*0.1 + IF(I6-Uzman_D!$G$4<0, -(I6-Uzman_D!$G$4), I6-Uzman_D!$G$4)*0.1 + IF(J6-Uzman_D!$H$4<0, -(J6-Uzman_D!$H$4), J6-Uzman_D!$H$4)*0.1 + IF(K6-Uzman_D!$I$4<0, -(K6-Uzman_D!$I$4), K6-Uzman_D!$I$4)*0.1 + IF(L6-Uzman_D!$J$4<0, -(L6-Uzman_D!$J$4), L6-Uzman_D!$J$4)*0.1 ) + IF(ROUND((IF(N6-Uzman_D!$L$4<0, -(N6-Uzman_D!$L$4), N6-Uzman_D!$L$4)*2),0)/2 = IF(N6-Uzman_D!$L$4<0, -(N6-Uzman_D!$L$4), N6-Uzman_D!$L$4), (ROUND((IF(N6-Uzman_D!$L$4<0, -(N6-Uzman_D!$L$4), N6-Uzman_D!$L$4)*2),0)/1 * 0.1), 0) + IF(O6-Uzman_D!$M$4<0, -(O6-Uzman_D!$M$4), O6-Uzman_D!$M$4)*1 ) -> -0.9 | AC6: =1 - ( SUM( IF(Q6-Uzman_D!$B$5<0, -(Q6-Uzman_D!$B$5), Q6-Uzman_D!$B$5)*0.1 + IF(R6-Uzman_D!$C$5<0, -(R6-Uzman_D!$C$5), R6-Uzman_D!$C$5)*0.1 + IF(S6-Uzman_D!$D$5<0, -(S6-Uzman_D!$D$5), S6-Uzman_D!$D$5)*0.1 + IF(T6-Uzman_D!$E$5<0, -(T6-Uzman_D!$E$5), T6-Uzman_D!$E$5)*0.1 + IF(U6-Uzman_D!$F$5<0, -(U6-Uzman_D!$F$5), U6-Uzman_D!$F$5)*0.1 + IF(V6-Uzman_D!$G$5<0, -(V6-Uzman_D!$G$5), V6-Uzman_D!$G$5)*0.1 + IF(W6-Uzman_D!$H$5<0, -(W6-Uzman_D!$H$5), W6-Uzman_D!$H$5)*0.1 + IF(X6-Uzman_D!$I$5<0, -(X6-Uzman_D!$I$5), X6-Uzman_D!$I$5)*0.1 + IF(Y6-Uzman_D!$J$5<0, -(Y6-Uzman_D!$J$5), Y6-Uzman_D!$J$5)*0.1 ) + IF(ROUND((IF(AA6-Uzman_D!$L$5<0, -(AA6-Uzman_D!$L$5), AA6-Uzman_D!$L$5)*2),0)/2 = IF(AA6-Uzman_D!$L$5<0, -(AA6-Uzman_D!$L$5), AA6-Uzman_D!$L$5), (ROUND((IF(AA6-Uzman_D!$L$5<0, -(AA6-Uzman_D!$L$5), AA6-Uzman_D!$L$5)*2),0)/1 * 0.1), 0) + IF(AB6-Uzman_D!$M$5<0, -(AB6-Uzman_D!$M$5), AB6-Uzman_D!$M$5)*1 ) -> -0.5 | AP6: =1 - ( SUM( IF(AD6-Uzman_D!$B$6<0, -(AD6-Uzman_D!$B$6), AD6-Uzman_D!$B$6)*0.1 + IF(AE6-Uzman_D!$C$6<0, -(AE6-Uzman_D!$C$6), AE6-Uzman_D!$C$6)*0.1 + IF(AF6-Uzman_D!$D$6<0, -(AF6-Uzman_D!$D$6), AF6-Uzman_D!$D$6)*0.1 + IF(AG6-Uzman_D!$E$6<0, -(AG6-Uzman_D!$E$6), AG6-Uzman_D!$E$6)*0.1 + IF(AH6-Uzman_D!$F$6<0, -(AH6-Uzman_D!$F$6), AH6-Uzman_D!$F$6)*0.1 + IF(AI6-Uzman_D!$G$6<0, -(AI6-Uzman_D!$G$6), AI6-Uzman_D!$G$6)*0.1 + IF(AJ6-Uzman_D!$H$6<0, -(AJ6-Uzman_D!$H$6), AJ6-Uzman_D!$H$6)*0.1 + IF(AK6-Uzman_D!$I$6<0, -(AK6-Uzman_D!$I$6), AK6-Uzman_D!$I$6)*0.1 + IF(AL6-Uzman_D!$J$6<0, -(AL6-Uzman_D!$J$6), AL6-Uzman_D!$J$6)*0.1 ) + IF(ROUND((IF(AN6-Uzman_D!$L$6<0, -(AN6-Uzman_D!$L$6), AN6-Uzman_D!$L$6)*2),0)/2 = IF(AN6-Uzman_D!$L$6<0, -(AN6-Uzman_D!$L$6), AN6-Uzman_D!$L$6), (ROUND((IF(AN6-Uzman_D!$L$6<0, -(AN6-Uzman_D!$L$6), AN6-Uzman_D!$L$6)*2),0)/1 * 0.1), 0) + IF(AO6-Uzman_D!$M$6<0, -(AO6-Uzman_D!$M$6), AO6-Uzman_D!$M$6)*1 ) -> -0.6 | BC6: =1 - ( SUM( IF(AQ6-Uzman_D!$B$7<0, -(AQ6-Uzman_D!$B$7), AQ6-Uzman_D!$B$7)*0.1 + IF(AR6-Uzman_D!$C$7<0, -(AR6-Uzman_D!$C$7), AR6-Uzman_D!$C$7)*0.1 + IF(AS6-Uzman_D!$D$7<0, -(AS6-Uzman_D!$D$7), AS6-Uzman_D!$D$7)*0.1 + IF(AT6-Uzman_D!$E$7<0, -(AT6-Uzman_D!$E$7), AT6-Uzman_D!$E$7)*0.1 + IF(AU6-Uzman_D!$F$7<0, -(AU6-Uzman_D!$F$7), AU6-Uzman_D!$F$7)*0.1 + IF(AV6-Uzman_D!$G$7<0, -(AV6-Uzman_D!$G$7), AV6-Uzman_D!$G$7)*0.1 + IF(AW6-Uzman_D!$H$7<0, -(AW6-Uzman_D!$H$7), AW6-Uzman_D!$H$7)*0.1 + IF(AX6-Uzman_D!$I$7<0, -(AX6-Uzman_D!$I$7), AX6-Uzman_D!$I$7)*0.1 + IF(AY6-Uzman_D!$J$7<0, -(AY6-Uzman_D!$J$7), AY6-Uzman_D!$J$7)*0.1 ) + IF(ROUND((IF(BA6-Uzman_D!$L$7<0, -(BA6-Uzman_D!$L$7), BA6-Uzman_D!$L$7)*2),0)/2 = IF(BA6-Uzman_D!$L$7<0, -(BA6-Uzman_D!$L$7), BA6-Uzman_D!$L$7), (ROUND((IF(BA6-Uzman_D!$L$7<0, -(BA6-Uzman_D!$L$7), BA6-Uzman_D!$L$7)*2),0)/1 * 0.1), 0) + IF(BB6-Uzman_D!$M$7<0, -(BB6-Uzman_D!$M$7), BB6-Uzman_D!$M$7)*1 ) -> -0.5 | BP6: =1 - ( SUM( IF(BD6-Uzman_D!$B$8<0, -(BD6-Uzman_D!$B$8), BD6-Uzman_D!$B$8)*0.1 + IF(BE6-Uzman_D!$C$8<0, -(BE6-Uzman_D!$C$8), BE6-Uzman_D!$C$8)*0.1 + IF(BF6-Uzman_D!$D$8<0, -(BF6-Uzman_D!$D$8), BF6-Uzman_D!$D$8)*0.1 + IF(BG6-Uzman_D!$E$8<0, -(BG6-Uzman_D!$E$8), BG6-Uzman_D!$E$8)*0.1 + IF(BH6-Uzman_D!$F$8<0, -(BH6-Uzman_D!$F$8), BH6-Uzman_D!$F$8)*0.1 + IF(BI6-Uzman_D!$G$8<0, -(BI6-Uzman_D!$G$8), BI6-Uzman_D!$G$8)*0.1 + IF(BJ6-Uzman_D!$H$8<0, -(BJ6-Uzman_D!$H$8), BJ6-Uzman_D!$H$8)*0.1 + IF(BK6-Uzman_D!$I$8<0, -(BK6-Uzman_D!$I$8), BK6-Uzman_D!$I$8)*0.1 + IF(BL6-Uzman_D!$J$8<0, -(BL6-Uzman_D!$J$8), BL6-Uzman_D!$J$8)*0.1 ) + IF(ROUND((IF(BN6-Uzman_D!$L$8<0, -(BN6-Uzman_D!$L$8), BN6-Uzman_D!$L$8)*2),0)/2 = IF(BN6-Uzman_D!$L$8<0, -(BN6-Uzman_D!$L$8), BN6-Uzman_D!$L$8), (ROUND((IF(BN6-Uzman_D!$L$8<0, -(BN6-Uzman_D!$L$8), BN6-Uzman_D!$L$8)*2),0)/1 * 0.1), 0) + IF(BO6-Uzman_D!$M$8<0, -(BO6-Uzman_D!$M$8), BO6-Uzman_D!$M$8)*1 ) -> -0.2 | BQ6: =(P6+AC6+AP6+BC6+BP6)/5 -> -0.54
