Workbook

Sheet Kurs
B2: TCF ACB Sınav Değerlendirme Sistemi (SDS) 2024
B6: Sınava Ait Bilgiler
B9: Kursu veren | C9: : | D9: Türkiye Cimnastik Federasyonu
B11: Eğitmen | C11: :
B13: Şehir | C13: : | D13: ANTALYA
B15: Tarih | C15: : | D15: 19-21.12.2024

Sheet Hakemler
A1: Hakemlere Ait Bilgiler
A3: No. | B3: Soyadı | C3: Adı | D3: Şehir | E3: 14. Dönem brövesi | F3: 15. Dönem brövesi
A4: 1 | B4: YAZICI | C4: SUZAN
A5: =A4+1 -> 2 | B5: ASLAN | C5: SEMA FİDEL
A6: =A5+1 -> 3 | B6: TUNA | C6: MUNİSE
A7: =A6+1 -> 4 | B7: ÜNAL | C7: FATMA HANIM
A8: =A7+1 -> 5 | B8: BAŞKAN PERÇİN | C8: ÖZGE
A9: =A8+1 -> 6 | B9: ŞEN İZMİRLİ | C9: SİNEM
A10: =A9+1 -> 7 | B10: YILDIRIMER | C10: BUSE
A11: =A10+1 -> 8 | B11: KESKİN | C11: ENFAL
A12: =A11+1 -> 9 | B12: ÜNAL | C12: NAZLINEHİR
A13: =A12+1 -> 10 | B13: ÜÇTAŞ ŞANLI | C13: GÖKSU
A14: =A13+1 -> 11 | B14: YÜCEL | C14: SİBEL
A15: =A14+1 -> 12 | B15: YILMAZER | C15: ZEHRA
A16: =A15+1 -> 13 | B16: ŞAHİNTEKİN | C16: MUHAMMED
... A49: =A48+1 -> 46 | B49: EDE | C49: İHSAN
A50: =A49+1 -> 47
A51: =A50+1 -> 48
A52: =A51+1 -> 49
A53: =A52+1 -> 50
A54: =A53+1 -> 51
A55: =A54+1 -> 52
A56: =A55+1 -> 53
A57: =A56+1 -> 54
A58: =A57+1 -> 55
A59: =A58+1 -> 56
A60: =A59+1 -> 57
A61: =A60+1 -> 58
... A103: =A102+1 -> 100

Sheet AtM_D
A1: ATLAMA MASASI - D Puanı
A2: No. | B2: Soyadı | C2: Adı | D2: D1 | F2: D2 | H2: D3 | J2: D4 | L2: D5 | N2: D6 | P2: D7 | R2: D8 | T2: D9 | V2: D10
D3: D1 | E3: P | F3: D2 | G3: P | H3: D3 | I3: P | J3: D4 | K3: P | L3: D5 | M3: P | N3: D5 | O3: P | P3: D5 | Q3: P | R3: D5 | S3: P | T3: D5 | U3: P | V3: D5 | W3: P | X3: Ortalama
A4: 1 | B4: =Hakemler!B4 -> YAZICI | C4: =Hakemler!C4 -> SUZAN | D4: 3.8 | E4: 1 | F4: 0 | G4: 1 | H4: 5 | I4: 1 | J4: 3.8 | K4: 1 | L4: 4.2 | M4: 1 | N4: 4.2 | O4: 1 | P4: 3.2 | Q4: 1 | R4: 5.8 | S4: 0 | T4: 4.2 | U4: 1 | V4: 4.6 | W4: 1 | X4: =(E4+G4+I4+K4+M4+O4+Q4+S4+U4+W4)/10 -> 0.9
A5: 2 | B5: =Hakemler!B5 -> ASLAN | C5: =Hakemler!C5 -> SEMA FİDEL | D5: 3.4 | E5: =IF(D5=Uzman_D!$B$24,1,0) -> 0 | F5: 0 | G5: =IF(F5=Uzman_D!$B$25,1,0) -> 1 | H5: 5 | I5: =IF(H5=Uzman_D!$B$26,1,0) -> 1 | J5: 3.8 | K5: =IF(J5=Uzman_D!$B$27,1,0) -> 1 | L5: 4.8 | M5: =IF(L5=Uzman_D!$B$28,1,0) -> 0 | N5: 4.2 | O5: =IF(N5=Uzman_D!$B$29,1,0) -> 1 | P5: 3.2 | Q5: =IF(P5=Uzman_D!$B$30,1,0) -> 1 | R5: 4.4 | S5: =IF(R5=Uzman_D!$B$31,1,0) -> 1 | T5: 4.2 | U5: =IF(T5=Uzman_D!$B$32,1,0) -> 1 | V5: 4.6 | W5: =IF(V5=Uzman_D!$B$33,1,0) -> 1 | X5: =(E5+G5+I5+K5+M5+O5+Q5+S5+U5+W5)/10 -> 0.8
A6: 3 | B6: =Hakemler!B6 -> TUNA | C6: =Hakemler!C6 -> MUNİSE | E6: =IF(D6=Uzman_D!$B$24,1,0) -> 0 | G6: =IF(F6=Uzman_D!$B$25,1,0) -> 1 | I6: =IF(H6=Uzman_D!$B$26,1,0) -> 0 | K6: =IF(J6=Uzman_D!$B$27,1,0) -> 0 | M6: =IF(L6=Uzman_D!$B$28,1,0) -> 0 | O6: =IF(N6=Uzman_D!$B$29,1,0) -> 0 | Q6: =IF(P6=Uzman_D!$B$30,1,0) -> 0 | S6: =IF(R6=Uzman_D!$B$31,1,0) -> 0 | U6: =IF(T6=Uzman_D!$B$32,1,0) -> 0 | W6: =IF(V6=Uzman_D!$B$33,1,0) -> 0 | X6: =(E6+G6+I6+K6+M6+O6+Q6+S6+U6+W6)/10 -> 0.1
A7: 4 | B7: =Hakemler!B7 -> ÜNAL | C7: =Hakemler!C7 -> FATMA HANIM | E7: =IF(D7=Uzman_D!$B$24,1,0) -> 0 | G7: =IF(F7=Uzman_D!$B$25,1,0) -> 1 | I7: =IF(H7=Uzman_D!$B$26,1,0) -> 0 | K7: =IF(J7=Uzman_D!$B$27,1,0) -> 0 | M7: =IF(L7=Uzman_D!$B$28,1,0) -> 0 | O7: =IF(N7=Uzman_D!$B$29,1,0) -> 0 | Q7: =IF(P7=Uzman_D!$B$30,1,0) -> 0 | S7: =IF(R7=Uzman_D!$B$31,1,0) -> 0 | U7: =IF(T7=Uzman_D!$B$32,1,0) -> 0 | W7: =IF(V7=Uzman_D!$B$33,1,0) -> 0 | X7: =(E7+G7+I7+K7+M7+O7+Q7+S7+U7+W7)/10 -> 0.1
A8: 5 | B8: =Hakemler!B8 -> BAŞKAN PERÇİN | C8: =Hakemler!C8 -> ÖZGE | E8: =IF(D8=Uzman_D!$B$24,1,0) -> 0 | G8: =IF(F8=Uzman_D!$B$25,1,0) -> 1 | I8: =IF(H8=Uzman_D!$B$26,1,0) -> 0 | K8: =IF(J8=Uzman_D!$B$27,1,0) -> 0 | M8: =IF(L8=Uzman_D!$B$28,1,0) -> 0 | O8: =IF(N8=Uzman_D!$B$29,1,0) -> 0 | Q8: =IF(P8=Uzman_D!$B$30,1,0) -> 0 | S8: =IF(R8=Uzman_D!$B$31,1,0) -> 0 | U8: =IF(T8=Uzman_D!$B$32,1,0) -> 0 | W8: =IF(V8=Uzman_D!$B$33,1,0) -> 0 | X8: =(E8+G8+I8+K8+M8+O8+Q8+S8+U8+W8)/10 -> 0.1
A9: 6 | B9: =Hakemler!B9 -> ŞEN İZMİRLİ | C9: =Hakemler!C9 -> SİNEM | E9: =IF(D9=Uzman_D!$B$24,1,0) -> 0 | G9: =IF(F9=Uzman_D!$B$25,1,0) -> 1 | I9: =IF(H9=Uzman_D!$B$26,1,0) -> 0 | K9: =IF(J9=Uzman_D!$B$27,1,0) -> 0 | M9: =IF(L9=Uzman_D!$B$28,1,0) -> 0 | O9: =IF(N9=Uzman_D!$B$29,1,0) -> 0 | Q9: =IF(P9=Uzman_D!$B$30,1,0) -> 0 | S9: =IF(R9=Uzman_D!$B$31,1,0) -> 0 | U9: =IF(T9=Uzman_D!$B$32,1,0) -> 0 | W9: =IF(V9=Uzman_D!$B$33,1,0) -> 0 | X9: =(E9+G9+I9+K9+M9+O9+Q9+S9+U9+W9)/10 -> 0.1
A10: 7 | B10: =Hakemler!B10 -> YILDIRIMER | C10: =Hakemler!C10 -> BUSE | E10: =IF(D10=Uzman_D!$B$24,1,0) -> 0 | G10: =IF(F10=Uzman_D!$B$25,1,0) -> 1 | I10: =IF(H10=Uzman_D!$B$26,1,0) -> 0 | K10: =IF(J10=Uzman_D!$B$27,1,0) -> 0 | M10: =IF(L10=Uzman_D!$B$28,1,0) -> 0 | O10: =IF(N10=Uzman_D!$B$29,1,0) -> 0 | Q10: =IF(P10=Uzman_D!$B$30,1,0) -> 0 | S10: =IF(R10=Uzman_D!$B$31,1,0) -> 0 | U10: =IF(T10=Uzman_D!$B$32,1,0) -> 0 | W10: =IF(V10=Uzman_D!$B$33,1,0) -> 0 | X10: =(E10+G10+I10+K10+M10+O10+Q10+S10+U10+W10)/10 -> 0.1
A11: 8 | B11: =Hakemler!B11 -> KESKİN | C11: =Hakemler!C11 -> ENFAL | E11: =IF(D11=Uzman_D!$B$24,1,0) -> 0 | G11: =IF(F11=Uzman_D!$B$25,1,0) -> 1 | I11: =IF(H11=Uzman_D!$B$26,1,0) -> 0 | K11: =IF(J11=Uzman_D!$B$27,1,0) -> 0 | M11: =IF(L11=Uzman_D!$B$28,1,0) -> 0 | O11: =IF(N11=Uzman_D!$B$29,1,0) -> 0 | Q11: =IF(P11=Uzman_D!$B$30,1,0) -> 0 | S11: =IF(R11=Uzman_D!$B$31,1,0) -> 0 | U11: =IF(T11=Uzman_D!$B$32,1,0) -> 0 | W11: =IF(V11=Uzman_D!$B$33,1,0) -> 0 | X11: =(E11+G11+I11+K11+M11+O11+Q11+S11+U11+W11)/10 -> 0.1
A12: 9 | B12: =Hakemler!B12 -> ÜNAL | C12: =Hakemler!C12 -> NAZLINEHİR | E12: =IF(D12=Uzman_D!$B$24,1,0) -> 0 | G12: =IF(F12=Uzman_D!$B$25,1,0) -> 1 | I12: =IF(H12=Uzman_D!$B$26,1,0) -> 0 | K12: =IF(J12=Uzman_D!$B$27,1,0) -> 0 | M12: =IF(L12=Uzman_D!$B$28,1,0) -> 0 | O12: =IF(N12=Uzman_D!$B$29,1,0) -> 0 | Q12: =IF(P12=Uzman_D!$B$30,1,0) -> 0 | S12: =IF(R12=Uzman_D!$B$31,1,0) -> 0 | U12: =IF(T12=Uzman_D!$B$32,1,0) -> 0 | W12: =IF(V12=Uzman_D!$B$33,1,0) -> 0 | X12: =(E12+G12+I12+K12+M12+O12+Q12+S12+U12+W12)/10 -> 0.1
A13: 10 | B13: =Hakemler!B13 -> ÜÇTAŞ ŞANLI | C13: =Hakemler!C13 -> GÖKSU | E13: =IF(D13=Uzman_D!$B$24,1,0) -> 0 | G13: =IF(F13=Uzman_D!$B$25,1,0) -> 1 | I13: =IF(H13=Uzman_D!$B$26,1,0) -> 0 | K13: =IF(J13=Uzman_D!$B$27,1,0) -> 0 | M13: =IF(L13=Uzman_D!$B$28,1,0) -> 0 | O13: =IF(N13=Uzman_D!$B$29,1,0) -> 0 | Q13: =IF(P13=Uzman_D!$B$30,1,0) -> 0 | S13: =IF(R13=Uzman_D!$B$31,1,0) -> 0 | U13: =IF(T13=Uzman_D!$B$32,1,0) -> 0 | W13: =IF(V13=Uzman_D!$B$33,1,0) -> 0 | X13: =(E13+G13+I13+K13+M13+O13+Q13+S13+U13+W13)/10 -> 0.1
A14: 11 | B14: =Hakemler!B14 -> YÜCEL | C14: =Hakemler!C14 -> SİBEL | E14: =IF(D14=Uzman_D!$B$24,1,0) -> 0 | G14: =IF(F14=Uzman_D!$B$25,1,0) -> 1 | I14: =IF(H14=Uzman_D!$B$26,1,0) -> 0 | K14: =IF(J14=Uzman_D!$B$27,1,0) -> 0 | M14: =IF(L14=Uzman_D!$B$28,1,0) -> 0 | O14: =IF(N14=Uzman_D!$B$29,1,0) -> 0 | Q14: =IF(P14=Uzman_D!$B$30,1,0) -> 0 | S14: =IF(R14=Uzman_D!$B$31,1,0) -> 0 | U14: =IF(T14=Uzman_D!$B$32,1,0) -> 0 | W14: =IF(V14=Uzman_D!$B$33,1,0) -> 0 | X14: =(E14+G14+I14+K14+M14+O14+Q14+S14+U14+W14)/10 -> 0.1
A15: 12 | B15: =Hakemler!B15 -> YILMAZER | C15: =Hakemler!C15 -> ZEHRA | E15: =IF(D15=Uzman_D!$B$24,1,0) -> 0 | G15: =IF(F15=Uzman_D!$B$25,1,0) -> 1 | I15: =IF(H15=Uzman_D!$B$26,1,0) -> 0 | K15: =IF(J15=Uzman_D!$B$27,1,0) -> 0 | M15: =IF(L15=Uzman_D!$B$28,1,0) -> 0 | O15: =IF(N15=Uzman_D!$B$29,1,0) -> 0 | Q15: =IF(P15=Uzman_D!$B$30,1,0) -> 0 | S15: =IF(R15=Uzman_D!$B$31,1,0) -> 0 | U15: =IF(T15=Uzman_D!$B$32,1,0) -> 0 | W15: =IF(V15=Uzman_D!$B$33,1,0) -> 0 | X15: =(E15+G15+I15+K15+M15+O15+Q15+S15+U15+W15)/10 -> 0.1
A16: 13 | B16: =Hakemler!B16 -> ŞAHİNTEKİN | C16: =Hakemler!C16 -> MUHAMMED | E16: =IF(D16=Uzman_D!$B$24,1,0) -> 0 | G16: =IF(F16=Uzman_D!$B$25,1,0) -> 1 | I16: =IF(H16=Uzman_D!$B$26,1,0) -> 0 | K16: =IF(J16=Uzman_D!$B$27,1,0) -> 0 | M16: =IF(L16=Uzman_D!$B$28,1,0) -> 0 | O16: =IF(N16=Uzman_D!$B$29,1,0) -> 0 | Q16: =IF(P16=Uzman_D!$B$30,1,0) -> 0 | S16: =IF(R16=Uzman_D!$B$31,1,0) -> 0 | U16: =IF(T16=Uzman_D!$B$32,1,0) -> 0 | W16: =IF(V16=Uzman_D!$B$33,1,0) -> 0 | X16: =(E16+G16+I16+K16+M16+O16+Q16+S16+U16+W16)/10 -> 0.1
A17: 14 | B17: =Hakemler!B17 -> ERKUT | C17: =Hakemler!C17 -> OYA | E17: =IF(D17=Uzman_D!$B$24,1,0) -> 0 | G17: =IF(F17=Uzman_D!$B$25,1,0) -> 1 | I17: =IF(H17=Uzman_D!$B$26,1,0) -> 0 | K17: =IF(J17=Uzman_D!$B$27,1,0) -> 0 | M17: =IF(L17=Uzman_D!$B$28,1,0) -> 0 | O17: =IF(N17=Uzman_D!$B$29,1,0) -> 0 | Q17: =IF(P17=Uzman_D!$B$30,1,0) -> 0 | S17: =IF(R17=Uzman_D!$B$31,1,0) -> 0 | U17: =IF(T17=Uzman_D!$B$32,1,0) -> 0 | W17: =IF(V17=Uzman_D!$B$33,1,0) -> 0 | X17: =(E17+G17+I17+K17+M17+O17+Q17+S17+U17+W17)/10 -> 0.1
... A23: 20 | B23: =Hakemler!B23 -> ÖNER AĞAN | C23: =Hakemler!C23 -> DERYA | E23: =IF(D23=Uzman_D!$B$24,1,0) -> 0 | G23: =IF(F23=Uzman_D!$B$25,1,0) -> 1 | I23: =IF(H23=Uzman_D!$B$26,1,0) -> 0 | K23: =IF(J23=Uzman_D!$B$27,1,0) -> 0 | M23: =IF(L23=Uzman_D!$B$28,1,0) -> 0 | O23: =IF(N23=Uzman_D!$B$29,1,0) -> 0 | Q23: =IF(P23=Uzman_D!$B$30,1,0) -> 0 | S23: =IF(R23=Uzman_D!$B$31,1,0) -> 0 | U23: =IF(T23=Uzman_D!$B$32,1,0) -> 0 | W23: =IF(V23=Uzman_D!$B$33,1,0) -> 0 | X23: =(E23+G23+I23+K23+M23+O23+Q23+S23+U23+W23)/10 -> 0.1
A24: 21 | B24: =Hakemler!B24 -> ABACI | C24: =Hakemler!C24 -> BUSE | D24: 3.4 | E24: =IF(D24=Uzman_D!$B$24,1,0) -> 0 | F24: 5 | G24: =IF(F24=Uzman_D!$B$25,1,0) -> 0 | H24: 4.2 | I24: =IF(H24=Uzman_D!$B$26,1,0) -> 0 | J24: 3.8 | K24: =IF(J24=Uzman_D!$B$27,1,0) -> 1 | L24: 4.6 | M24: =IF(L24=Uzman_D!$B$28,1,0) -> 0 | N24: 4.2 | O24: =IF(N24=Uzman_D!$B$29,1,0) -> 1 | P24: 3.2 | Q24: =IF(P24=Uzman_D!$B$30,1,0) -> 1 | R24: 4.4 | S24: =IF(R24=Uzman_D!$B$31,1,0) -> 1 | T24: 4.2 | U24: =IF(T24=Uzman_D!$B$32,1,0) -> 1 | V24: 3.8 | W24: =IF(V24=Uzman_D!$B$33,1,0) -> 0 | X24: =(E24+G24+I24+K24+M24+O24+Q24+S24+U24+W24)/10 -> 0.5
A25: 22 | B25: =Hakemler!B25 -> KARAKAŞ | C25: =Hakemler!C25 -> TAHİR | D25: 3.4 | E25: =IF(D25=Uzman_D!$B$24,1,0) -> 0 | F25: 0 | G25: =IF(F25=Uzman_D!$B$25,1,0) -> 1 | H25: 4.6 | I25: =IF(H25=Uzman_D!$B$26,1,0) -> 0 | J25: 3.8 | K25: =IF(J25=Uzman_D!$B$27,1,0) -> 1 | L25: 4.8 | M25: =IF(L25=Uzman_D!$B$28,1,0) -> 0 | N25: 4.2 | O25: =IF(N25=Uzman_D!$B$29,1,0) -> 1 | P25: 3.2 | Q25: =IF(P25=Uzman_D!$B$30,1,0) -> 1 | R25: 5 | S25: =IF(R25=Uzman_D!$B$31,1,0) -> 0 | T25: 4.4 | U25: =IF(T25=Uzman_D!$B$32,1,0) -> 0 | V25: 3.8 | W25: =IF(V25=Uzman_D!$B$33,1,0) -> 0 | X25: =(E25+G25+I25+K25+M25+O25+Q25+S25+U25+W25)/10 -> 0.4
A26: 23 | B26: =Hakemler!B26 -> SAVAŞ OK | C26: =Hakemler!C26 -> DİLAY | D26: 3.8 | E26: =IF(D26=Uzman_D!$B$24,1,0) -> 1 | F26: 4.8 | G26: =IF(F26=Uzman_D!$B$25,1,0) -> 0 | H26: 5.6 | I26: =IF(H26=Uzman_D!$B$26,1,0) -> 0 | J26: 3.8 | K26: =IF(J26=Uzman_D!$B$27,1,0) -> 1 | L26: 5.6 | M26: =IF(L26=Uzman_D!$B$28,1,0) -> 0 | N26: 4.2 | O26: =IF(N26=Uzman_D!$B$29,1,0) -> 1 | P26: 3.2 | Q26: =IF(P26=Uzman_D!$B$30,1,0) -> 1 | R26: 5.8 | S26: =IF(R26=Uzman_D!$B$31,1,0) -> 0 | T26: 4.2 | U26: =IF(T26=Uzman_D!$B$32,1,0) -> 1 | V26: 4.6 | W26: =IF(V26=Uzman_D!$B$33,1,0) -> 1 | X26: =(E26+G26+I26+K26+M26+O26+Q26+S26+U26+W26)/10 -> 0.6
A27: 24 | B27: =Hakemler!B27 -> AYDEMİR | C27: =Hakemler!C27 -> AYŞE DİLARA | D27: 5.2 | E27: =IF(D27=Uzman_D!$B$24,1,0) -> 0 | F27: 0 | G27: =IF(F27=Uzman_D!$B$25,1,0) -> 1 | H27: 5 | I27: =IF(H27=Uzman_D!$B$26,1,0) -> 1 | J27: 3.8 | K27: =IF(J27=Uzman_D!$B$27,1,0) -> 1 | L27: 5.6 | M27: =IF(L27=Uzman_D!$B$28,1,0) -> 0 | N27: 4.2 | O27: =IF(N27=Uzman_D!$B$29,1,0) -> 1 | P27: 3.2 | Q27: =IF(P27=Uzman_D!$B$30,1,0) -> 1 | R27: 4.4 | S27: =IF(R27=Uzman_D!$B$31,1,0) -> 1 | T27: 4.2 | U27: =IF(T27=Uzman_D!$B$32,1,0) -> 1 | V27: 4.6 | W27: =IF(V27=Uzman_D!$B$33,1,0) -> 1 | X27: =(E27+G27+I27+K27+M27+O27+Q27+S27+U27+W27)/10 -> 0.8
A28: 25 | B28: =Hakemler!B28 -> AKIN | C28: =Hakemler!C28 -> MANOLYA | D28: 3.4 | E28: =IF(D28=Uzman_D!$B$24,1,0) -> 0 | F28: 4.4 | G28: =IF(F28=Uzman_D!$B$25,1,0) -> 0 | H28: 4.2 | I28: =IF(H28=Uzman_D!$B$26,1,0) -> 0 | J28: 3.4 | K28: =IF(J28=Uzman_D!$B$27,1,0) -> 0 | L28: 5 | M28: =IF(L28=Uzman_D!$B$28,1,0) -> 0 | N28: 3.2 | O28: =IF(N28=Uzman_D!$B$29,1,0) -> 0 | P28: 3.2 | Q28: =IF(P28=Uzman_D!$B$30,1,0) -> 1 | R28: 4 | S28: =IF(R28=Uzman_D!$B$31,1,0) -> 0 | T28: 4.2 | U28: =IF(T28=Uzman_D!$B$32,1,0) -> 1 | V28: 5 | W28: =IF(V28=Uzman_D!$B$33,1,0) -> 0 | X28: =(E28+G28+I28+K28+M28+O28+Q28+S28+U28+W28)/10 -> 0.2
A29: 26 | B29: =Hakemler!B29 -> PINAR | C29: =Hakemler!C29 -> YELİZ | D29: 4.4 | E29: =IF(D29=Uzman_D!$B$24,1,0) -> 0 | F29: 4.6 | G29: =IF(F29=Uzman_D!$B$25,1,0) -> 0 | H29: 5 | I29: =IF(H29=Uzman_D!$B$26,1,0) -> 1 | J29: 3.8 | K29: =IF(J29=Uzman_D!$B$27,1,0) -> 1 | L29: 4.2 | M29: =IF(L29=Uzman_D!$B$28,1,0) -> 1 | N29: 4.2 | O29: =IF(N29=Uzman_D!$B$29,1,0) -> 1 | P29: 3.2 | Q29: =IF(P29=Uzman_D!$B$30,1,0) -> 1 | R29: 5 | S29: =IF(R29=Uzman_D!$B$31,1,0) -> 0 | T29: 4.2 | U29: =IF(T29=Uzman_D!$B$32,1,0) -> 1 | V29: 5 | W29: =IF(V29=Uzman_D!$B$33,1,0) -> 0 | X29: =(E29+G29+I29+K29+M29+O29+Q29+S29+U29+W29)/10 -> 0.6
A30: 27 | B30: =Hakemler!B30 -> KATRANCI | C30: =Hakemler!C30 -> AYŞEN | D30: 3.4 | E30: =IF(D30=Uzman_D!$B$24,1,0) -> 0 | F30: 0 | G30: =IF(F30=Uzman_D!$B$25,1,0) -> 1 | H30: 5 | I30: =IF(H30=Uzman_D!$B$26,1,0) -> 1 | J30: 3.8 | K30: =IF(J30=Uzman_D!$B$27,1,0) -> 1 | L30: 4.8 | M30: =IF(L30=Uzman_D!$B$28,1,0) -> 0 | N30: 4.2 | O30: =IF(N30=Uzman_D!$B$29,1,0) -> 1 | P30: 3.6 | Q30: =IF(P30=Uzman_D!$B$30,1,0) -> 0 | R30: 4.4 | S30: =IF(R30=Uzman_D!$B$31,1,0) -> 1 | T30: 4.2 | U30: =IF(T30=Uzman_D!$B$32,1,0) -> 1 | V30: 4.6 | W30: =IF(V30=Uzman_D!$B$33,1,0) -> 1 | X30: =(E30+G30+I30+K30+M30+O30+Q30+S30+U30+W30)/10 -> 0.7
A31: 28 | B31: =Hakemler!B31 -> GÜRKAN KİRAZ | C31: =Hakemler!C31 -> FULYA | D31: 3.4 | E31: =IF(D31=Uzman_D!$B$24,1,0) -> 0 | F31: 3.6 | G31: =IF(F31=Uzman_D!$B$25,1,0) -> 0 | H31: 4.2 | I31: =IF(H31=Uzman_D!$B$26,1,0) -> 0 | J31: 3.8 | K31: =IF(J31=Uzman_D!$B$27,1,0) -> 1 | L31: 4.8 | M31: =IF(L31=Uzman_D!$B$28,1,0) -> 0 | N31: 5.6 | O31: =IF(N31=Uzman_D!$B$29,1,0) -> 0 | P31: 4.2 | Q31: =IF(P31=Uzman_D!$B$30,1,0) -> 0 | R31: 5.8 | S31: =IF(R31=Uzman_D!$B$31,1,0) -> 0 | T31: 4.2 | U31: =IF(T31=Uzman_D!$B$32,1,0) -> 1 | V31: 3.6 | W31: =IF(V31=Uzman_D!$B$33,1,0) -> 0 | X31: =(E31+G31+I31+K31+M31+O31+Q31+S31+U31+W31)/10 -> 0.2
A32: 29 | B32: =Hakemler!B32 -> KILIÇ | C32: =Hakemler!C32 -> AYŞE | D32: 4.4 | E32: =IF(D32=Uzman_D!$B$24,1,0) -> 0 | F32: 3.8 | G32: =IF(F32=Uzman_D!$B$25,1,0) -> 0 | H32: 4.6 | I32: =IF(H32=Uzman_D!$B$26,1,0) -> 0 | J32: 4.6 | K32: =IF(J32=Uzman_D!$B$27,1,0) -> 0 | L32: 5.6 | M32: =IF(L32=Uzman_D!$B$28,1,0) -> 0 | N32: 4.8 | O32: =IF(N32=Uzman_D!$B$29,1,0) -> 0 | P32: 5 | Q32: =IF(P32=Uzman_D!$B$30,1,0) -> 0 | R32: 5.4 | S32: =IF(R32=Uzman_D!$B$31,1,0) -> 0 | T32: 4.4 | U32: =IF(T32=Uzman_D!$B$32,1,0) -> 0 | V32: 4.2 | W32: =IF(V32=Uzman_D!$B$33,1,0) -> 0 | X32: =(E32+G32+I32+K32+M32+O32+Q32+S32+U32+W32)/10 -> 0
A33: 30 | B33: =Hakemler!B33 -> ÖZGENLİK TATAR | C33: =Hakemler!C33 -> ARZU | D33: 3.8 | E33: =IF(D33=Uzman_D!$B$24,1,0) -> 1 | F33: 5 | G33: =IF(F33=Uzman_D!$B$25,1,0) -> 0 | H33: 5 | I33: =IF(H33=Uzman_D!$B$26,1,0) -> 1 | J33: 3.8 | K33: =IF(J33=Uzman_D!$B$27,1,0) -> 1 | L33: 5.6 | M33: =IF(L33=Uzman_D!$B$28,1,0) -> 0 | N33: 4.2 | O33: =IF(N33=Uzman_D!$B$29,1,0) -> 1 | P33: 3.2 | Q33: =IF(P33=Uzman_D!$B$30,1,0) -> 1 | R33: 5.4 | S33: =IF(R33=Uzman_D!$B$31,1,0) -> 0 | T33: 4.4 | U33: =IF(T33=Uzman_D!$B$32,1,0) -> 0 | V33: 4.6 | W33: =IF(V33=Uzman_D!$B$33,1,0) -> 1 | X33: =(E33+G33+I33+K33+M33+O33+Q33+S33+U33+W33)/10 -> 0.6
A34: 31 | B34: =Hakemler!B34 -> KARADENİZ | C34: =Hakemler!C34 -> EMEL | D34: 3.4 | E34: =IF(D34=Uzman_D!$B$24,1,0) -> 0 | F34: 4.4 | G34: =IF(F34=Uzman_D!$B$25,1,0) -> 0 | H34: 5 | I34: =IF(H34=Uzman_D!$B$26,1,0) -> 1 | J34: 3.8 | K34: =IF(J34=Uzman_D!$B$27,1,0) -> 1 | L34: 5.6 | M34: =IF(L34=Uzman_D!$B$28,1,0) -> 0 | N34: 3.6 | O34: =IF(N34=Uzman_D!$B$29,1,0) -> 0 | P34: 3.2 | Q34: =IF(P34=Uzman_D!$B$30,1,0) -> 1 | R34: 5 | S34: =IF(R34=Uzman_D!$B$31,1,0) -> 0 | T34: 3.8 | U34: =IF(T34=Uzman_D!$B$32,1,0) -> 0 | V34: 4.6 | W34: =IF(V34=Uzman_D!$B$33,1,0) -> 1 | X34: =(E34+G34+I34+K34+M34+O34+Q34+S34+U34+W34)/10 -> 0.4
A35: 32 | B35: =Hakemler!B35 -> TOYRAN | C35: =Hakemler!C35 -> SİNEM NUR | D35: 4.4 | E35: =IF(D35=Uzman_D!$B$24,1,0) -> 0 | F35: 5 | G35: =IF(F35=Uzman_D!$B$25,1,0) -> 0 | H35: 5 | I35: =IF(H35=Uzman_D!$B$26,1,0) -> 1 | J35: 4.4 | K35: =IF(J35=Uzman_D!$B$27,1,0) -> 0 | L35: 4.8 | M35: =IF(L35=Uzman_D!$B$28,1,0) -> 0 | N35: 4.2 | O35: =IF(N35=Uzman_D!$B$29,1,0) -> 1 | P35: 3.6 | Q35: =IF(P35=Uzman_D!$B$30,1,0) -> 0 | R35: 5 | S35: =IF(R35=Uzman_D!$B$31,1,0) -> 0 | T35: 4 | U35: =IF(T35=Uzman_D!$B$32,1,0) -> 0 | V35: 4.6 | W35: =IF(V35=Uzman_D!$B$33,1,0) -> 1 | X35: =(E35+G35+I35+K35+M35+O35+Q35+S35+U35+W35)/10 -> 0.3
... A49: 46 | B49: =Hakemler!B49 -> EDE | C49: =Hakemler!C49 -> İHSAN | D49: 2.5 | E49: =IF(D49=Uzman_D!$B$24,1,0) -> 0 | F49: 4.2 | G49: =IF(F49=Uzman_D!$B$25,1,0) -> 0 | H49: 3.2 | I49: =IF(H49=Uzman_D!$B$26,1,0) -> 0 | J49: 2.5 | K49: =IF(J49=Uzman_D!$B$27,1,0) -> 0 | L49: 3 | M49: =IF(L49=Uzman_D!$B$28,1,0) -> 0 | N49: 4 | O49: =IF(N49=Uzman_D!$B$29,1,0) -> 0 | P49: 2.5 | Q49: =IF(P49=Uzman_D!$B$30,1,0) -> 0 | R49: 4 | S49: =IF(R49=Uzman_D!$B$31,1,0) -> 0 | T49: 3.5 | U49: =IF(T49=Uzman_D!$B$32,1,0) -> 0 | V49: 4 | W49: =IF(V49=Uzman_D!$B$33,1,0) -> 0 | X49: =(E49+G49+I49+K49+M49+O49+Q49+S49+U49+W49)/10 -> 0
A50: 47 | B50: =Hakemler!B50 -> 0 | C50: =Hakemler!C50 -> 0 | E50: =IF(D50=Uzman_D!$B$24,1,0) -> 0 | G50: =IF(F50=Uzman_D!$B$25,1,0) -> 1 | I50: =IF(H50=Uzman_D!$B$26,1,0) -> 0 | K50: =IF(J50=Uzman_D!$B$27,1,0) -> 0 | M50: =IF(L50=Uzman_D!$B$28,1,0) -> 0 | O50: =IF(N50=Uzman_D!$B$29,1,0) -> 0 | Q50: =IF(P50=Uzman_D!$B$30,1,0) -> 0 | S50: =IF(R50=Uzman_D!$B$31,1,0) -> 0 | U50: =IF(T50=Uzman_D!$B$32,1,0) -> 0 | W50: =IF(V50=Uzman_D!$B$33,1,0) -> 0 | X50: =(E50+G50+I50+K50+M50+O50+Q50+S50+U50+W50)/10 -> 0.1
A51: 48 | B51: =Hakemler!B51 -> 0 | C51: =Hakemler!C51 -> 0 | E51: =IF(D51=Uzman_D!$B$24,1,0) -> 0 | G51: =IF(F51=Uzman_D!$B$25,1,0) -> 1 | I51: =IF(H51=Uzman_D!$B$26,1,0) -> 0 | K51: =IF(J51=Uzman_D!$B$27,1,0) -> 0 | M51: =IF(L51=Uzman_D!$B$28,1,0) -> 0 | O51: =IF(N51=Uzman_D!$B$29,1,0) -> 0 | Q51: =IF(P51=Uzman_D!$B$30,1,0) -> 0 | S51: =IF(R51=Uzman_D!$B$31,1,0) -> 0 | U51: =IF(T51=Uzman_D!$B$32,1,0) -> 0 | W51: =IF(V51=Uzman_D!$B$33,1,0) -> 0 | X51: =(E51+G51+I51+K51+M51+O51+Q51+S51+U51+W51)/10 -> 0.1
A52: 49 | B52: =Hakemler!B52 -> 0 | C52: =Hakemler!C52 -> 0 | E52: =IF(D52=Uzman_D!$B$24,1,0) -> 0 | G52: =IF(F52=Uzman_D!$B$25,1,0) -> 1 | I52: =IF(H52=Uzman_D!$B$26,1,0) -> 0 | K52: =IF(J52=Uzman_D!$B$27,1,0) -> 0 | M52: =IF(L52=Uzman_D!$B$28,1,0) -> 0 | O52: =IF(N52=Uzman_D!$B$29,1,0) -> 0 | Q52: =IF(P52=Uzman_D!$B$30,1,0) -> 0 | S52: =IF(R52=Uzman_D!$B$31,1,0) -> 0 | U52: =IF(T52=Uzman_D!$B$32,1,0) -> 0 | W52: =IF(V52=Uzman_D!$B$33,1,0) -> 0 | X52: =(E52+G52+I52+K52+M52+O52+Q52+S52+U52+W52)/10 -> 0.1
A53: 50 | B53: =Hakemler!B53 -> 0 | C53: =Hakemler!C53 -> 0 | E53: =IF(D53=Uzman_D!$B$24,1,0) -> 0 | G53: =IF(F53=Uzman_D!$B$25,1,0) -> 1 | I53: =IF(H53=Uzman_D!$B$26,1,0) -> 0 | K53: =IF(J53=Uzman_D!$B$27,1,0) -> 0 | M53: =IF(L53=Uzman_D!$B$28,1,0) -> 0 | O53: =IF(N53=Uzman_D!$B$29,1,0) -> 0 | Q53: =IF(P53=Uzman_D!$B$30,1,0) -> 0 | S53: =IF(R53=Uzman_D!$B$31,1,0) -> 0 | U53: =IF(T53=Uzman_D!$B$32,1,0) -> 0 | W53: =IF(V53=Uzman_D!$B$33,1,0) -> 0 | X53: =(E53+G53+I53+K53+M53+O53+Q53+S53+U53+W53)/10 -> 0.1
A54: 51 | B54: =Hakemler!B54 -> 0 | C54: =Hakemler!C54 -> 0 | E54: =IF(D54=Uzman_D!$B$24,1,0) -> 0 | G54: =IF(F54=Uzman_D!$B$25,1,0) -> 1 | I54: =IF(H54=Uzman_D!$B$26,1,0) -> 0 | K54: =IF(J54=Uzman_D!$B$27,1,0) -> 0 | M54: =IF(L54=Uzman_D!$B$28,1,0) -> 0 | O54: =IF(N54=Uzman_D!$B$29,1,0) -> 0 | Q54: =IF(P54=Uzman_D!$B$30,1,0) -> 0 | S54: =IF(R54=Uzman_D!$B$31,1,0) -> 0 | U54: =IF(T54=Uzman_D!$B$32,1,0) -> 0 | W54: =IF(V54=Uzman_D!$B$33,1,0) -> 0 | X54: =(E54+G54+I54+K54+M54+O54+Q54+S54+U54+W54)/10 -> 0.1
A55: 52 | B55: =Hakemler!B55 -> 0 | C55: =Hakemler!C55 -> 0 | E55: =IF(D55=Uzman_D!$B$24,1,0) -> 0 | G55: =IF(F55=Uzman_D!$B$25,1,0) -> 1 | I55: =IF(H55=Uzman_D!$B$26,1,0) -> 0 | K55: =IF(J55=Uzman_D!$B$27,1,0) -> 0 | M55: =IF(L55=Uzman_D!$B$28,1,0) -> 0 | O55: =IF(N55=Uzman_D!$B$29,1,0) -> 0 | Q55: =IF(P55=Uzman_D!$B$30,1,0) -> 0 | S55: =IF(R55=Uzman_D!$B$31,1,0) -> 0 | U55: =IF(T55=Uzman_D!$B$32,1,0) -> 0 | W55: =IF(V55=Uzman_D!$B$33,1,0) -> 0 | X55: =(E55+G55+I55+K55+M55+O55+Q55+S55+U55+W55)/10 -> 0.1
A56: 53 | B56: =Hakemler!B56 -> 0 | C56: =Hakemler!C56 -> 0 | E56: =IF(D56=Uzman_D!$B$24,1,0) -> 0 | G56: =IF(F56=Uzman_D!$B$25,1,0) -> 1 | I56: =IF(H56=Uzman_D!$B$26,1,0) -> 0 | K56: =IF(J56=Uzman_D!$B$27,1,0) -> 0 | M56: =IF(L56=Uzman_D!$B$28,1,0) -> 0 | O56: =IF(N56=Uzman_D!$B$29,1,0) -> 0 | Q56: =IF(P56=Uzman_D!$B$30,1,0) -> 0 | S56: =IF(R56=Uzman_D!$B$31,1,0) -> 0 | U56: =IF(T56=Uzman_D!$B$32,1,0) -> 0 | W56: =IF(V56=Uzman_D!$B$33,1,0) -> 0 | X56: =(E56+G56+I56+K56+M56+O56+Q56+S56+U56+W56)/10 -> 0.1
A57: 54 | B57: =Hakemler!B57 -> 0 | C57: =Hakemler!C57 -> 0 | E57: =IF(D57=Uzman_D!$B$24,1,0) -> 0 | G57: =IF(F57=Uzman_D!$B$25,1,0) -> 1 | I57: =IF(H57=Uzman_D!$B$26,1,0) -> 0 | K57: =IF(J57=Uzman_D!$B$27,1,0) -> 0 | M57: =IF(L57=Uzman_D!$B$28,1,0) -> 0 | O57: =IF(N57=Uzman_D!$B$29,1,0) -> 0 | Q57: =IF(P57=Uzman_D!$B$30,1,0) -> 0 | S57: =IF(R57=Uzman_D!$B$31,1,0) -> 0 | U57: =IF(T57=Uzman_D!$B$32,1,0) -> 0 | W57: =IF(V57=Uzman_D!$B$33,1,0) -> 0 | X57: =(E57+G57+I57+K57+M57+O57+Q57+S57+U57+W57)/10 -> 0.1
A58: 55 | B58: =Hakemler!B58 -> 0 | C58: =Hakemler!C58 -> 0 | E58: =IF(D58=Uzman_D!$B$24,1,0) -> 0 | G58: =IF(F58=Uzman_D!$B$25,1,0) -> 1 | I58: =IF(H58=Uzman_D!$B$26,1,0) -> 0 | K58: =IF(J58=Uzman_D!$B$27,1,0) -> 0 | M58: =IF(L58=Uzman_D!$B$28,1,0) -> 0 | O58: =IF(N58=Uzman_D!$B$29,1,0) -> 0 | Q58: =IF(P58=Uzman_D!$B$30,1,0) -> 0 | S58: =IF(R58=Uzman_D!$B$31,1,0) -> 0 | U58: =IF(T58=Uzman_D!$B$32,1,0) -> 0 | W58: =IF(V58=Uzman_D!$B$33,1,0) -> 0 | X58: =(E58+G58+I58+K58+M58+O58+Q58+S58+U58+W58)/10 -> 0.1
...

Sheet AtM_E
A1: ATLAMA MASASI - E Puanı
A2: No. | B2: Soyadı | C2: Adı | D2: E1 | G2: E2 | J2: E3 | M2: E4 | P2: E5
D3: E1 | E3: Hata | F3: P | G3: E2 | H3: Hata | I3: P | J3: E3 | K3: Hata | L3: P | M3: E4 | N3: Hata | O3: P | P3: E5 | Q3: Hata | R3: P | S3: Ortalama
A4: 1 | B4: =Hakemler!B4 -> YAZICI | C4: =Hakemler!C4 -> SUZAN | D4: 1.6 | E4: =IF(ISBLANK(D4),0,ABS(Uzman_E!A$4-D4)) -> 0.2 | F4: =IF(ISBLANK(D4),0,INDEX(Tablo_E!$B$2:$CX$102,MATCH(ROUND(Uzman_E!A$4,1),Tablo_E!$A$2:$A$102,1),MATCH(ROUND(E4,1),Tablo_E!$B$1:$CX$1,1))) -> 1 | G4: 1.8 | H4: =IF(ISBLANK(G4),0,ABS(Uzman_E!B$4-G4)) -> 0.5 | I4: =IF(ISBLANK(G4),0,INDEX(Tablo_E!$B$2:$CX$102,MATCH(ROUND(Uzman_E!B$4,1),Tablo_E!$A$2:$A$102,1),MATCH(ROUND(H4,1),Tablo_E!$B$1:$CX$1,1))) -> 0.85 | J4: 1.3 | K4: =IF(ISBLANK(J4),0,ABS(Uzman_E!C$4-J4)) -> 0.2 | L4: =IF(ISBLANK(J4),0,INDEX(Tablo_E!$B$2:$CX$102,MATCH(ROUND(Uzman_E!C$4,1),Tablo_E!$A$2:$A$102,1),MATCH(ROUND(K4,1),Tablo_E!$B$1:$CX$1,1))) -> 1 | M4: 1 | N4: =IF(ISBLANK(M4),0,ABS(Uzman_E!D$4-M4)) -> 0.2 | O4: =IF(ISBLANK(M4),0,INDEX(Tablo_E!$B$2:$CX$102,MATCH(ROUND(Uzman_E!D$4,1),Tablo_E!$A$2:$A$102,1),MATCH(ROUND(N4,1),Tablo_E!$B$1:$CX$1,1))) -> 1 | P4: 0.8 | Q4: =IF(ISBLANK(P4),0,ABS(Uzman_E!E$4-P4)) -> 0.2 | R4: =IF(ISBLANK(P4),0,INDEX(Tablo_E!$B$2:$CX$102,MATCH(ROUND(Uzman_E!B$4,1),Tablo_E!$A$2:$A$102,1),MATCH(ROUND(Q4,1),Tablo_E!$B$1:$CX$1,1))) -> 1 | S4: =(F4+I4+L4+O4+R4)/5 -> 0.97
A5: 2 | B5: =Hakemler!B5 -> ASLAN | C5: =Hakemler!C5 -> SEMA FİDEL | D5: 1 | E5: =IF(ISBLANK(D5),0,ABS(Uzman_E!A$4-D5)) -> 0.4 | F5: =IF(ISBLANK(D5),0,INDEX(Tablo_E!$B$2:$CX$102,MATCH(ROUND(Uzman_E!A$4,1),Tablo_E!$A$2:$A$102,1),MATCH(ROUND(E5,1),Tablo_E!$B$1:$CX$1,1))) -> 0.8 | H5: =IF(ISBLANK(G5),0,ABS(Uzman_E!B$4-G5)) -> 0 | I5: =IF(ISBLANK(G5),0,INDEX(Tablo_E!$B$2:$CX$102,MATCH(ROUND(Uzman_E!B$4,1),Tablo_E!$A$2:$A$102,1),MATCH(ROUND(H5,1),Tablo_E!$B$1:$CX$1,1))) -> 0 | K5: =IF(ISBLANK(J5),0,ABS(Uzman_E!C$4-J5)) -> 0 | L5: =IF(ISBLANK(J5),0,INDEX(Tablo_E!$B$2:$CX$102,MATCH(ROUND(Uzman_E!C$4,1),Tablo_E!$A$2:$A$102,1),MATCH(ROUND(K5,1),Tablo_E!$B$1:$CX$1,1))) -> 0 | N5: =IF(ISBLANK(M5),0,ABS(Uzman_E!D$4-M5)) -> 0 | O5: =IF(ISBLANK(M5),0,INDEX(Tablo_E!$B$2:$CX$102,MATCH(ROUND(Uzman_E!D$4,1),Tablo_E!$A$2:$A$102,1),MATCH(ROUND(N5,1),Tablo_E!$B$1:$CX$1,1))) -> 0 | P5: 1 | Q5: =IF(ISBLANK(P5),0,ABS(Uzman_E!E$4-P5)) -> 0 | R5: =IF(ISBLANK(P5),0,INDEX(Tablo_E!$B$2:$CX$102,MATCH(ROUND(Uzman_E!B$4,1),Tablo_E!$A$2:$A$102,1),MATCH(ROUND(Q5,1),Tablo_E!$B$1:$CX$1,1))) -> 1 | S5: =(F5+I5+L5+O5+R5)/5 -> 0.36
A6: 3 | B6: =Hakemler!B6 -> TUNA | C6: =Hakemler!C6 -> MUNİSE | E6: =IF(ISBLANK(D6),0,ABS(Uzman_E!A$4-D6)) -> 0 | F6: =IF(ISBLANK(D6),0,INDEX(Tablo_E!$B$2:$CX$102,MATCH(ROUND(Uzman_E!A$4,1),Tablo_E!$A$2:$A$102,1),MATCH(ROUND(E6,1),Tablo_E!$B$1:$CX$1,1))) -> 0 | H6: =IF(ISBLANK(G6),0,ABS(Uzman_E!B$4-G6)) -> 0 | I6: =IF(ISBLANK(G6),0,INDEX(Tablo_E!$B$2:$CX$102,MATCH(ROUND(Uzman_E!B$4,1),Tablo_E!$A$2:$A$102,1),MATCH(ROUND(H6,1),Tablo_E!$B$1:$CX$1,1))) -> 0 | J6: 3 | K6: =IF(ISBLANK(J6),0,ABS(Uzman_E!C$4-J6)) -> 1.9 | L6: =IF(ISBLANK(J6),0,INDEX(Tablo_E!$B$2:$CX$102,MATCH(ROUND(Uzman_E!C$4,1),Tablo_E!$A$2:$A$102,1),MATCH(ROUND(K6,1),Tablo_E!$B$1:$CX$1,1))) -> 0 | N6: =IF(ISBLANK(M6),0,ABS(Uzman_E!D$4-M6)) -> 0 | O6: =IF(ISBLANK(M6),0,INDEX(Tablo_E!$B$2:$CX$102,MATCH(ROUND(Uzman_E!D$4,1),Tablo_E!$A$2:$A$102,1),MATCH(ROUND(N6,1),Tablo_E!$B$1:$CX$1,1))) -> 0 | P6: 1.2 | Q6: =IF(ISBLANK(P6),0,ABS(Uzman_E!E$4-P6)) -> 0.2 | R6: =IF(ISBLANK(P6),0,INDEX(Tablo_E!$B$2:$CX$102,MATCH(ROUND(Uzman_E!B$4,1),Tablo_E!$A$2:$A$102,1),MATCH(ROUND(Q6,1),Tablo_E!$B$1:$CX$1,1))) -> 1 | S6: =(F6+I6+L6+O6+R6)/5 -> 0.2
A7: 4 | B7: =Hakemler!B7 -> ÜNAL | C7: =Hakemler!C7 -> FATMA HANIM | E7: =IF(ISBLANK(D7),0,ABS(Uzman_E!A$4-D7)) -> 0 | F7: =IF(ISBLANK(D7),0,INDEX(Tablo_E!$B$2:$CX$102,MATCH(ROUND(Uzman_E!A$4,1),Tablo_E!$A$2:$A$102,1),MATCH(ROUND(E7,1),Tablo_E!$B$1:$CX$1,1))) -> 0 | G7: 2 | H7: =IF(ISBLANK(G7),0,ABS(Uzman_E!B$4-G7)) -> 0.3 | I7: =IF(ISBLANK(G7),0,INDEX(Tablo_E!$B$2:$CX$102,MATCH(ROUND(Uzman_E!B$4,1),Tablo_E!$A$2:$A$102,1),MATCH(ROUND(H7,1),Tablo_E!$B$1:$CX$1,1))) -> 1 | J7: 2 | K7: =IF(ISBLANK(J7),0,ABS(Uzman_E!C$4-J7)) -> 0.9 | L7: =IF(ISBLANK(J7),0,INDEX(Tablo_E!$B$2:$CX$102,MATCH(ROUND(Uzman_E!C$4,1),Tablo_E!$A$2:$A$102,1),MATCH(ROUND(K7,1),Tablo_E!$B$1:$CX$1,1))) -> 0.3 | N7: =IF(ISBLANK(M7),0,ABS(Uzman_E!D$4-M7)) -> 0 | O7: =IF(ISBLANK(M7),0,INDEX(Tablo_E!$B$2:$CX$102,MATCH(ROUND(Uzman_E!D$4,1),Tablo_E!$A$2:$A$102,1),MATCH(ROUND(N7,1),Tablo_E!$B$1:$CX$1,1))) -> 0 | P7: 1.4 | Q7: =IF(ISBLANK(P7),0,ABS(Uzman_E!E$4-P7)) -> 0.4 | R7: =IF(ISBLANK(P7),0,INDEX(Tablo_E!$B$2:$CX$102,MATCH(ROUND(Uzman_E!B$4,1),Tablo_E!$A$2:$A$102,1),MATCH(ROUND(Q7,1),Tablo_E!$B$1:$CX$1,1))) -> 0.95 | S7: =(F7+I7+L7+O7+R7)/5 -> 0.45
A8: 5 | B8: =Hakemler!B8 -> BAŞKAN PERÇİN | C8: =Hakemler!C8 -> ÖZGE | E8: =IF(ISBLANK(D8),0,ABS(Uzman_E!A$4-D8)) -> 0 | F8: =IF(ISBLANK(D8),0,INDEX(Tablo_E!$B$2:$CX$102,MATCH(ROUND(Uzman_E!A$4,1),Tablo_E!$A$2:$A$102,1),MATCH(ROUND(E8,1),Tablo_E!$B$1:$CX$1,1))) -> 0 | G8: 1.2 | H8: =IF(ISBLANK(G8),0,ABS(Uzman_E!B$4-G8)) -> 1.1 | I8: =IF(ISBLANK(G8),0,INDEX(Tablo_E!$B$2:$CX$102,MATCH(ROUND(Uzman_E!B$4,1),Tablo_E!$A$2:$A$102,1),MATCH(ROUND(H8,1),Tablo_E!$B$1:$CX$1,1))) -> 0.3 | J8: 1 | K8: =IF(ISBLANK(J8),0,ABS(Uzman_E!C$4-J8)) -> 0.1 | L8: =IF(ISBLANK(J8),0,INDEX(Tablo_E!$B$2:$CX$102,MATCH(ROUND(Uzman_E!C$4,1),Tablo_E!$A$2:$A$102,1),MATCH(ROUND(K8,1),Tablo_E!$B$1:$CX$1,1))) -> 1 | N8: =IF(ISBLANK(M8),0,ABS(Uzman_E!D$4-M8)) -> 0 | O8: =IF(ISBLANK(M8),0,INDEX(Tablo_E!$B$2:$CX$102,MATCH(ROUND(Uzman_E!D$4,1),Tablo_E!$A$2:$A$102,1),MATCH(ROUND(N8,1),Tablo_E!$B$1:$CX$1,1))) -> 0 | Q8: =IF(ISBLANK(P8),0,ABS(Uzman_E!E$4-P8)) -> 0 | R8: =IF(ISBLANK(P8),0,INDEX(Tablo_E!$B$2:$CX$102,MATCH(ROUND(Uzman_E!B$4,1),Tablo_E!$A$2:$A$102,1),MATCH(ROUND(Q8,1),Tablo_E!$B$1:$CX$1,1))) -> 0 | S8: =(F8+I8+L8+O8+R8)/5 -> 0.26
A9: 6 | B9: =Hakemler!B9 -> ŞEN İZMİRLİ | C9: =Hakemler!C9 -> SİNEM | E9: =IF(ISBLANK(D9),0,ABS(Uzman_E!A$4-D9)) -> 0 | F9: =IF(ISBLANK(D9),0,INDEX(Tablo_E!$B$2:$CX$102,MATCH(ROUND(Uzman_E!A$4,1),Tablo_E!$A$2:$A$102,1),MATCH(ROUND(E9,1),Tablo_E!$B$1:$CX$1,1))) -> 0 | G9: 1 | H9: =IF(ISBLANK(G9),0,ABS(Uzman_E!B$4-G9)) -> 1.3 | I9: =IF(ISBLANK(G9),0,INDEX(Tablo_E!$B$2:$CX$102,MATCH(ROUND(Uzman_E!B$4,1),Tablo_E!$A$2:$A$102,1),MATCH(ROUND(H9,1),Tablo_E!$B$1:$CX$1,1))) -> 0.1 | J9: 5 | K9: =IF(ISBLANK(J9),0,ABS(Uzman_E!C$4-J9)) -> 3.9 | L9: =IF(ISBLANK(J9),0,INDEX(Tablo_E!$B$2:$CX$102,MATCH(ROUND(Uzman_E!C$4,1),Tablo_E!$A$2:$A$102,1),MATCH(ROUND(K9,1),Tablo_E!$B$1:$CX$1,1))) -> 0 | N9: =IF(ISBLANK(M9),0,ABS(Uzman_E!D$4-M9)) -> 0 | O9: =IF(ISBLANK(M9),0,INDEX(Tablo_E!$B$2:$CX$102,MATCH(ROUND(Uzman_E!D$4,1),Tablo_E!$A$2:$A$102,1),MATCH(ROUND(N9,1),Tablo_E!$B$1:$CX$1,1))) -> 0 | Q9: =IF(ISBLANK(P9),0,ABS(Uzman_E!E$4-P9)) -> 0 | R9: =IF(ISBLANK(P9),0,INDEX(Tablo_E!$B$2:$CX$102,MATCH(ROUND(Uzman_E!B$4,1),Tablo_E!$A$2:$A$102,1),MATCH(ROUND(Q9,1),Tablo_E!$B$1:$CX$1,1))) -> 0 | S9: =(F9+I9+L9+O9+R9)/5 -> 0.02
A10: 7 | B10: =Hakemler!B10 -> YILDIRIMER | C10: =Hakemler!C10 -> BUSE | E10: =IF(ISBLANK(D10),0,ABS(Uzman_E!A$4-D10)) -> 0 | F10: =IF(ISBLANK(D10),0,INDEX(Tablo_E!$B$2:$CX$102,MATCH(ROUND(Uzman_E!A$4,1),Tablo_E!$A$2:$A$102,1),MATCH(ROUND(E10,1),Tablo_E!$B$1:$CX$1,1))) -> 0 | G10: 1.5 | H10: =IF(ISBLANK(G10),0,ABS(Uzman_E!B$4-G10)) -> 0.8 | I10: =IF(ISBLANK(G10),0,INDEX(Tablo_E!$B$2:$CX$102,MATCH(ROUND(Uzman_E!B$4,1),Tablo_E!$A$2:$A$102,1),MATCH(ROUND(H10,1),Tablo_E!$B$1:$CX$1,1))) -> 0.6 | J10: 4 | K10: =IF(ISBLANK(J10),0,ABS(Uzman_E!C$4-J10)) -> 2.9 | L10: =IF(ISBLANK(J10),0,INDEX(Tablo_E!$B$2:$CX$102,MATCH(ROUND(Uzman_E!C$4,1),Tablo_E!$A$2:$A$102,1),MATCH(ROUND(K10,1),Tablo_E!$B$1:$CX$1,1))) -> 0 | N10: =IF(ISBLANK(M10),0,ABS(Uzman_E!D$4-M10)) -> 0 | O10: =IF(ISBLANK(M10),0,INDEX(Tablo_E!$B$2:$CX$102,MATCH(ROUND(Uzman_E!D$4,1),Tablo_E!$A$2:$A$102,1),MATCH(ROUND(N10,1),Tablo_E!$B$1:$CX$1,1))) -> 0 | Q10: =IF(ISBLANK(P10),0,ABS(Uzman_E!E$4-P10)) -> 0 | R10: =IF(ISBLANK(P10),0,INDEX(Tablo_E!$B$2:$CX$102,MATCH(ROUND(Uzman_E!B$4,1),Tablo_E!$A$2:$A$102,1),MATCH(ROUND(Q10,1),Tablo_E!$B$1:$CX$1,1))) -> 0 | S10: =(F10+I10+L10+O10+R10)/5 -> 0.12
A11: 8 | B11: =Hakemler!B11 -> KESKİN | C11: =Hakemler!C11 -> ENFAL | E11: =IF(ISBLANK(D11),0,ABS(Uzman_E!A$4-D11)) -> 0 | F11: =IF(ISBLANK(D11),0,INDEX(Tablo_E!$B$2:$CX$102,MATCH(ROUND(Uzman_E!A$4,1),Tablo_E!$A$2:$A$102,1),MATCH(ROUND(E11,1),Tablo_E!$B$1:$CX$1,1))) -> 0 | H11: =IF(ISBLANK(G11),0,ABS(Uzman_E!B$4-G11)) -> 0 | I11: =IF(ISBLANK(G11),0,INDEX(Tablo_E!$B$2:$CX$102,MATCH(ROUND(Uzman_E!B$4,1),Tablo_E!$A$2:$A$102,1),MATCH(ROUND(H11,1),Tablo_E!$B$1:$CX$1,1))) -> 0 | K11: =IF(ISBLANK(J11),0,ABS(Uzman_E!C$4-J11)) -> 0 | L11: =IF(ISBLANK(J11),0,INDEX(Tablo_E!$B$2:$CX$102,MATCH(ROUND(Uzman_E!C$4,1),Tablo_E!$A$2:$A$102,1),MATCH(ROUND(K11,1),Tablo_E!$B$1:$CX$1,1))) -> 0 | N11: =IF(ISBLANK(M11),0,ABS(Uzman_E!D$4-M11)) -> 0 | O11: =IF(ISBLANK(M11),0,INDEX(Tablo_E!$B$2:$CX$102,MATCH(ROUND(Uzman_E!D$4,1),Tablo_E!$A$2:$A$102,1),MATCH(ROUND(N11,1),Tablo_E!$B$1:$CX$1,1))) -> 0 | Q11: =IF(ISBLANK(P11),0,ABS(Uzman_E!E$4-P11)) -> 0 | R11: =IF(ISBLANK(P11),0,INDEX(Tablo_E!$B$2:$CX$102,MATCH(ROUND(Uzman_E!B$4,1),Tablo_E!$A$2:$A$102,1),MATCH(ROUND(Q11,1),Tablo_E!$B$1:$CX$1,1))) -> 0 | S11: =(F11+I11+L11+O11+R11)/5 -> 0
A12: 9 | B12: =Hakemler!B12 -> ÜNAL | C12: =Hakemler!C12 -> NAZLINEHİR | E12: =IF(ISBLANK(D12),0,ABS(Uzman_E!A$4-D12)) -> 0 | F12: =IF(ISBLANK(D12),0,INDEX(Tablo_E!$B$2:$CX$102,MATCH(ROUND(Uzman_E!A$4,1),Tablo_E!$A$2:$A$102,1),MATCH(ROUND(E12,1),Tablo_E!$B$1:$CX$1,1))) -> 0 | H12: =IF(ISBLANK(G12),0,ABS(Uzman_E!B$4-G12)) -> 0 | I12: =IF(ISBLANK(G12),0,INDEX(Tablo_E!$B$2:$CX$102,MATCH(ROUND(Uzman_E!B$4,1),Tablo_E!$A$2:$A$102,1),MATCH(ROUND(H12,1),Tablo_E!$B$1:$CX$1,1))) -> 0 | J12: 3 | K12: =IF(ISBLANK(J12),0,ABS(Uzman_E!C$4-J12)) -> 1.9 | L12: =IF(ISBLANK(J12),0,INDEX(Tablo_E!$B$2:$CX$102,MATCH(ROUND(Uzman_E!C$4,1),Tablo_E!$A$2:$A$102,1),MATCH(ROUND(K12,1),Tablo_E!$B$1:$CX$1,1))) -> 0 | N12: =IF(ISBLANK(M12),0,ABS(Uzman_E!D$4-M12)) -> 0 | O12: =IF(ISBLANK(M12),0,INDEX(Tablo_E!$B$2:$CX$102,MATCH(ROUND(Uzman_E!D$4,1),Tablo_E!$A$2:$A$102,1),MATCH(ROUND(N12,1),Tablo_E!$B$1:$CX$1,1))) -> 0 | Q12: =IF(ISBLANK(P12),0,ABS(Uzman_E!E$4-P12)) -> 0 | R12: =IF(ISBLANK(P12),0,INDEX(Tablo_E!$B$2:$CX$102,MATCH(ROUND(Uzman_E!B$4,1),Tablo_E!$A$2:$A$102,1),MATCH(ROUND(Q12,1),Tablo_E!$B$1:$CX$1,1))) -> 0 | S12: =(F12+I12+L12+O12+R12)/5 -> 0
A13: 10 | B13: =Hakemler!B13 -> ÜÇTAŞ ŞANLI | C13: =Hakemler!C13 -> GÖKSU | E13: =IF(ISBLANK(D13),0,ABS(Uzman_E!A$4-D13)) -> 0 | F13: =IF(ISBLANK(D13),0,INDEX(Tablo_E!$B$2:$CX$102,MATCH(ROUND(Uzman_E!A$4,1),Tablo_E!$A$2:$A$102,1),MATCH(ROUND(E13,1),Tablo_E!$B$1:$CX$1,1))) -> 0 | H13: =IF(ISBLANK(G13),0,ABS(Uzman_E!B$4-G13)) -> 0 | I13: =IF(ISBLANK(G13),0,INDEX(Tablo_E!$B$2:$CX$102,MATCH(ROUND(Uzman_E!B$4,1),Tablo_E!$A$2:$A$102,1),MATCH(ROUND(H13,1),Tablo_E!$B$1:$CX$1,1))) -> 0 | J13: 1.1 | K13: =IF(ISBLANK(J13),0,ABS(Uzman_E!C$4-J13)) -> 0 | L13: =IF(ISBLANK(J13),0,INDEX(Tablo_E!$B$2:$CX$102,MATCH(ROUND(Uzman_E!C$4,1),Tablo_E!$A$2:$A$102,1),MATCH(ROUND(K13,1),Tablo_E!$B$1:$CX$1,1))) -> 1 | N13: =IF(ISBLANK(M13),0,ABS(Uzman_E!D$4-M13)) -> 0 | O13: =IF(ISBLANK(M13),0,INDEX(Tablo_E!$B$2:$CX$102,MATCH(ROUND(Uzman_E!D$4,1),Tablo_E!$A$2:$A$102,1),MATCH(ROUND(N13,1),Tablo_E!$B$1:$CX$1,1))) -> 0 | Q13: =IF(ISBLANK(P13),0,ABS(Uzman_E!E$4-P13)) -> 0 | R13: =IF(ISBLANK(P13),0,INDEX(Tablo_E!$B$2:$CX$102,MATCH(ROUND(Uzman_E!B$4,1),Tablo_E!$A$2:$A$102,1),MATCH(ROUND(Q13,1),Tablo_E!$B$1:$CX$1,1))) -> 0 | S13: =(F13+I13+L13+O13+R13)/5 -> 0.2
A14: 11 | B14: =Hakemler!B14 -> YÜCEL | C14: =Hakemler!C14 -> SİBEL | E14: =IF(ISBLANK(D14),0,ABS(Uzman_E!A$4-D14)) -> 0 | F14: =IF(ISBLANK(D14),0,INDEX(Tablo_E!$B$2:$CX$102,MATCH(ROUND(Uzman_E!A$4,1),Tablo_E!$A$2:$A$102,1),MATCH(ROUND(E14,1),Tablo_E!$B$1:$CX$1,1))) -> 0 | H14: =IF(ISBLANK(G14),0,ABS(Uzman_E!B$4-G14)) -> 0 | I14: =IF(ISBLANK(G14),0,INDEX(Tablo_E!$B$2:$CX$102,MATCH(ROUND(Uzman_E!B$4,1),Tablo_E!$A$2:$A$102,1),MATCH(ROUND(H14,1),Tablo_E!$B$1:$CX$1,1))) -> 0 | J14: 1.2 | K14: =IF(ISBLANK(J14),0,ABS(Uzman_E!C$4-J14)) -> 0.1 | L14: =IF(ISBLANK(J14),0,INDEX(Tablo_E!$B$2:$CX$102,MATCH(ROUND(Uzman_E!C$4,1),Tablo_E!$A$2:$A$102,1),MATCH(ROUND(K14,1),Tablo_E!$B$1:$CX$1,1))) -> 1 | N14: =IF(ISBLANK(M14),0,ABS(Uzman_E!D$4-M14)) -> 0 | O14: =IF(ISBLANK(M14),0,INDEX(Tablo_E!$B$2:$CX$102,MATCH(ROUND(Uzman_E!D$4,1),Tablo_E!$A$2:$A$102,1),MATCH(ROUND(N14,1),Tablo_E!$B$1:$CX$1,1))) -> 0 | Q14: =IF(ISBLANK(P14),0,ABS(Uzman_E!E$4-P14)) -> 0 | R14: =IF(ISBLANK(P14),0,INDEX(Tablo_E!$B$2:$CX$102,MATCH(ROUND(Uzman_E!B$4,1),Tablo_E!$A$2:$A$102,1),MATCH(ROUND(Q14,1),Tablo_E!$B$1:$CX$1,1))) -> 0 | S14: =(F14+I14+L14+O14+R14)/5 -> 0.2
A15: 12 | B15: =Hakemler!B15 -> YILMAZER | C15: =Hakemler!C15 -> ZEHRA | E15: =IF(ISBLANK(D15),0,ABS(Uzman_E!A$4-D15)) -> 0 | F15: =IF(ISBLANK(D15),0,INDEX(Tablo_E!$B$2:$CX$102,MATCH(ROUND(Uzman_E!A$4,1),Tablo_E!$A$2:$A$102,1),MATCH(ROUND(E15,1),Tablo_E!$B$1:$CX$1,1))) -> 0 | H15: =IF(ISBLANK(G15),0,ABS(Uzman_E!B$4-G15)) -> 0 | I15: =IF(ISBLANK(G15),0,INDEX(Tablo_E!$B$2:$CX$102,MATCH(ROUND(Uzman_E!B$4,1),Tablo_E!$A$2:$A$102,1),MATCH(ROUND(H15,1),Tablo_E!$B$1:$CX$1,1))) -> 0 | J15: 1.3 | K15: =IF(ISBLANK(J15),0,ABS(Uzman_E!C$4-J15)) -> 0.2 | L15: =IF(ISBLANK(J15),0,INDEX(Tablo_E!$B$2:$CX$102,MATCH(ROUND(Uzman_E!C$4,1),Tablo_E!$A$2:$A$102,1),MATCH(ROUND(K15,1),Tablo_E!$B$1:$CX$1,1))) -> 1 | M15: 1.6 | N15: =IF(ISBLANK(M15),0,ABS(Uzman_E!D$4-M15)) -> 0.8 | O15: =IF(ISBLANK(M15),0,INDEX(Tablo_E!$B$2:$CX$102,MATCH(ROUND(Uzman_E!D$4,1),Tablo_E!$A$2:$A$102,1),MATCH(ROUND(N15,1),Tablo_E!$B$1:$CX$1,1))) -> 0.3 | Q15: =IF(ISBLANK(P15),0,ABS(Uzman_E!E$4-P15)) -> 0 | R15: =IF(ISBLANK(P15),0,INDEX(Tablo_E!$B$2:$CX$102,MATCH(ROUND(Uzman_E!B$4,1),Tablo_E!$A$2:$A$102,1),MATCH(ROUND(Q15,1),Tablo_E!$B$1:$CX$1,1))) -> 0 | S15: =(F15+I15+L15+O15+R15)/5 -> 0.26
A16: 13 | B16: =Hakemler!B16 -> ŞAHİNTEKİN | C16: =Hakemler!C16 -> MUHAMMED | E16: =IF(ISBLANK(D16),0,ABS(Uzman_E!A$4-D16)) -> 0 | F16: =IF(ISBLANK(D16),0,INDEX(Tablo_E!$B$2:$CX$102,MATCH(ROUND(Uzman_E!A$4,1),Tablo_E!$A$2:$A$102,1),MATCH(ROUND(E16,1),Tablo_E!$B$1:$CX$1,1))) -> 0 | H16: =IF(ISBLANK(G16),0,ABS(Uzman_E!B$4-G16)) -> 0 | I16: =IF(ISBLANK(G16),0,INDEX(Tablo_E!$B$2:$CX$102,MATCH(ROUND(Uzman_E!B$4,1),Tablo_E!$A$2:$A$102,1),MATCH(ROUND(H16,1),Tablo_E!$B$1:$CX$1,1))) -> 0 | K16: =IF(ISBLANK(J16),0,ABS(Uzman_E!C$4-J16)) -> 0 | L16: =IF(ISBLANK(J16),0,INDEX(Tablo_E!$B$2:$CX$102,MATCH(ROUND(Uzman_E!C$4,1),Tablo_E!$A$2:$A$102,1),MATCH(ROUND(K16,1),Tablo_E!$B$1:$CX$1,1))) -> 0 | M16: 1.5 | N16: =IF(ISBLANK(M16),0,ABS(Uzman_E!D$4-M16)) -> 0.7 | O16: =IF(ISBLANK(M16),0,INDEX(Tablo_E!$B$2:$CX$102,MATCH(ROUND(Uzman_E!D$4,1),Tablo_E!$A$2:$A$102,1),MATCH(ROUND(N16,1),Tablo_E!$B$1:$CX$1,1))) -> 0.4 | Q16: =IF(ISBLANK(P16),0,ABS(Uzman_E!E$4-P16)) -> 0 | R16: =IF(ISBLANK(P16),0,INDEX(Tablo_E!$B$2:$CX$102,MATCH(ROUND(Uzman_E!B$4,1),Tablo_E!$A$2:$A$102,1),MATCH(ROUND(Q16,1),Tablo_E!$B$1:$CX$1,1))) -> 0 | S16: =(F16+I16+L16+O16+R16)/5 -> 0.08
A17: 14 | B17: =Hakemler!B17 -> ERKUT | C17: =Hakemler!C17 -> OYA | E17: =IF(ISBLANK(D17),0,ABS(Uzman_E!A$4-D17)) -> 0 | F17: =IF(ISBLANK(D17),0,INDEX(Tablo_E!$B$2:$CX$102,MATCH(ROUND(Uzman_E!A$4,1),Tablo_E!$A$2:$A$102,1),MATCH(ROUND(E17,1),Tablo_E!$B$1:$CX$1,1))) -> 0 | H17: =IF(ISBLANK(G17),0,ABS(Uzman_E!B$4-G17)) -> 0 | I17: =IF(ISBLANK(G17),0,INDEX(Tablo_E!$B$2:$CX$102,MATCH(ROUND(Uzman_E!B$4,1),Tablo_E!$A$2:$A$102,1),MATCH(ROUND(H17,1),Tablo_E!$B$1:$CX$1,1))) -> 0 | K17: =IF(ISBLANK(J17),0,ABS(Uzman_E!C$4-J17)) -> 0 | L17: =IF(ISBLANK(J17),0,INDEX(Tablo_E!$B$2:$CX$102,MATCH(ROUND(Uzman_E!C$4,1),Tablo_E!$A$2:$A$102,1),MATCH(ROUND(K17,1),Tablo_E!$B$1:$CX$1,1))) -> 0 | M17: 1.4 | N17: =IF(ISBLANK(M17),0,ABS(Uzman_E!D$4-M17)) -> 0.6 | O17: =IF(ISBLANK(M17),0,INDEX(Tablo_E!$B$2:$CX$102,MATCH(ROUND(Uzman_E!D$4,1),Tablo_E!$A$2:$A$102,1),MATCH(ROUND(N17,1),Tablo_E!$B$1:$CX$1,1))) -> 0.5 | Q17: =IF(ISBLANK(P17),0,ABS(Uzman_E!E$4-P17)) -> 0 | R17: =IF(ISBLANK(P17),0,INDEX(Tablo_E!$B$2:$CX$102,MATCH(ROUND(Uzman_E!B$4,1),Tablo_E!$A$2:$A$102,1),MATCH(ROUND(Q17,1),Tablo_E!$B$1:$CX$1,1))) -> 0 | S17: =(F17+I17+L17+O17+R17)/5 -> 0.1
A18: 15 | B18: =Hakemler!B18 -> GÜMÜŞLÜ | C18: =Hakemler!C18 -> AYSEL | E18: =IF(ISBLANK(D18),0,ABS(Uzman_E!A$4-D18)) -> 0 | F18: =IF(ISBLANK(D18),0,INDEX(Tablo_E!$B$2:$CX$102,MATCH(ROUND(Uzman_E!A$4,1),Tablo_E!$A$2:$A$102,1),MATCH(ROUND(E18,1),Tablo_E!$B$1:$CX$1,1))) -> 0 | H18: =IF(ISBLANK(G18),0,ABS(Uzman_E!B$4-G18)) -> 0 | I18: =IF(ISBLANK(G18),0,INDEX(Tablo_E!$B$2:$CX$102,MATCH(ROUND(Uzman_E!B$4,1),Tablo_E!$A$2:$A$102,1),MATCH(ROUND(H18,1),Tablo_E!$B$1:$CX$1,1))) -> 0 | K18: =IF(ISBLANK(J18),0,ABS(Uzman_E!C$4-J18)) -> 0 | L18: =IF(ISBLANK(J18),0,INDEX(Tablo_E!$B$2:$CX$102,MATCH(ROUND(Uzman_E!C$4,1),Tablo_E!$A$2:$A$102,1),MATCH(ROUND(K18,1),Tablo_E!$B$1:$CX$1,1))) -> 0 | M18: 1.3 | N18: =IF(ISBLANK(M18),0,ABS(Uzman_E!D$4-M18)) -> 0.5 | O18: =IF(ISBLANK(M18),0,INDEX(Tablo_E!$B$2:$CX$102,MATCH(ROUND(Uzman_E!D$4,1),Tablo_E!$A$2:$A$102,1),MATCH(ROUND(N18,1),Tablo_E!$B$1:$CX$1,1))) -> 0.6 | Q18: =IF(ISBLANK(P18),0,ABS(Uzman_E!E$4-P18)) -> 0 | R18: =IF(ISBLANK(P18),0,INDEX(Tablo_E!$B$2:$CX$102,MATCH(ROUND(Uzman_E!B$4,1),Tablo_E!$A$2:$A$102,1),MATCH(ROUND(Q18,1),Tablo_E!$B$1:$CX$1,1))) -> 0 | S18: =(F18+I18+L18+O18+R18)/5 -> 0.12
A19: 16 | B19: =Hakemler!B19 -> CURA COŞKUN | C19: =Hakemler!C19 -> MELİKE | E19: =IF(ISBLANK(D19),0,ABS(Uzman_E!A$4-D19)) -> 0 | F19: =IF(ISBLANK(D19),0,INDEX(Tablo_E!$B$2:$CX$102,MATCH(ROUND(Uzman_E!A$4,1),Tablo_E!$A$2:$A$102,1),MATCH(ROUND(E19,1),Tablo_E!$B$1:$CX$1,1))) -> 0 | H19: =IF(ISBLANK(G19),0,ABS(Uzman_E!B$4-G19)) -> 0 | I19: =IF(ISBLANK(G19),0,INDEX(Tablo_E!$B$2:$CX$102,MATCH(ROUND(Uzman_E!B$4,1),Tablo_E!$A$2:$A$102,1),MATCH(ROUND(H19,1),Tablo_E!$B$1:$CX$1,1))) -> 0 | K19: =IF(ISBLANK(J19),0,ABS(Uzman_E!C$4-J19)) -> 0 | L19: =IF(ISBLANK(J19),0,INDEX(Tablo_E!$B$2:$CX$102,MATCH(ROUND(Uzman_E!C$4,1),Tablo_E!$A$2:$A$102,1),MATCH(ROUND(K19,1),Tablo_E!$B$1:$CX$1,1))) -> 0 | M19: 1.2 | N19: =IF(ISBLANK(M19),0,ABS(Uzman_E!D$4-M19)) -> 0.4 | O19: =IF(ISBLANK(M19),0,INDEX(Tablo_E!$B$2:$CX$102,MATCH(ROUND(Uzman_E!D$4,1),Tablo_E!$A$2:$A$102,1),MATCH(ROUND(N19,1),Tablo_E!$B$1:$CX$1,1))) -> 0.7 | Q19: =IF(ISBLANK(P19),0,ABS(Uzman_E!E$4-P19)) -> 0 | R19: =IF(ISBLANK(P19),0,INDEX(Tablo_E!$B$2:$CX$102,MATCH(ROUND(Uzman_E!B$4,1),Tablo_E!$A$2:$A$102,1),MATCH(ROUND(Q19,1),Tablo_E!$B$1:$CX$1,1))) -> 0 | S19: =(F19+I19+L19+O19+R19)/5 -> 0.14
A20: 17 | B20: =Hakemler!B20 -> KENDİRCİ | C20: =Hakemler!C20 -> CEMRE | E20: =IF(ISBLANK(D20),0,ABS(Uzman_E!A$4-D20)) -> 0 | F20: =IF(ISBLANK(D20),0,INDEX(Tablo_E!$B$2:$CX$102,MATCH(ROUND(Uzman_E!A$4,1),Tablo_E!$A$2:$A$102,1),MATCH(ROUND(E20,1),Tablo_E!$B$1:$CX$1,1))) -> 0 | H20: =IF(ISBLANK(G20),0,ABS(Uzman_E!B$4-G20)) -> 0 | I20: =IF(ISBLANK(G20),0,INDEX(Tablo_E!$B$2:$CX$102,MATCH(ROUND(Uzman_E!B$4,1),Tablo_E!$A$2:$A$102,1),MATCH(ROUND(H20,1),Tablo_E!$B$1:$CX$1,1))) -> 0 | K20: =IF(ISBLANK(J20),0,ABS(Uzman_E!C$4-J20)) -> 0 | L20: =IF(ISBLANK(J20),0,INDEX(Tablo_E!$B$2:$CX$102,MATCH(ROUND(Uzman_E!C$4,1),Tablo_E!$A$2:$A$102,1),MATCH(ROUND(K20,1),Tablo_E!$B$1:$CX$1,1))) -> 0 | M20: 1.1 | N20: =IF(ISBLANK(M20),0,ABS(Uzman_E!D$4-M20)) -> 0.3 | O20: =IF(ISBLANK(M20),0,INDEX(Tablo_E!$B$2:$CX$102,MATCH(ROUND(Uzman_E!D$4,1),Tablo_E!$A$2:$A$102,1),MATCH(ROUND(N20,1),Tablo_E!$B$1:$CX$1,1))) -> 0.8 | Q20: =IF(ISBLANK(P20),0,ABS(Uzman_E!E$4-P20)) -> 0 | R20: =IF(ISBLANK(P20),0,INDEX(Tablo_E!$B$2:$CX$102,MATCH(ROUND(Uzman_E!B$4,1),Tablo_E!$A$2:$A$102,1),MATCH(ROUND(Q20,1),Tablo_E!$B$1:$CX$1,1))) -> 0 | S20: =(F20+I20+L20+O20+R20)/5 -> 0.16
A21: 18 | B21: =Hakemler!B21 -> CANATAN | C21: =Hakemler!C21 -> BEYZA | E21: =IF(ISBLANK(D21),0,ABS(Uzman_E!A$4-D21)) -> 0 | F21: =IF(ISBLANK(D21),0,INDEX(Tablo_E!$B$2:$CX$102,MATCH(ROUND(Uzman_E!A$4,1),Tablo_E!$A$2:$A$102,1),MATCH(ROUND(E21,1),Tablo_E!$B$1:$CX$1,1))) -> 0 | H21: =IF(ISBLANK(G21),0,ABS(Uzman_E!B$4-G21)) -> 0 | I21: =IF(ISBLANK(G21),0,INDEX(Tablo_E!$B$2:$CX$102,MATCH(ROUND(Uzman_E!B$4,1),Tablo_E!$A$2:$A$102,1),MATCH(ROUND(H21,1),Tablo_E!$B$1:$CX$1,1))) -> 0 | K21: =IF(ISBLANK(J21),0,ABS(Uzman_E!C$4-J21)) -> 0 | L21: =IF(ISBLANK(J21),0,INDEX(Tablo_E!$B$2:$CX$102,MATCH(ROUND(Uzman_E!C$4,1),Tablo_E!$A$2:$A$102,1),MATCH(ROUND(K21,1),Tablo_E!$B$1:$CX$1,1))) -> 0 | M21: 1 | N21: =IF(ISBLANK(M21),0,ABS(Uzman_E!D$4-M21)) -> 0.2 | O21: =IF(ISBLANK(M21),0,INDEX(Tablo_E!$B$2:$CX$102,MATCH(ROUND(Uzman_E!D$4,1),Tablo_E!$A$2:$A$102,1),MATCH(ROUND(N21,1),Tablo_E!$B$1:$CX$1,1))) -> 1 | Q21: =IF(ISBLANK(P21),0,ABS(Uzman_E!E$4-P21)) -> 0 | R21: =IF(ISBLANK(P21),0,INDEX(Tablo_E!$B$2:$CX$102,MATCH(ROUND(Uzman_E!B$4,1),Tablo_E!$A$2:$A$102,1),MATCH(ROUND(Q21,1),Tablo_E!$B$1:$CX$1,1))) -> 0 | S21: =(F21+I21+L21+O21+R21)/5 -> 0.2
A22: 19 | B22: =Hakemler!B22 -> SAYIN | C22: =Hakemler!C22 -> ZEYNEP TÜRKAN | E22: =IF(ISBLANK(D22),0,ABS(Uzman_E!A$4-D22)) -> 0 | F22: =IF(ISBLANK(D22),0,INDEX(Tablo_E!$B$2:$CX$102,MATCH(ROUND(Uzman_E!A$4,1),Tablo_E!$A$2:$A$102,1),MATCH(ROUND(E22,1),Tablo_E!$B$1:$CX$1,1))) -> 0 | H22: =IF(ISBLANK(G22),0,ABS(Uzman_E!B$4-G22)) -> 0 | I22: =IF(ISBLANK(G22),0,INDEX(Tablo_E!$B$2:$CX$102,MATCH(ROUND(Uzman_E!B$4,1),Tablo_E!$A$2:$A$102,1),MATCH(ROUND(H22,1),Tablo_E!$B$1:$CX$1,1))) -> 0 | K22: =IF(ISBLANK(J22),0,ABS(Uzman_E!C$4-J22)) -> 0 | L22: =IF(ISBLANK(J22),0,INDEX(Tablo_E!$B$2:$CX$102,MATCH(ROUND(Uzman_E!C$4,1),Tablo_E!$A$2:$A$102,1),MATCH(ROUND(K22,1),Tablo_E!$B$1:$CX$1,1))) -> 0 | N22: =IF(ISBLANK(M22),0,ABS(Uzman_E!D$4-M22)) -> 0 | O22: =IF(ISBLANK(M22),0,INDEX(Tablo_E!$B$2:$CX$102,MATCH(ROUND(Uzman_E!D$4,1),Tablo_E!$A$2:$A$102,1),MATCH(ROUND(N22,1),Tablo_E!$B$1:$CX$1,1))) -> 0 | Q22: =IF(ISBLANK(P22),0,ABS(Uzman_E!E$4-P22)) -> 0 | R22: =IF(ISBLANK(P22),0,INDEX(Tablo_E!$B$2:$CX$102,MATCH(ROUND(Uzman_E!B$4,1),Tablo_E!$A$2:$A$102,1),MATCH(ROUND(Q22,1),Tablo_E!$B$1:$CX$1,1))) -> 0 | S22: =(F22+I22+L22+O22+R22)/5 -> 0
A23: 20 | B23: =Hakemler!B23 -> ÖNER AĞAN | C23: =Hakemler!C23 -> DERYA | E23: =IF(ISBLANK(D23),0,ABS(Uzman_E!A$4-D23)) -> 0 | F23: =IF(ISBLANK(D23),0,INDEX(Tablo_E!$B$2:$CX$102,MATCH(ROUND(Uzman_E!A$4,1),Tablo_E!$A$2:$A$102,1),MATCH(ROUND(E23,1),Tablo_E!$B$1:$CX$1,1))) -> 0 | H23: =IF(ISBLANK(G23),0,ABS(Uzman_E!B$4-G23)) -> 0 | I23: =IF(ISBLANK(G23),0,INDEX(Tablo_E!$B$2:$CX$102,MATCH(ROUND(Uzman_E!B$4,1),Tablo_E!$A$2:$A$102,1),MATCH(ROUND(H23,1),Tablo_E!$B$1:$CX$1,1))) -> 0 | K23: =IF(ISBLANK(J23),0,ABS(Uzman_E!C$4-J23)) -> 0 | L23: =IF(ISBLANK(J23),0,INDEX(Tablo_E!$B$2:$CX$102,MATCH(ROUND(Uzman_E!C$4,1),Tablo_E!$A$2:$A$102,1),MATCH(ROUND(K23,1),Tablo_E!$B$1:$CX$1,1))) -> 0 | N23: =IF(ISBLANK(M23),0,ABS(Uzman_E!D$4-M23)) -> 0 | O23: =IF(ISBLANK(M23),0,INDEX(Tablo_E!$B$2:$CX$102,MATCH(ROUND(Uzman_E!D$4,1),Tablo_E!$A$2:$A$102,1),MATCH(ROUND(N23,1),Tablo_E!$B$1:$CX$1,1))) -> 0 | Q23: =IF(ISBLANK(P23),0,ABS(Uzman_E!E$4-P23)) -> 0 | R23: =IF(ISBLANK(P23),0,INDEX(Tablo_E!$B$2:$CX$102,MATCH(ROUND(Uzman_E!B$4,1),Tablo_E!$A$2:$A$102,1),MATCH(ROUND(Q23,1),Tablo_E!$B$1:$CX$1,1))) -> 0 | S23: =(F23+I23+L23+O23+R23)/5 -> 0
A24: 21 | B24: =Hakemler!B24 -> ABACI | C24: =Hakemler!C24 -> BUSE | D24: 1.2 | E24: =IF(ISBLANK(D24),0,ABS(Uzman_E!A$4-D24)) -> 0.2 | F24: =IF(ISBLANK(D24),0,INDEX(Tablo_E!$B$2:$CX$102,MATCH(ROUND(Uzman_E!A$4,1),Tablo_E!$A$2:$A$102,1),MATCH(ROUND(E24,1),Tablo_E!$B$1:$CX$1,1))) -> 1 | G24: 2.1 | H24: =IF(ISBLANK(G24),0,ABS(Uzman_E!B$4-G24)) -> 0.2 | I24: =IF(ISBLANK(G24),0,INDEX(Tablo_E!$B$2:$CX$102,MATCH(ROUND(Uzman_E!B$4,1),Tablo_E!$A$2:$A$102,1),MATCH(ROUND(H24,1),Tablo_E!$B$1:$CX$1,1))) -> 1 | J24: 0.8 | K24: =IF(ISBLANK(J24),0,ABS(Uzman_E!C$4-J24)) -> 0.3 | L24: =IF(ISBLANK(J24),0,INDEX(Tablo_E!$B$2:$CX$102,MATCH(ROUND(Uzman_E!C$4,1),Tablo_E!$A$2:$A$102,1),MATCH(ROUND(K24,1),Tablo_E!$B$1:$CX$1,1))) -> 0.9 | M24: 1.5 | N24: =IF(ISBLANK(M24),0,ABS(Uzman_E!D$4-M24)) -> 0.7 | O24: =IF(ISBLANK(M24),0,INDEX(Tablo_E!$B$2:$CX$102,MATCH(ROUND(Uzman_E!D$4,1),Tablo_E!$A$2:$A$102,1),MATCH(ROUND(N24,1),Tablo_E!$B$1:$CX$1,1))) -> 0.4 | P24: 0.5 | Q24: =IF(ISBLANK(P24),0,ABS(Uzman_E!E$4-P24)) -> 0.5 | R24: =IF(ISBLANK(P24),0,INDEX(Tablo_E!$B$2:$CX$102,MATCH(ROUND(Uzman_E!B$4,1),Tablo_E!$A$2:$A$102,1),MATCH(ROUND(Q24,1),Tablo_E!$B$1:$CX$1,1))) -> 0.85 | S24: =(F24+I24+L24+O24+R24)/5 -> 0.83
A25: 22 | B25: =Hakemler!B25 -> KARAKAŞ | C25: =Hakemler!C25 -> TAHİR | D25: 1.4 | E25: =IF(ISBLANK(D25),0,ABS(Uzman_E!A$4-D25)) -> 0 | F25: =IF(ISBLANK(D25),0,INDEX(Tablo_E!$B$2:$CX$102,MATCH(ROUND(Uzman_E!A$4,1),Tablo_E!$A$2:$A$102,1),MATCH(ROUND(E25,1),Tablo_E!$B$1:$CX$1,1))) -> 1 | G25: 2.1 | H25: =IF(ISBLANK(G25),0,ABS(Uzman_E!B$4-G25)) -> 0.2 | I25: =IF(ISBLANK(G25),0,INDEX(Tablo_E!$B$2:$CX$102,MATCH(ROUND(Uzman_E!B$4,1),Tablo_E!$A$2:$A$102,1),MATCH(ROUND(H25,1),Tablo_E!$B$1:$CX$1,1))) -> 1 | J25: 0.9 | K25: =IF(ISBLANK(J25),0,ABS(Uzman_E!C$4-J25)) -> 0.2 | L25: =IF(ISBLANK(J25),0,INDEX(Tablo_E!$B$2:$CX$102,MATCH(ROUND(Uzman_E!C$4,1),Tablo_E!$A$2:$A$102,1),MATCH(ROUND(K25,1),Tablo_E!$B$1:$CX$1,1))) -> 1 | M25: 0.7 | N25: =IF(ISBLANK(M25),0,ABS(Uzman_E!D$4-M25)) -> 0.1 | O25: =IF(ISBLANK(M25),0,INDEX(Tablo_E!$B$2:$CX$102,MATCH(ROUND(Uzman_E!D$4,1),Tablo_E!$A$2:$A$102,1),MATCH(ROUND(N25,1),Tablo_E!$B$1:$CX$1,1))) -> 1 | P25: 1.1 | Q25: =IF(ISBLANK(P25),0,ABS(Uzman_E!E$4-P25)) -> 0.1 | R25: =IF(ISBLANK(P25),0,INDEX(Tablo_E!$B$2:$CX$102,MATCH(ROUND(Uzman_E!B$4,1),Tablo_E!$A$2:$A$102,1),MATCH(ROUND(Q25,1),Tablo_E!$B$1:$CX$1,1))) -> 1 | S25: =(F25+I25+L25+O25+R25)/5 -> 1
A26: 23 | B26: =Hakemler!B26 -> SAVAŞ OK | C26: =Hakemler!C26 -> DİLAY | D26: 2 | E26: =IF(ISBLANK(D26),0,ABS(Uzman_E!A$4-D26)) -> 0.6 | F26: =IF(ISBLANK(D26),0,INDEX(Tablo_E!$B$2:$CX$102,MATCH(ROUND(Uzman_E!A$4,1),Tablo_E!$A$2:$A$102,1),MATCH(ROUND(E26,1),Tablo_E!$B$1:$CX$1,1))) -> 0.6 | G26: 3.1 | H26: =IF(ISBLANK(G26),0,ABS(Uzman_E!B$4-G26)) -> 0.8 | I26: =IF(ISBLANK(G26),0,INDEX(Tablo_E!$B$2:$CX$102,MATCH(ROUND(Uzman_E!B$4,1),Tablo_E!$A$2:$A$102,1),MATCH(ROUND(H26,1),Tablo_E!$B$1:$CX$1,1))) -> 0.6 | J26: 0.8 | K26: =IF(ISBLANK(J26),0,ABS(Uzman_E!C$4-J26)) -> 0.3 | L26: =IF(ISBLANK(J26),0,INDEX(Tablo_E!$B$2:$CX$102,MATCH(ROUND(Uzman_E!C$4,1),Tablo_E!$A$2:$A$102,1),MATCH(ROUND(K26,1),Tablo_E!$B$1:$CX$1,1))) -> 0.9 | M26: 1.1 | N26: =IF(ISBLANK(M26),0,ABS(Uzman_E!D$4-M26)) -> 0.3 | O26: =IF(ISBLANK(M26),0,INDEX(Tablo_E!$B$2:$CX$102,MATCH(ROUND(Uzman_E!D$4,1),Tablo_E!$A$2:$A$102,1),MATCH(ROUND(N26,1),Tablo_E!$B$1:$CX$1,1))) -> 0.8 | P26: 1 | Q26: =IF(ISBLANK(P26),0,ABS(Uzman_E!E$4-P26)) -> 0 | R26: =IF(ISBLANK(P26),0,INDEX(Tablo_E!$B$2:$CX$102,MATCH(ROUND(Uzman_E!B$4,1),Tablo_E!$A$2:$A$102,1),MATCH(ROUND(Q26,1),Tablo_E!$B$1:$CX$1,1))) -> 1 | S26: =(F26+I26+L26+O26+R26)/5 -> 0.78
A27: 24 | B27: =Hakemler!B27 -> AYDEMİR | C27: =Hakemler!C27 -> AYŞE DİLARA | D27: 2 | E27: =IF(ISBLANK(D27),0,ABS(Uzman_E!A$4-D27)) -> 0.6 | F27: =IF(ISBLANK(D27),0,INDEX(Tablo_E!$B$2:$CX$102,MATCH(ROUND(Uzman_E!A$4,1),Tablo_E!$A$2:$A$102,1),MATCH(ROUND(E27,1),Tablo_E!$B$1:$CX$1,1))) -> 0.6 | G27: 1.8 | H27: =IF(ISBLANK(G27),0,ABS(Uzman_E!B$4-G27)) -> 0.5 | I27: =IF(ISBLANK(G27),0,INDEX(Tablo_E!$B$2:$CX$102,MATCH(ROUND(Uzman_E!B$4,1),Tablo_E!$A$2:$A$102,1),MATCH(ROUND(H27,1),Tablo_E!$B$1:$CX$1,1))) -> 0.85 | J27: 0.5 | K27: =IF(ISBLANK(J27),0,ABS(Uzman_E!C$4-J27)) -> 0.6 | L27: =IF(ISBLANK(J27),0,INDEX(Tablo_E!$B$2:$CX$102,MATCH(ROUND(Uzman_E!C$4,1),Tablo_E!$A$2:$A$102,1),MATCH(ROUND(K27,1),Tablo_E!$B$1:$CX$1,1))) -> 0.6 | M27: 0.7 | N27: =IF(ISBLANK(M27),0,ABS(Uzman_E!D$4-M27)) -> 0.1 | O27: =IF(ISBLANK(M27),0,INDEX(Tablo_E!$B$2:$CX$102,MATCH(ROUND(Uzman_E!D$4,1),Tablo_E!$A$2:$A$102,1),MATCH(ROUND(N27,1),Tablo_E!$B$1:$CX$1,1))) -> 1 | P27: 0.8 | Q27: =IF(ISBLANK(P27),0,ABS(Uzman_E!E$4-P27)) -> 0.2 | R27: =IF(ISBLANK(P27),0,INDEX(Tablo_E!$B$2:$CX$102,MATCH(ROUND(Uzman_E!B$4,1),Tablo_E!$A$2:$A$102,1),MATCH(ROUND(Q27,1),Tablo_E!$B$1:$CX$1,1))) -> 1 | S27: =(F27+I27+L27+O27+R27)/5 -> 0.81
A28: 25 | B28: =Hakemler!B28 -> AKIN | C28: =Hakemler!C28 -> MANOLYA | D28: 1.7 | E28: =IF(ISBLANK(D28),0,ABS(Uzman_E!A$4-D28)) -> 0.3 | F28: =IF(ISBLANK(D28),0,INDEX(Tablo_E!$B$2:$CX$102,MATCH(ROUND(Uzman_E!A$4,1),Tablo_E!$A$2:$A$102,1),MATCH(ROUND(E28,1),Tablo_E!$B$1:$CX$1,1))) -> 0.9 | G28: 2.3 | H28: =IF(ISBLANK(G28),0,ABS(Uzman_E!B$4-G28)) -> 0 | I28: =IF(ISBLANK(G28),0,INDEX(Tablo_E!$B$2:$CX$102,MATCH(ROUND(Uzman_E!B$4,1),Tablo_E!$A$2:$A$102,1),MATCH(ROUND(H28,1),Tablo_E!$B$1:$CX$1,1))) -> 1 | J28: 0.9 | K28: =IF(ISBLANK(J28),0,ABS(Uzman_E!C$4-J28)) -> 0.2 | L28: =IF(ISBLANK(J28),0,INDEX(Tablo_E!$B$2:$CX$102,MATCH(ROUND(Uzman_E!C$4,1),Tablo_E!$A$2:$A$102,1),MATCH(ROUND(K28,1),Tablo_E!$B$1:$CX$1,1))) -> 1 | M28: 1 | N28: =IF(ISBLANK(M28),0,ABS(Uzman_E!D$4-M28)) -> 0.2 | O28: =IF(ISBLANK(M28),0,INDEX(Tablo_E!$B$2:$CX$102,MATCH(ROUND(Uzman_E!D$4,1),Tablo_E!$A$2:$A$102,1),MATCH(ROUND(N28,1),Tablo_E!$B$1:$CX$1,1))) -> 1 | P28: 1.2 | Q28: =IF(ISBLANK(P28),0,ABS(Uzman_E!E$4-P28)) -> 0.2 | R28: =IF(ISBLANK(P28),0,INDEX(Tablo_E!$B$2:$CX$102,MATCH(ROUND(Uzman_E!B$4,1),Tablo_E!$A$2:$A$102,1),MATCH(ROUND(Q28,1),Tablo_E!$B$1:$CX$1,1))) -> 1 | S28: =(F28+I28+L28+O28+R28)/5 -> 0.98
A29: 26 | B29: =Hakemler!B29 -> PINAR | C29: =Hakemler!C29 -> YELİZ | D29: 1.5 | E29: =IF(ISBLANK(D29),0,ABS(Uzman_E!A$4-D29)) -> 0.1 | F29: =IF(ISBLANK(D29),0,INDEX(Tablo_E!$B$2:$CX$102,MATCH(ROUND(Uzman_E!A$4,1),Tablo_E!$A$2:$A$102,1),MATCH(ROUND(E29,1),Tablo_E!$B$1:$CX$1,1))) -> 1 | G29: 1.7 | H29: =IF(ISBLANK(G29),0,ABS(Uzman_E!B$4-G29)) -> 0.6 | I29: =IF(ISBLANK(G29),0,INDEX(Tablo_E!$B$2:$CX$102,MATCH(ROUND(Uzman_E!B$4,1),Tablo_E!$A$2:$A$102,1),MATCH(ROUND(H29,1),Tablo_E!$B$1:$CX$1,1))) -> 0.8 | J29: 1 | K29: =IF(ISBLANK(J29),0,ABS(Uzman_E!C$4-J29)) -> 0.1 | L29: =IF(ISBLANK(J29),0,INDEX(Tablo_E!$B$2:$CX$102,MATCH(ROUND(Uzman_E!C$4,1),Tablo_E!$A$2:$A$102,1),MATCH(ROUND(K29,1),Tablo_E!$B$1:$CX$1,1))) -> 1 | M29: 1.1 | N29: =IF(ISBLANK(M29),0,ABS(Uzman_E!D$4-M29)) -> 0.3 | O29: =IF(ISBLANK(M29),0,INDEX(Tablo_E!$B$2:$CX$102,MATCH(ROUND(Uzman_E!D$4,1),Tablo_E!$A$2:$A$102,1),MATCH(ROUND(N29,1),Tablo_E!$B$1:$CX$1,1))) -> 0.8 | P29: 0.6 | Q29: =IF(ISBLANK(P29),0,ABS(Uzman_E!E$4-P29)) -> 0.4 | R29: =IF(ISBLANK(P29),0,INDEX(Tablo_E!$B$2:$CX$102,MATCH(ROUND(Uzman_E!B$4,1),Tablo_E!$A$2:$A$102,1),MATCH(ROUND(Q29,1),Tablo_E!$B$1:$CX$1,1))) -> 0.95 | S29: =(F29+I29+L29+O29+R29)/5 -> 0.91
A30: 27 | B30: =Hakemler!B30 -> KATRANCI | C30: =Hakemler!C30 -> AYŞEN | D30: 2 | E30: =IF(ISBLANK(D30),0,ABS(Uzman_E!A$4-D30)) -> 0.6 | F30: =IF(ISBLANK(D30),0,INDEX(Tablo_E!$B$2:$CX$102,MATCH(ROUND(Uzman_E!A$4,1),Tablo_E!$A$2:$A$102,1),MATCH(ROUND(E30,1),Tablo_E!$B$1:$CX$1,1))) -> 0.6 | G30: 2 | H30: =IF(ISBLANK(G30),0,ABS(Uzman_E!B$4-G30)) -> 0.3 | I30: =IF(ISBLANK(G30),0,INDEX(Tablo_E!$B$2:$CX$102,MATCH(ROUND(Uzman_E!B$4,1),Tablo_E!$A$2:$A$102,1),MATCH(ROUND(H30,1),Tablo_E!$B$1:$CX$1,1))) -> 1 | J30: 1 | K30: =IF(ISBLANK(J30),0,ABS(Uzman_E!C$4-J30)) -> 0.1 | L30: =IF(ISBLANK(J30),0,INDEX(Tablo_E!$B$2:$CX$102,MATCH(ROUND(Uzman_E!C$4,1),Tablo_E!$A$2:$A$102,1),MATCH(ROUND(K30,1),Tablo_E!$B$1:$CX$1,1))) -> 1 | M30: 1.2 | N30: =IF(ISBLANK(M30),0,ABS(Uzman_E!D$4-M30)) -> 0.4 | O30: =IF(ISBLANK(M30),0,INDEX(Tablo_E!$B$2:$CX$102,MATCH(ROUND(Uzman_E!D$4,1),Tablo_E!$A$2:$A$102,1),MATCH(ROUND(N30,1),Tablo_E!$B$1:$CX$1,1))) -> 0.7 | P30: 1.6 | Q30: =IF(ISBLANK(P30),0,ABS(Uzman_E!E$4-P30)) -> 0.6 | R30: =IF(ISBLANK(P30),0,INDEX(Tablo_E!$B$2:$CX$102,MATCH(ROUND(Uzman_E!B$4,1),Tablo_E!$A$2:$A$102,1),MATCH(ROUND(Q30,1),Tablo_E!$B$1:$CX$1,1))) -> 0.8 | S30: =(F30+I30+L30+O30+R30)/5 -> 0.82
A31: 28 | B31: =Hakemler!B31 -> GÜRKAN KİRAZ | C31: =Hakemler!C31 -> FULYA | D31: 1.5 | E31: =IF(ISBLANK(D31),0,ABS(Uzman_E!A$4-D31)) -> 0.1 | F31: =IF(ISBLANK(D31),0,INDEX(Tablo_E!$B$2:$CX$102,MATCH(ROUND(Uzman_E!A$4,1),Tablo_E!$A$2:$A$102,1),MATCH(ROUND(E31,1),Tablo_E!$B$1:$CX$1,1))) -> 1 | G31: 1.8 | H31: =IF(ISBLANK(G31),0,ABS(Uzman_E!B$4-G31)) -> 0.5 | I31: =IF(ISBLANK(G31),0,INDEX(Tablo_E!$B$2:$CX$102,MATCH(ROUND(Uzman_E!B$4,1),Tablo_E!$A$2:$A$102,1),MATCH(ROUND(H31,1),Tablo_E!$B$1:$CX$1,1))) -> 0.85 | J31: 1 | K31: =IF(ISBLANK(J31),0,ABS(Uzman_E!C$4-J31)) -> 0.1 | L31: =IF(ISBLANK(J31),0,INDEX(Tablo_E!$B$2:$CX$102,MATCH(ROUND(Uzman_E!C$4,1),Tablo_E!$A$2:$A$102,1),MATCH(ROUND(K31,1),Tablo_E!$B$1:$CX$1,1))) -> 1 | M31: 0.8 | N31: =IF(ISBLANK(M31),0,ABS(Uzman_E!D$4-M31)) -> 0 | O31: =IF(ISBLANK(M31),0,INDEX(Tablo_E!$B$2:$CX$102,MATCH(ROUND(Uzman_E!D$4,1),Tablo_E!$A$2:$A$102,1),MATCH(ROUND(N31,1),Tablo_E!$B$1:$CX$1,1))) -> 1 | P31: 1.2 | Q31: =IF(ISBLANK(P31),0,ABS(Uzman_E!E$4-P31)) -> 0.2 | R31: =IF(ISBLANK(P31),0,INDEX(Tablo_E!$B$2:$CX$102,MATCH(ROUND(Uzman_E!B$4,1),Tablo_E!$A$2:$A$102,1),MATCH(ROUND(Q31,1),Tablo_E!$B$1:$CX$1,1))) -> 1 | S31: =(F31+I31+L31+O31+R31)/5 -> 0.97
A32: 29 | B32: =Hakemler!B32 -> KILIÇ | C32: =Hakemler!C32 -> AYŞE | D32: 1.2 | E32: =IF(ISBLANK(D32),0,ABS(Uzman_E!A$4-D32)) -> 0.2 | F32: =IF(ISBLANK(D32),0,INDEX(Tablo_E!$B$2:$CX$102,MATCH(ROUND(Uzman_E!A$4,1),Tablo_E!$A$2:$A$102,1),MATCH(ROUND(E32,1),Tablo_E!$B$1:$CX$1,1))) -> 1 | G32: 2.5 | H32: =IF(ISBLANK(G32),0,ABS(Uzman_E!B$4-G32)) -> 0.2 | I32: =IF(ISBLANK(G32),0,INDEX(Tablo_E!$B$2:$CX$102,MATCH(ROUND(Uzman_E!B$4,1),Tablo_E!$A$2:$A$102,1),MATCH(ROUND(H32,1),Tablo_E!$B$1:$CX$1,1))) -> 1 | J32: 1 | K32: =IF(ISBLANK(J32),0,ABS(Uzman_E!C$4-J32)) -> 0.1 | L32: =IF(ISBLANK(J32),0,INDEX(Tablo_E!$B$2:$CX$102,MATCH(ROUND(Uzman_E!C$4,1),Tablo_E!$A$2:$A$102,1),MATCH(ROUND(K32,1),Tablo_E!$B$1:$CX$1,1))) -> 1 | M32: 1.1 | N32: =IF(ISBLANK(M32),0,ABS(Uzman_E!D$4-M32)) -> 0.3 | O32: =IF(ISBLANK(M32),0,INDEX(Tablo_E!$B$2:$CX$102,MATCH(ROUND(Uzman_E!D$4,1),Tablo_E!$A$2:$A$102,1),MATCH(ROUND(N32,1),Tablo_E!$B$1:$CX$1,1))) -> 0.8 | P32: 1.2 | Q32: =IF(ISBLANK(P32),0,ABS(Uzman_E!E$4-P32)) -> 0.2 | R32: =IF(ISBLANK(P32),0,INDEX(Tablo_E!$B$2:$CX$102,MATCH(ROUND(Uzman_E!B$4,1),Tablo_E!$A$2:$A$102,1),MATCH(ROUND(Q32,1),Tablo_E!$B$1:$CX$1,1))) -> 1 | S32: =(F32+I32+L32+O32+R32)/5 -> 0.96
A33: 30 | B33: =Hakemler!B33 -> ÖZGENLİK TATAR | C33: =Hakemler!C33 -> ARZU | D33: 1.2 | E33: =IF(ISBLANK(D33),0,ABS(Uzman_E!A$4-D33)) -> 0.2 | F33: =IF(ISBLANK(D33),0,INDEX(Tablo_E!$B$2:$CX$102,MATCH(ROUND(Uzman_E!A$4,1),Tablo_E!$A$2:$A$102,1),MATCH(ROUND(E33,1),Tablo_E!$B$1:$CX$1,1))) -> 1 | G33: 2.1 | H33: =IF(ISBLANK(G33),0,ABS(Uzman_E!B$4-G33)) -> 0.2 | I33: =IF(ISBLANK(G33),0,INDEX(Tablo_E!$B$2:$CX$102,MATCH(ROUND(Uzman_E!B$4,1),Tablo_E!$A$2:$A$102,1),MATCH(ROUND(H33,1),Tablo_E!$B$1:$CX$1,1))) -> 1 | J33: 1.1 | K33: =IF(ISBLANK(J33),0,ABS(Uzman_E!C$4-J33)) -> 0 | L33: =IF(ISBLANK(J33),0,INDEX(Tablo_E!$B$2:$CX$102,MATCH(ROUND(Uzman_E!C$4,1),Tablo_E!$A$2:$A$102,1),MATCH(ROUND(K33,1),Tablo_E!$B$1:$CX$1,1))) -> 1 | M33: 0.8 | N33: =IF(ISBLANK(M33),0,ABS(Uzman_E!D$4-M33)) -> 0 | O33: =IF(ISBLANK(M33),0,INDEX(Tablo_E!$B$2:$CX$102,MATCH(ROUND(Uzman_E!D$4,1),Tablo_E!$A$2:$A$102,1),MATCH(ROUND(N33,1),Tablo_E!$B$1:$CX$1,1))) -> 1 | P33: 0.9 | Q33: =IF(ISBLANK(P33),0,ABS(Uzman_E!E$4-P33)) -> 0.1 | R33: =IF(ISBLANK(P33),0,INDEX(Tablo_E!$B$2:$CX$102,MATCH(ROUND(Uzman_E!B$4,1),Tablo_E!$A$2:$A$102,1),MATCH(ROUND(Q33,1),Tablo_E!$B$1:$CX$1,1))) -> 1 | S33: =(F33+I33+L33+O33+R33)/5 -> 1
A34: 31 | B34: =Hakemler!B34 -> KARADENİZ | C34: =Hakemler!C34 -> EMEL | D34: 2.4 | E34: =IF(ISBLANK(D34),0,ABS(Uzman_E!A$4-D34)) -> 1 | F34: =IF(ISBLANK(D34),0,INDEX(Tablo_E!$B$2:$CX$102,MATCH(ROUND(Uzman_E!A$4,1),Tablo_E!$A$2:$A$102,1),MATCH(ROUND(E34,1),Tablo_E!$B$1:$CX$1,1))) -> 0.2 | G34: 3.3 | H34: =IF(ISBLANK(G34),0,ABS(Uzman_E!B$4-G34)) -> 1 | I34: =IF(ISBLANK(G34),0,INDEX(Tablo_E!$B$2:$CX$102,MATCH(ROUND(Uzman_E!B$4,1),Tablo_E!$A$2:$A$102,1),MATCH(ROUND(H34,1),Tablo_E!$B$1:$CX$1,1))) -> 0.4 | J34: 1.3 | K34: =IF(ISBLANK(J34),0,ABS(Uzman_E!C$4-J34)) -> 0.2 | L34: =IF(ISBLANK(J34),0,INDEX(Tablo_E!$B$2:$CX$102,MATCH(ROUND(Uzman_E!C$4,1),Tablo_E!$A$2:$A$102,1),MATCH(ROUND(K34,1),Tablo_E!$B$1:$CX$1,1))) -> 1 | M34: 0.8 | N34: =IF(ISBLANK(M34),0,ABS(Uzman_E!D$4-M34)) -> 0 | O34: =IF(ISBLANK(M34),0,INDEX(Tablo_E!$B$2:$CX$102,MATCH(ROUND(Uzman_E!D$4,1),Tablo_E!$A$2:$A$102,1),MATCH(ROUND(N34,1),Tablo_E!$B$1:$CX$1,1))) -> 1 | P34: 0.6 | Q34: =IF(ISBLANK(P34),0,ABS(Uzman_E!E$4-P34)) -> 0.4 | R34: =IF(ISBLANK(P34),0,INDEX(Tablo_E!$B$2:$CX$102,MATCH(ROUND(Uzman_E!B$4,1),Tablo_E!$A$2:$A$102,1),MATCH(ROUND(Q34,1),Tablo_E!$B$1:$CX$1,1))) -> 0.95 | S34: =(F34+I34+L34+O34+R34)/5 -> 0.71
A35: 32 | B35: =Hakemler!B35 -> TOYRAN | C35: =Hakemler!C35 -> SİNEM NUR | D35: 1.9 | E35: =IF(ISBLANK(D35),0,ABS(Uzman_E!A$4-D35)) -> 0.5 | F35: =IF(ISBLANK(D35),0,INDEX(Tablo_E!$B$2:$CX$102,MATCH(ROUND(Uzman_E!A$4,1),Tablo_E!$A$2:$A$102,1),MATCH(ROUND(E35,1),Tablo_E!$B$1:$CX$1,1))) -> 0.7 | G35: 2.5 | H35: =IF(ISBLANK(G35),0,ABS(Uzman_E!B$4-G35)) -> 0.2 | I35: =IF(ISBLANK(G35),0,INDEX(Tablo_E!$B$2:$CX$102,MATCH(ROUND(Uzman_E!B$4,1),Tablo_E!$A$2:$A$102,1),MATCH(ROUND(H35,1),Tablo_E!$B$1:$CX$1,1))) -> 1 | J35: 1.4 | K35: =IF(ISBLANK(J35),0,ABS(Uzman_E!C$4-J35)) -> 0.3 | L35: =IF(ISBLANK(J35),0,INDEX(Tablo_E!$B$2:$CX$102,MATCH(ROUND(Uzman_E!C$4,1),Tablo_E!$A$2:$A$102,1),MATCH(ROUND(K35,1),Tablo_E!$B$1:$CX$1,1))) -> 0.9 | M35: 0.9 | N35: =IF(ISBLANK(M35),0,ABS(Uzman_E!D$4-M35)) -> 0.1 | O35: =IF(ISBLANK(M35),0,INDEX(Tablo_E!$B$2:$CX$102,MATCH(ROUND(Uzman_E!D$4,1),Tablo_E!$A$2:$A$102,1),MATCH(ROUND(N35,1),Tablo_E!$B$1:$CX$1,1))) -> 1 | P35: 1.5 | Q35: =IF(ISBLANK(P35),0,ABS(Uzman_E!E$4-P35)) -> 0.5 | R35: =IF(ISBLANK(P35),0,INDEX(Tablo_E!$B$2:$CX$102,MATCH(ROUND(Uzman_E!B$4,1),Tablo_E!$A$2:$A$102,1),MATCH(ROUND(Q35,1),Tablo_E!$B$1:$CX$1,1))) -> 0.85 | S35: =(F35+I35+L35+O35+R35)/5 -> 0.89
